Workbook

Sheet Audit Info
A1: Audit Info
A3: Client Name | B3: CBRE - Bloomberg
A4: Site Name | B4: 120 Park Avenue
A5: Site Address | B5: 120 Park Avenue, New York, NY
A6: Hauler | B6: Waste Connections
A7: Tenant/Area Breakouts | B7: BOH Foodservice Management
A8: Auditors
A9: Audit Date | B9: 2025-01-23
A10: Site Occupancy
A11: Source | B11: Collected via tablet field form

Sheet Materials Master
A1: material_id | B1: material_name | C1: material_category | D1: currently_divertible | E1: accepted_in_program | F1: target: Trash | G1: target: GMPC Recycling | H1: target: Organics Recycling | I1: target: Cardboard Recycling | J1: target: Paper Recycling | K1: target: Terracycle
A2: FIB01 | B2: Corrugated Cardboard | C2: Fibers | D2: Yes | E2: Yes | F2: No | G2: Yes | H2: No | I2: Yes | J2: Yes | K2: No
A3: FIB02 | B3: Soiled Cardboard | C3: Fibers | D3: No | E3: No | F3: Yes | G3: No | H3: No | I3: No | J3: No | K3: No
A4: FIB03 | B4: Waxed Cardboard | C4: Fibers | D4: No | E4: No | F4: Yes | G4: No | H4: No | I4: No | J4: No | K4: No
A5: FIB04 | B5: Mixed Paper | C5: Fibers | D5: Yes | E5: Yes | F5: No | G5: Yes | H5: No | I5: Yes | J5: Yes | K5: No
A6: FIB05 | B6: Soiled Paper | C6: Fibers | D6: No | E6: No | F6: Yes | G6: No | H6: No | I6: No | J6: No | K6: No
A7: FIB06 | B7: Beverage Cartons | C7: Fibers | D7: Yes | E7: Yes | F7: No | G7: Yes | H7: No | I7: Yes | J7: Yes | K7: No
A8: FIB07 | B8: Soiled Beverage Cartons | C8: Fibers | D8: No | E8: No | F8: Yes | G8: No | H8: No | I8: No | J8: No | K8: No
A9: FIB08 | B9: Paper Cups / Other Coated Paper Containers | C9: Fibers | D9: No | E9: No | F9: Yes | G9: No | H9: No | I9: No | J9: No | K9: No
A10: GLA01 | B10: Glass Bottles & Jars | C10: Glass | D10: Yes | E10: Yes | F10: No | G10: Yes | H10: No | I10: Yes | J10: Yes | K10: No
A11: GLA02 | B11: Soiled Glass | C11: Glass | D11: No | E11: No | F11: Yes | G11: No | H11: No | I11: No | J11: No | K11: No
A12: MET01 | B12: Aluminum & Bi-Metal Containers | C12: Metals | D12: Yes | E12: Yes | F12: No | G12: Yes | H12: No | I12: Yes | J12: Yes | K12: No
... A27: OTH02 | B27: Other/Residual Materials | C27: Other | D27: No | E27: No | F27: Yes | G27: No | H27: No | I27: No | J27: No | K27: No

Sheet Areas
A1: area_id | B1: area_name | C1: rollup_group
A2: OFFICES | B2: OFFICES | C2: Rest of Building
A3: CAFE_BOH | B3: CAFÉ BOH | C3: BOH
A4: LOC_C | B4: LOCATION C | C4: Rest of Building
A5: LOC_D | B5: LOCATION D | C5: Rest of Building
A6: BATHROOM | B6: BATHROOM | C6: Rest of Building

Sheet Streams
A1: stream_name
A2: Trash
A3: GMPC Recycling
A4: Organics Recycling
A5: Cardboard Recycling
A6: Paper Recycling
A7: Terracycle

Sheet Fact_SortedWeights
A1: audit_id | B1: stream | C1: area | D1: material_id | E1: weight_lbs | F1: material_name | G1: material_category | H1: currently_divertible | I1: accepted_in_program | J1: belongs_here | K1: rollup_group | L1: notes
A2: 120PARK-2025 | B2: Cardboard Recycling | C2: OFFICES | D2: FIB01 | E2: 301.78 | F2: =IFERROR(INDEX('Materials Master'!$B$2:$B$27,MATCH(D2,'Materials Master'!$A$2:$A$27,0)),"") -> Corrugated Cardboard | G2: =IFERROR(INDEX('Materials Master'!$C$2:$C$27,MATCH(D2,'Materials Master'!$A$2:$A$27,0)),"") -> Fibers | H2: =IFERROR(INDEX('Materials Master'!$D$2:$D$27,MATCH(D2,'Materials Master'!$A$2:$A$27,0)),"") -> Yes | I2: =IFERROR(INDEX('Materials Master'!$E$2:$E$27,MATCH(D2,'Materials Master'!$A$2:$A$27,0)),"") -> Yes | J2: =IFERROR(IF(B2="Trash",INDEX('Materials Master'!$F$2:$F$27,MATCH(D2,'Materials Master'!$A$2:$A$27,0)),IF(B2="GMPC Recycling",INDEX('Materials Master'!$G$2:$G$27,MATCH(D2,'Materials Master'!$A$2:$A$27,0)),IF(B2="Organics Recycling",INDEX('Materials Master'!$H$2:$H$27,MATCH(D2,'Materials Master'!$A$2:$A$27,0)),IF(B2="Cardboard Recycling",INDEX('Materials Master'!$I$2:$I$27,MATCH(D2,'Materials Master'!$A$2:$A$27,0)),IF(B2="Paper Recycling",INDEX('Materials Master'!$J$2:$J$27,MATCH(D2,'Materials Master'!$A$2:$A$27,0)),IF(B2="Terracycle",INDEX('Materials Master'!$K$2:$K$27,MATCH(D2,'Materials Master'!$A$2:$A$27,0)),"No")))))),"") -> Yes | K2: =IFERROR(INDEX(Areas!$C$2:$C$6,MATCH(C2,Areas!$B$2:$B$6,0)),"") -> Rest of Building
A3: 120PARK-2025 | B3: Cardboard Recycling | C3: OFFICES | D3: FIB03 | E3: 4.4 | F3: =IFERROR(INDEX('Materials Master'!$B$2:$B$27,MATCH(D3,'Materials Master'!$A$2:$A$27,0)),"") -> Waxed Cardboard | G3: =IFERROR(INDEX('Materials Master'!$C$2:$C$27,MATCH(D3,'Materials Master'!$A$2:$A$27,0)),"") -> Fibers | H3: =IFERROR(INDEX('Materials Master'!$D$2:$D$27,MATCH(D3,'Materials Master'!$A$2:$A$27,0)),"") -> No | I3: =IFERROR(INDEX('Materials Master'!$E$2:$E$27,MATCH(D3,'Materials Master'!$A$2:$A$27,0)),"") -> No | J3: =IFERROR(IF(B3="Trash",INDEX('Materials Master'!$F$2:$F$27,MATCH(D3,'Materials Master'!$A$2:$A$27,0)),IF(B3="GMPC Recycling",INDEX('Materials Master'!$G$2:$G$27,MATCH(D3,'Materials Master'!$A$2:$A$27,0)),IF(B3="Organics Recycling",INDEX('Materials Master'!$H$2:$H$27,MATCH(D3,'Materials Master'!$A$2:$A$27,0)),IF(B3="Cardboard Recycling",INDEX('Materials Master'!$I$2:$I$27,MATCH(D3,'Materials Master'!$A$2:$A$27,0)),IF(B3="Paper Recycling",INDEX('Materials Master'!$J$2:$J$27,MATCH(D3,'Materials Master'!$A$2:$A$27,0)),IF(B3="Terracycle",INDEX('Materials Master'!$K$2:$K$27,MATCH(D3,'Materials Master'!$A$2:$A$27,0)),"No")))))),"") -> No | K3: =IFERROR(INDEX(Areas!$C$2:$C$6,MATCH(C3,Areas!$B$2:$B$6,0)),"") -> Rest of Building
A4: 120PARK-2025 | B4: Cardboard Recycling | C4: OFFICES | D4: FIB04 | E4: 33.2 | F4: =IFERROR(INDEX('Materials Master'!$B$2:$B$27,MATCH(D4,'Materials Master'!$A$2:$A$27,0)),"") -> Mixed Paper | G4: =IFERROR(INDEX('Materials Master'!$C$2:$C$27,MATCH(D4,'Materials Master'!$A$2:$A$27,0)),"") -> Fibers | H4: =IFERROR(INDEX('Materials Master'!$D$2:$D$27,MATCH(D4,'Materials Master'!$A$2:$A$27,0)),"") -> Yes | I4: =IFERROR(INDEX('Materials Master'!$E$2:$E$27,MATCH(D4,'Materials Master'!$A$2:$A$27,0)),"") -> Yes | J4: =IFERROR(IF(B4="Trash",INDEX('Materials Master'!$F$2:$F$27,MATCH(D4,'Materials Master'!$A$2:$A$27,0)),IF(B4="GMPC Recycling",INDEX('Materials Master'!$G$2:$G$27,MATCH(D4,'Materials Master'!$A$2:$A$27,0)),IF(B4="Organics Recycling",INDEX('Materials Master'!$H$2:$H$27,MATCH(D4,'Materials Master'!$A$2:$A$27,0)),IF(B4="Cardboard Recycling",INDEX('Materials Master'!$I$2:$I$27,MATCH(D4,'Materials Master'!$A$2:$A$27,0)),IF(B4="Paper Recycling",INDEX('Materials Master'!$J$2:$J$27,MATCH(D4,'Materials Master'!$A$2:$A$27,0)),IF(B4="Terracycle",INDEX('Materials Master'!$K$2:$K$27,MATCH(D4,'Materials Master'!$A$2:$A$27,0)),"No")))))),"") -> Yes | K4: =IFERROR(INDEX(Areas!$C$2:$C$6,MATCH(C4,Areas!$B$2:$B$6,0)),"") -> Rest of Building
A5: 120PARK-2025 | B5: Cardboard Recycling | C5: OFFICES | D5: FIB06 | E5: 0.163125 | F5: =IFERROR(INDEX('Materials Master'!$B$2:$B$27,MATCH(D5,'Materials Master'!$A$2:$A$27,0)),"") -> Beverage Cartons | G5: =IFERROR(INDEX('Materials Master'!$C$2:$C$27,MATCH(D5,'Materials Master'!$A$2:$A$27,0)),"") -> Fibers | H5: =IFERROR(INDEX('Materials Master'!$D$2:$D$27,MATCH(D5,'Materials Master'!$A$2:$A$27,0)),"") -> Yes | I5: =IFERROR(INDEX('Materials Master'!$E$2:$E$27,MATCH(D5,'Materials Master'!$A$2:$A$27,0)),"") -> Yes | J5: =IFERROR(IF(B5="Trash",INDEX('Materials Master'!$F$2:$F$27,MATCH(D5,'Materials Master'!$A$2:$A$27,0)),IF(B5="GMPC Recycling",INDEX('Materials Master'!$G$2:$G$27,MATCH(D5,'Materials Master'!$A$2:$A$27,0)),IF(B5="Organics Recycling",INDEX('Materials Master'!$H$2:$H$27,MATCH(D5,'Materials Master'!$A$2:$A$27,0)),IF(B5="Cardboard Recycling",INDEX('Materials Master'!$I$2:$I$27,MATCH(D5,'Materials Master'!$A$2:$A$27,0)),IF(B5="Paper Recycling",INDEX('Materials Master'!$J$2:$J$27,MATCH(D5,'Materials Master'!$A$2:$A$27,0)),IF(B5="Terracycle",INDEX('Materials Master'!$K$2:$K$27,MATCH(D5,'Materials Master'!$A$2:$A$27,0)),"No")))))),"") -> Yes | K5: =IFERROR(INDEX(Areas!$C$2:$C$6,MATCH(C5,Areas!$B$2:$B$6,0)),"") -> Rest of Building
A6: 120PARK-2025 | B6: Cardboard Recycling | C6: OFFICES | D6: PLA03 | E6: 1.716875 | F6: =IFERROR(INDEX('Materials Master'!$B$2:$B$27,MATCH(D6,'Materials Master'!$A$2:$A$27,0)),"") -> Film Plastics | G6: =IFERROR(INDEX('Materials Master'!$C$2:$C$27,MATCH(D6,'Materials Master'!$A$2:$A$27,0)),"") -> Plastics | H6: =IFERROR(INDEX('Materials Master'!$D$2:$D$27,MATCH(D6,'Materials Master'!$A$2:$A$27,0)),"") -> No | I6: =IFERROR(INDEX('Materials Master'!$E$2:$E$27,MATCH(D6,'Materials Master'!$A$2:$A$27,0)),"") -> No | J6: =IFERROR(IF(B6="Trash",INDEX('Materials Master'!$F$2:$F$27,MATCH(D6,'Materials Master'!$A$2:$A$27,0)),IF(B6="GMPC Recycling",INDEX('Materials Master'!$G$2:$G$27,MATCH(D6,'Materials Master'!$A$2:$A$27,0)),IF(B6="Organics Recycling",INDEX('Materials Master'!$H$2:$H$27,MATCH(D6,'Materials Master'!$A$2:$A$27,0)),IF(B6="Cardboard Recycling",INDEX('Materials Master'!$I$2:$I$27,MATCH(D6,'Materials Master'!$A$2:$A$27,0)),IF(B6="Paper Recycling",INDEX('Materials Master'!$J$2:$J$27,MATCH(D6,'Materials Master'!$A$2:$A$27,0)),IF(B6="Terracycle",INDEX('Materials Master'!$K$2:$K$27,MATCH(D6,'Materials Master'!$A$2:$A$27,0)),"No")))))),"") -> No | K6: =IFERROR(INDEX(Areas!$C$2:$C$6,MATCH(C6,Areas!$B$2:$B$6,0)),"") -> Rest of Building
A7: 120PARK-2025 | B7: Cardboard Recycling | C7: OFFICES | D7: PLA04 | E7: 0.15 | F7: =IFERROR(INDEX('Materials Master'!$B$2:$B$27,MATCH(D7,'Materials Master'!$A$2:$A$27,0)),"") -> Foams | G7: =IFERROR(INDEX('Materials Master'!$C$2:$C$27,MATCH(D7,'Materials Master'!$A$2:$A$27,0)),"") -> Plastics | H7: =IFERROR(INDEX('Materials Master'!$D$2:$D$27,MATCH(D7,'Materials Master'!$A$2:$A$27,0)),"") -> No | I7: =IFERROR(INDEX('Materials Master'!$E$2:$E$27,MATCH(D7,'Materials Master'!$A$2:$A$27,0)),"") -> No | J7: =IFERROR(IF(B7="Trash",INDEX('Materials Master'!$F$2:$F$27,MATCH(D7,'Materials Master'!$A$2:$A$27,0)),IF(B7="GMPC Recycling",INDEX('Materials Master'!$G$2:$G$27,MATCH(D7,'Materials Master'!$A$2:$A$27,0)),IF(B7="Organics Recycling",INDEX('Materials Master'!$H$2:$H$27,MATCH(D7,'Materials Master'!$A$2:$A$27,0)),IF(B7="Cardboard Recycling",INDEX('Materials Master'!$I$2:$I$27,MATCH(D7,'Materials Master'!$A$2:$A$27,0)),IF(B7="Paper Recycling",INDEX('Materials Master'!$J$2:$J$27,MATCH(D7,'Materials Master'!$A$2:$A$27,0)),IF(B7="Terracycle",INDEX('Materials Master'!$K$2:$K$27,MATCH(D7,'Materials Master'!$A$2:$A$27,0)),"No")))))),"") -> No | K7: =IFERROR(INDEX(Areas!$C$2:$C$6,MATCH(C7,Areas!$B$2:$B$6,0)),"") -> Rest of Building
A8: 120PARK-2025 | B8: Cardboard Recycling | C8: OFFICES | D8: ORG01 | E8: 0.024375 | F8: =IFERROR(INDEX('Materials Master'!$B$2:$B$27,MATCH(D8,'Materials Master'!$A$2:$A$27,0)),"") -> Food Waste | G8: =IFERROR(INDEX('Materials Master'!$C$2:$C$27,MATCH(D8,'Materials Master'!$A$2:$A$27,0)),"") -> Organics | H8: =IFERROR(INDEX('Materials Master'!$D$2:$D$27,MATCH(D8,'Materials Master'!$A$2:$A$27,0)),"") -> Yes | I8: =IFERROR(INDEX('Materials Master'!$E$2:$E$27,MATCH(D8,'Materials Master'!$A$2:$A$27,0)),"") -> Yes | J8: =IFERROR(IF(B8="Trash",INDEX('Materials Master'!$F$2:$F$27,MATCH(D8,'Materials Master'!$A$2:$A$27,0)),IF(B8="GMPC Recycling",INDEX('Materials Master'!$G$2:$G$27,MATCH(D8,'Materials Master'!$A$2:$A$27,0)),IF(B8="Organics Recycling",INDEX('Materials Master'!$H$2:$H$27,MATCH(D8,'Materials Master'!$A$2:$A$27,0)),IF(B8="Cardboard Recycling",INDEX('Materials Master'!$I$2:$I$27,MATCH(D8,'Materials Master'!$A$2:$A$27,0)),IF(B8="Paper Recycling",INDEX('Materials Master'!$J$2:$J$27,MATCH(D8,'Materials Master'!$A$2:$A$27,0)),IF(B8="Terracycle",INDEX('Materials Master'!$K$2:$K$27,MATCH(D8,'Materials Master'!$A$2:$A$27,0)),"No")))))),"") -> No | K8: =IFERROR(INDEX(Areas!$C$2:$C$6,MATCH(C8,Areas!$B$2:$B$6,0)),"") -> Rest of Building
A9: 120PARK-2025 | B9: Cardboard Recycling | C9: OFFICES | D9: ORG02 | E9: 0.0575 | F9: =IFERROR(INDEX('Materials Master'!$B$2:$B$27,MATCH(D9,'Materials Master'!$A$2:$A$27,0)),"") -> Paper Fibers and Food-Soiled Paper (FSP) | G9: =IFERROR(INDEX('Materials Master'!$C$2:$C$27,MATCH(D9,'Materials Master'!$A$2:$A$27,0)),"") -> Organics | H9: =IFERROR(INDEX('Materials Master'!$D$2:$D$27,MATCH(D9,'Materials Master'!$A$2:$A$27,0)),"") -> No | I9: =IFERROR(INDEX('Materials Master'!$E$2:$E$27,MATCH(D9,'Materials Master'!$A$2:$A$27,0)),"") -> No | J9: =IFERROR(IF(B9="Trash",INDEX('Materials Master'!$F$2:$F$27,MATCH(D9,'Materials Master'!$A$2:$A$27,0)),IF(B9="GMPC Recycling",INDEX('Materials Master'!$G$2:$G$27,MATCH(D9,'Materials Master'!$A$2:$A$27,0)),IF(B9="Organics Recycling",INDEX('Materials Master'!$H$2:$H$27,MATCH(D9,'Materials Master'!$A$2:$A$27,0)),IF(B9="Cardboard Recycling",INDEX('Materials Master'!$I$2:$I$27,MATCH(D9,'Materials Master'!$A$2:$A$27,0)),IF(B9="Paper Recycling",INDEX('Materials Master'!$J$2:$J$27,MATCH(D9,'Materials Master'!$A$2:$A$27,0)),IF(B9="Terracycle",INDEX('Materials Master'!$K$2:$K$27,MATCH(D9,'Materials Master'!$A$2:$A$27,0)),"No")))))),"") -> No | K9: =IFERROR(INDEX(Areas!$C$2:$C$6,MATCH(C9,Areas!$B$2:$B$6,0)),"") -> Rest of Building
A10: 120PARK-2025 | B10: Cardboard Recycling | C10: OFFICES | D10: ORG04 | E10: 0.035 | F10: =IFERROR(INDEX('Materials Master'!$B$2:$B$27,MATCH(D10,'Materials Master'!$A$2:$A$27,0)),"") -> PLA Compostable Serviceware | G10: =IFERROR(INDEX('Materials Master'!$C$2:$C$27,MATCH(D10,'Materials Master'!$A$2:$A$27,0)),"") -> Organics | H10: =IFERROR(INDEX('Materials Master'!$D$2:$D$27,MATCH(D10,'Materials Master'!$A$2:$A$27,0)),"") -> No | I10: =IFERROR(INDEX('Materials Master'!$E$2:$E$27,MATCH(D10,'Materials Master'!$A$2:$A$27,0)),"") -> No | J10: =IFERROR(IF(B10="Trash",INDEX('Materials Master'!$F$2:$F$27,MATCH(D10,'Materials Master'!$A$2:$A$27,0)),IF(B10="GMPC Recycling",INDEX('Materials Master'!$G$2:$G$27,MATCH(D10,'Materials Master'!$A$2:$A$27,0)),IF(B10="Organics Recycling",INDEX('Materials Master'!$H$2:$H$27,MATCH(D10,'Materials Master'!$A$2:$A$27,0)),IF(B10="Cardboard Recycling",INDEX('Materials Master'!$I$2:$I$27,MATCH(D10,'Materials Master'!$A$2:$A$27,0)),IF(B10="Paper Recycling",INDEX('Materials Master'!$J$2:$J$27,MATCH(D10,'Materials Master'!$A$2:$A$27,0)),IF(B10="Terracycle",INDEX('Materials Master'!$K$2:$K$27,MATCH(D10,'Materials Master'!$A$2:$A$27,0)),"No")))))),"") -> No | K10: =IFERROR(INDEX(Areas!$C$2:$C$6,MATCH(C10,Areas!$B$2:$B$6,0)),"") -> Rest of Building
A11: 120PARK-2025 | B11: Cardboard Recycling | C11: OFFICES | D11: OTH01 | E11: 0.1 | F11: =IFERROR(INDEX('Materials Master'!$B$2:$B$27,MATCH(D11,'Materials Master'!$A$2:$A$27,0)),"") -> Snack Wrappers (Composites) | G11: =IFERROR(INDEX('Materials Master'!$C$2:$C$27,MATCH(D11,'Materials Master'!$A$2:$A$27,0)),"") -> Other | H11: =IFERROR(INDEX('Materials Master'!$D$2:$D$27,MATCH(D11,'Materials Master'!$A$2:$A$27,0)),"") -> No | I11: =IFERROR(INDEX('Materials Master'!$E$2:$E$27,MATCH(D11,'Materials Master'!$A$2:$A$27,0)),"") -> Yes | J11: =IFERROR(IF(B11="Trash",INDEX('Materials Master'!$F$2:$F$27,MATCH(D11,'Materials Master'!$A$2:$A$27,0)),IF(B11="GMPC Recycling",INDEX('Materials Master'!$G$2:$G$27,MATCH(D11,'Materials Master'!$A$2:$A$27,0)),IF(B11="Organics Recycling",INDEX('Materials Master'!$H$2:$H$27,MATCH(D11,'Materials Master'!$A$2:$A$27,0)),IF(B11="Cardboard Recycling",INDEX('Materials Master'!$I$2:$I$27,MATCH(D11,'Materials Master'!$A$2:$A$27,0)),IF(B11="Paper Recycling",INDEX('Materials Master'!$J$2:$J$27,MATCH(D11,'Materials Master'!$A$2:$A$27,0)),IF(B11="Terracycle",INDEX('Materials Master'!$K$2:$K$27,MATCH(D11,'Materials Master'!$A$2:$A$27,0)),"No")))))),"") -> No | K11: =IFERROR(INDEX(Areas!$C$2:$C$6,MATCH(C11,Areas!$B$2:$B$6,0)),"") -> Rest of Building
A12: 120PARK-2025 | B12: Cardboard Recycling | C12: OFFICES | D12: OTH02 | E12: 8.2 | F12: =IFERROR(INDEX('Materials Master'!$B$2:$B$27,MATCH(D12,'Materials Master'!$A$2:$A$27,0)),"") -> Other/Residual Materials | G12: =IFERROR(INDEX('Materials Master'!$C$2:$C$27,MATCH(D12,'Materials Master'!$A$2:$A$27,0)),"") -> Other | H12: =IFERROR(INDEX('Materials Master'!$D$2:$D$27,MATCH(D12,'Materials Master'!$A$2:$A$27,0)),"") -> No | I12: =IFERROR(INDEX('Materials Master'!$E$2:$E$27,MATCH(D12,'Materials Master'!$A$2:$A$27,0)),"") -> No | J12: =IFERROR(IF(B12="Trash",INDEX('Materials Master'!$F$2:$F$27,MATCH(D12,'Materials Master'!$A$2:$A$27,0)),IF(B12="GMPC Recycling",INDEX('Materials Master'!$G$2:$G$27,MATCH(D12,'Materials Master'!$A$2:$A$27,0)),IF(B12="Organics Recycling",INDEX('Materials Master'!$H$2:$H$27,MATCH(D12,'Materials Master'!$A$2:$A$27,0)),IF(B12="Cardboard Recycling",INDEX('Materials Master'!$I$2:$I$27,MATCH(D12,'Materials Master'!$A$2:$A$27,0)),IF(B12="Paper Recycling",INDEX('Materials Master'!$J$2:$J$27,MATCH(D12,'Materials Master'!$A$2:$A$27,0)),IF(B12="Terracycle",INDEX('Materials Master'!$K$2:$K$27,MATCH(D12,'Materials Master'!$A$2:$A$27,0)),"No")))))),"") -> No | K12: =IFERROR(INDEX(Areas!$C$2:$C$6,MATCH(C12,Areas!$B$2:$B$6,0)),"") -> Rest of Building
A13: 120PARK-2025 | B13: Trash | C13: OFFICES | D13: FIB04 | E13: 17 | F13: =IFERROR(INDEX('Materials Master'!$B$2:$B$27,MATCH(D13,'Materials Master'!$A$2:$A$27,0)),"") -> Mixed Paper | G13: =IFERROR(INDEX('Materials Master'!$C$2:$C$27,MATCH(D13,'Materials Master'!$A$2:$A$27,0)),"") -> Fibers | H13: =IFERROR(INDEX('Materials Master'!$D$2:$D$27,MATCH(D13,'Materials Master'!$A$2:$A$27,0)),"") -> Yes | I13: =IFERROR(INDEX('Materials Master'!$E$2:$E$27,MATCH(D13,'Materials Master'!$A$2:$A$27,0)),"") -> Yes | J13: =IFERROR(IF(B13="Trash",INDEX('Materials Master'!$F$2:$F$27,MATCH(D13,'Materials Master'!$A$2:$A$27,0)),IF(B13="GMPC Recycling",INDEX('Materials Master'!$G$2:$G$27,MATCH(D13,'Materials Master'!$A$2:$A$27,0)),IF(B13="Organics Recycling",INDEX('Materials Master'!$H$2:$H$27,MATCH(D13,'Materials Master'!$A$2:$A$27,0)),IF(B13="Cardboard Recycling",INDEX('Materials Master'!$I$2:$I$27,MATCH(D13,'Materials Master'!$A$2:$A$27,0)),IF(B13="Paper Recycling",INDEX('Materials Master'!$J$2:$J$27,MATCH(D13,'Materials Master'!$A$2:$A$27,0)),IF(B13="Terracycle",INDEX('Materials Master'!$K$2:$K$27,MATCH(D13,'Materials Master'!$A$2:$A$27,0)),"No")))))),"") -> No | K13: =IFERROR(INDEX(Areas!$C$2:$C$6,MATCH(C13,Areas!$B$2:$B$6,0)),"") -> Rest of Building
... A89: 120PARK-2025 | B89: Organics Recycling | C89: CAFÉ BOH | D89: OTH02 | E89: 2.4 | F89: =IFERROR(INDEX('Materials Master'!$B$2:$B$27,MATCH(D89,'Materials Master'!$A$2:$A$27,0)),"") -> Other/Residual Materials | G89: =IFERROR(INDEX('Materials Master'!$C$2:$C$27,MATCH(D89,'Materials Master'!$A$2:$A$27,0)),"") -> Other | H89: =IFERROR(INDEX('Materials Master'!$D$2:$D$27,MATCH(D89,'Materials Master'!$A$2:$A$27,0)),"") -> No | I89: =IFERROR(INDEX('Materials Master'!$E$2:$E$27,MATCH(D89,'Materials Master'!$A$2:$A$27,0)),"") -> No | J89: =IFERROR(IF(B89="Trash",INDEX('Materials Master'!$F$2:$F$27,MATCH(D89,'Materials Master'!$A$2:$A$27,0)),IF(B89="GMPC Recycling",INDEX('Materials Master'!$G$2:$G$27,MATCH(D89,'Materials Master'!$A$2:$A$27,0)),IF(B89="Organics Recycling",INDEX('Materials Master'!$H$2:$H$27,MATCH(D89,'Materials Master'!$A$2:$A$27,0)),IF(B89="Cardboard Recycling",INDEX('Materials Master'!$I$2:$I$27,MATCH(D89,'Materials Master'!$A$2:$A$27,0)),IF(B89="Paper Recycling",INDEX('Materials Master'!$J$2:$J$27,MATCH(D89,'Materials Master'!$A$2:$A$27,0)),IF(B89="Terracycle",INDEX('Materials Master'!$K$2:$K$27,MATCH(D89,'Materials Master'!$A$2:$A$27,0)),"No")))))),"") -> No | K89: =IFERROR(INDEX(Areas!$C$2:$C$6,MATCH(C89,Areas!$B$2:$B$6,0)),"") -> BOH

Sheet Fact_PreSortWeights
A1: audit_id | B1: stream | C1: area | D1: bag_number | E1: weight_lbs | F1: notes
A2: 120PARK-2025 | B2: Trash | C2: OFFICES | D2: 1 | E2: 3.3
A3: 120PARK-2025 | B3: Trash | C3: OFFICES | D3: 2 | E3: 8.8
A4: 120PARK-2025 | B4: Trash | C4: OFFICES | D4: 3 | E4: 3.4
A5: 120PARK-2025 | B5: Trash | C5: OFFICES | D5: 4 | E5: 16.5
A6: 120PARK-2025 | B6: Trash | C6: OFFICES | D6: 5 | E6: 9.5
A7: 120PARK-2025 | B7: Trash | C7: OFFICES | D7: 6 | E7: 24.4
A8: 120PARK-2025 | B8: Trash | C8: OFFICES | D8: 7 | E8: 17.9
A9: 120PARK-2025 | B9: Trash | C9: OFFICES | D9: 8 | E9: 15
A10: 120PARK-2025 | B10: Trash | C10: OFFICES | D10: 9 | E10: 11.2
A11: 120PARK-2025 | B11: Trash | C11: OFFICES | D11: 10 | E11: 3
A12: 120PARK-2025 | B12: Trash | C12: OFFICES | D12: 11 | E12: 11.8
A13: 120PARK-2025 | B13: Trash | C13: OFFICES | D13: 12 | E13: 16.4
... A186: 120PARK-2025 | B186: Organics Recycling | C186: BATHROOM | D186: 19 | E186: 23.1

Sheet Fact_Extrapolated
A1: area | B1: stream | C1: material_id | D1: material_name | E1: material_category | F1: extrapolated_weight_lbs | G1: correctly_placed | H1: accepted_in_program | I1: rollup_group | J1: belongs_here
A2: OFFICES | B2: Trash | C2: FIB01 | D2: =IFERROR(INDEX('Materials Master'!$B$2:$B$27,MATCH($C2,'Materials Master'!$A$2:$A$27,0)),"") -> Corrugated Cardboard | E2: =IFERROR(INDEX('Materials Master'!$C$2:$C$27,MATCH($C2,'Materials Master'!$A$2:$A$27,0)),"") -> Fibers | F2: =IF(SUMIFS(Fact_SortedWeights!$E$2:$E$89,Fact_SortedWeights!$C$2:$C$89,$A2,Fact_SortedWeights!$B$2:$B$89,$B2)=0,0,SUMIFS(Fact_SortedWeights!$E$2:$E$89,Fact_SortedWeights!$C$2:$C$89,$A2,Fact_SortedWeights!$B$2:$B$89,$B2,Fact_SortedWeights!$D$2:$D$89,$C2)/SUMIFS(Fact_SortedWeights!$E$2:$E$89,Fact_SortedWeights!$C$2:$C$89,$A2,Fact_SortedWeights!$B$2:$B$89,$B2)*(IF($B2="Cardboard Recycling",SUMIFS(Fact_SortedWeights!$E$2:$E$89,Fact_SortedWeights!$C$2:$C$89,$A2,Fact_SortedWeights!$B$2:$B$89,$B2),SUMIFS(Fact_PreSortWeights!$E$2:$E$186,Fact_PreSortWeights!$C$2:$C$186,$A2,Fact_PreSortWeights!$B$2:$B$186,$B2)))) -> 0 | G2: =IF(AND(IF($B2="Trash",INDEX('Materials Master'!$F$2:$F$27,MATCH($C2,'Materials Master'!$A$2:$A$27,0)),IF($B2="GMPC Recycling",INDEX('Materials Master'!$G$2:$G$27,MATCH($C2,'Materials Master'!$A$2:$A$27,0)),IF($B2="Organics Recycling",INDEX('Materials Master'!$H$2:$H$27,MATCH($C2,'Materials Master'!$A$2:$A$27,0)),IF($B2="Cardboard Recycling",INDEX('Materials Master'!$I$2:$I$27,MATCH($C2,'Materials Master'!$A$2:$A$27,0)),IF($B2="Paper Recycling",INDEX('Materials Master'!$J$2:$J$27,MATCH($C2,'Materials Master'!$A$2:$A$27,0)),IF($B2="Terracycle",INDEX('Materials Master'!$K$2:$K$27,MATCH($C2,'Materials Master'!$A$2:$A$27,0)),"No"))))))="Yes",INDEX('Materials Master'!$E$2:$E$27,MATCH($C2,'Materials Master'!$A$2:$A$27,0))="Yes",$B2<>"Trash"),1,0) -> 0 | H2: =INDEX('Materials Master'!$E$2:$E$27,MATCH($C2,'Materials Master'!$A$2:$A$27,0)) -> Yes | I2: =IFERROR(INDEX(Areas!$C$2:$C$6,MATCH($A2,Areas!$B$2:$B$6,0)),"") -> Rest of Building | J2: =IF(IF($B2="Trash",INDEX('Materials Master'!$F$2:$F$27,MATCH($C2,'Materials Master'!$A$2:$A$27,0)),IF($B2="GMPC Recycling",INDEX('Materials Master'!$G$2:$G$27,MATCH($C2,'Materials Master'!$A$2:$A$27,0)),IF($B2="Organics Recycling",INDEX('Materials Master'!$H$2:$H$27,MATCH($C2,'Materials Master'!$A$2:$A$27,0)),IF($B2="Cardboard Recycling",INDEX('Materials Master'!$I$2:$I$27,MATCH($C2,'Materials Master'!$A$2:$A$27,0)),IF($B2="Paper Recycling",INDEX('Materials Master'!$J$2:$J$27,MATCH($C2,'Materials Master'!$A$2:$A$27,0)),IF($B2="Terracycle",INDEX('Materials Master'!$K$2:$K$27,MATCH($C2,'Materials Master'!$A$2:$A$27,0)),"No"))))))="Yes",1,0) -> 0
A3: OFFICES | B3: Trash | C3: FIB02 | D3: =IFERROR(INDEX('Materials Master'!$B$2:$B$27,MATCH($C3,'Materials Master'!$A$2:$A$27,0)),"") -> Soiled Cardboard | E3: =IFERROR(INDEX('Materials Master'!$C$2:$C$27,MATCH($C3,'Materials Master'!$A$2:$A$27,0)),"") -> Fibers | F3: =IF(SUMIFS(Fact_SortedWeights!$E$2:$E$89,Fact_SortedWeights!$C$2:$C$89,$A3,Fact_SortedWeights!$B$2:$B$89,$B3)=0,0,SUMIFS(Fact_SortedWeights!$E$2:$E$89,Fact_SortedWeights!$C$2:$C$89,$A3,Fact_SortedWeights!$B$2:$B$89,$B3,Fact_SortedWeights!$D$2:$D$89,$C3)/SUMIFS(Fact_SortedWeights!$E$2:$E$89,Fact_SortedWeights!$C$2:$C$89,$A3,Fact_SortedWeights!$B$2:$B$89,$B3)*(IF($B3="Cardboard Recycling",SUMIFS(Fact_SortedWeights!$E$2:$E$89,Fact_SortedWeights!$C$2:$C$89,$A3,Fact_SortedWeights!$B$2:$B$89,$B3),SUMIFS(Fact_PreSortWeights!$E$2:$E$186,Fact_PreSortWeights!$C$2:$C$186,$A3,Fact_PreSortWeights!$B$2:$B$186,$B3)))) -> 0 | G3: =IF(AND(IF($B3="Trash",INDEX('Materials Master'!$F$2:$F$27,MATCH($C3,'Materials Master'!$A$2:$A$27,0)),IF($B3="GMPC Recycling",INDEX('Materials Master'!$G$2:$G$27,MATCH($C3,'Materials Master'!$A$2:$A$27,0)),IF($B3="Organics Recycling",INDEX('Materials Master'!$H$2:$H$27,MATCH($C3,'Materials Master'!$A$2:$A$27,0)),IF($B3="Cardboard Recycling",INDEX('Materials Master'!$I$2:$I$27,MATCH($C3,'Materials Master'!$A$2:$A$27,0)),IF($B3="Paper Recycling",INDEX('Materials Master'!$J$2:$J$27,MATCH($C3,'Materials Master'!$A$2:$A$27,0)),IF($B3="Terracycle",INDEX('Materials Master'!$K$2:$K$27,MATCH($C3,'Materials Master'!$A$2:$A$27,0)),"No"))))))="Yes",INDEX('Materials Master'!$E$2:$E$27,MATCH($C3,'Materials Master'!$A$2:$A$27,0))="Yes",$B3<>"Trash"),1,0) -> 0 | H3: =INDEX('Materials Master'!$E$2:$E$27,MATCH($C3,'Materials Master'!$A$2:$A$27,0)) -> No | I3: =IFERROR(INDEX(Areas!$C$2:$C$6,MATCH($A3,Areas!$B$2:$B$6,0)),"") -> Rest of Building | J3: =IF(IF($B3="Trash",INDEX('Materials Master'!$F$2:$F$27,MATCH($C3,'Materials Master'!$A$2:$A$27,0)),IF($B3="GMPC Recycling",INDEX('Materials Master'!$G$2:$G$27,MATCH($C3,'Materials Master'!$A$2:$A$27,0)),IF($B3="Organics Recycling",INDEX('Materials Master'!$H$2:$H$27,MATCH($C3,'Materials Master'!$A$2:$A$27,0)),IF($B3="Cardboard Recycling",INDEX('Materials Master'!$I$2:$I$27,MATCH($C3,'Materials Master'!$A$2:$A$27,0)),IF($B3="Paper Recycling",INDEX('Materials Master'!$J$2:$J$27,MATCH($C3,'Materials Master'!$A$2:$A$27,0)),IF($B3="Terracycle",INDEX('Materials Master'!$K$2:$K$27,MATCH($C3,'Materials Master'!$A$2:$A$27,0)),"No"))))))="Yes",1,0) -> 1
A4: OFFICES | B4: Trash | C4: FIB03 | D4: =IFERROR(INDEX('Materials Master'!$B$2:$B$27,MATCH($C4,'Materials Master'!$A$2:$A$27,0)),"") -> Waxed Cardboard | E4: =IFERROR(INDEX('Materials Master'!$C$2:$C$27,MATCH($C4,'Materials Master'!$A$2:$A$27,0)),"") -> Fibers | F4: =IF(SUMIFS(Fact_SortedWeights!$E$2:$E$89,Fact_SortedWeights!$C$2:$C$89,$A4,Fact_SortedWeights!$B$2:$B$89,$B4)=0,0,SUMIFS(Fact_SortedWeights!$E$2:$E$89,Fact_SortedWeights!$C$2:$C$89,$A4,Fact_SortedWeights!$B$2:$B$89,$B4,Fact_SortedWeights!$D$2:$D$89,$C4)/SUMIFS(Fact_SortedWeights!$E$2:$E$89,Fact_SortedWeights!$C$2:$C$89,$A4,Fact_SortedWeights!$B$2:$B$89,$B4)*(IF($B4="Cardboard Recycling",SUMIFS(Fact_SortedWeights!$E$2:$E$89,Fact_SortedWeights!$C$2:$C$89,$A4,Fact_SortedWeights!$B$2:$B$89,$B4),SUMIFS(Fact_PreSortWeights!$E$2:$E$186,Fact_PreSortWeights!$C$2:$C$186,$A4,Fact_PreSortWeights!$B$2:$B$186,$B4)))) -> 0 | G4: =IF(AND(IF($B4="Trash",INDEX('Materials Master'!$F$2:$F$27,MATCH($C4,'Materials Master'!$A$2:$A$27,0)),IF($B4="GMPC Recycling",INDEX('Materials Master'!$G$2:$G$27,MATCH($C4,'Materials Master'!$A$2:$A$27,0)),IF($B4="Organics Recycling",INDEX('Materials Master'!$H$2:$H$27,MATCH($C4,'Materials Master'!$A$2:$A$27,0)),IF($B4="Cardboard Recycling",INDEX('Materials Master'!$I$2:$I$27,MATCH($C4,'Materials Master'!$A$2:$A$27,0)),IF($B4="Paper Recycling",INDEX('Materials Master'!$J$2:$J$27,MATCH($C4,'Materials Master'!$A$2:$A$27,0)),IF($B4="Terracycle",INDEX('Materials Master'!$K$2:$K$27,MATCH($C4,'Materials Master'!$A$2:$A$27,0)),"No"))))))="Yes",INDEX('Materials Master'!$E$2:$E$27,MATCH($C4,'Materials Master'!$A$2:$A$27,0))="Yes",$B4<>"Trash"),1,0) -> 0 | H4: =INDEX('Materials Master'!$E$2:$E$27,MATCH($C4,'Materials Master'!$A$2:$A$27,0)) -> No | I4: =IFERROR(INDEX(Areas!$C$2:$C$6,MATCH($A4,Areas!$B$2:$B$6,0)),"") -> Rest of Building | J4: =IF(IF($B4="Trash",INDEX('Materials Master'!$F$2:$F$27,MATCH($C4,'Materials Master'!$A$2:$A$27,0)),IF($B4="GMPC Recycling",INDEX('Materials Master'!$G$2:$G$27,MATCH($C4,'Materials Master'!$A$2:$A$27,0)),IF($B4="Organics Recycling",INDEX('Materials Master'!$H$2:$H$27,MATCH($C4,'Materials Master'!$A$2:$A$27,0)),IF($B4="Cardboard Recycling",INDEX('Materials Master'!$I$2:$I$27,MATCH($C4,'Materials Master'!$A$2:$A$27,0)),IF($B4="Paper Recycling",INDEX('Materials Master'!$J$2:$J$27,MATCH($C4,'Materials Master'!$A$2:$A$27,0)),IF($B4="Terracycle",INDEX('Materials Master'!$K$2:$K$27,MATCH($C4,'Materials Master'!$A$2:$A$27,0)),"No"))))))="Yes",1,0) -> 1
A5: OFFICES | B5: Trash | C5: FIB04 | D5: =IFERROR(INDEX('Materials Master'!$B$2:$B$27,MATCH($C5,'Materials Master'!$A$2:$A$27,0)),"") -> Mixed Paper | E5: =IFERROR(INDEX('Materials Master'!$C$2:$C$27,MATCH($C5,'Materials Master'!$A$2:$A$27,0)),"") -> Fibers | F5: =IF(SUMIFS(Fact_SortedWeights!$E$2:$E$89,Fact_SortedWeights!$C$2:$C$89,$A5,Fact_SortedWeights!$B$2:$B$89,$B5)=0,0,SUMIFS(Fact_SortedWeights!$E$2:$E$89,Fact_SortedWeights!$C$2:$C$89,$A5,Fact_SortedWeights!$B$2:$B$89,$B5,Fact_SortedWeights!$D$2:$D$89,$C5)/SUMIFS(Fact_SortedWeights!$E$2:$E$89,Fact_SortedWeights!$C$2:$C$89,$A5,Fact_SortedWeights!$B$2:$B$89,$B5)*(IF($B5="Cardboard Recycling",SUMIFS(Fact_SortedWeights!$E$2:$E$89,Fact_SortedWeights!$C$2:$C$89,$A5,Fact_SortedWeights!$B$2:$B$89,$B5),SUMIFS(Fact_PreSortWeights!$E$2:$E$186,Fact_PreSortWeights!$C$2:$C$186,$A5,Fact_PreSortWeights!$B$2:$B$186,$B5)))) -> 41.067619 | G5: =IF(AND(IF($B5="Trash",INDEX('Materials Master'!$F$2:$F$27,MATCH($C5,'Materials Master'!$A$2:$A$27,0)),IF($B5="GMPC Recycling",INDEX('Materials Master'!$G$2:$G$27,MATCH($C5,'Materials Master'!$A$2:$A$27,0)),IF($B5="Organics Recycling",INDEX('Materials Master'!$H$2:$H$27,MATCH($C5,'Materials Master'!$A$2:$A$27,0)),IF($B5="Cardboard Recycling",INDEX('Materials Master'!$I$2:$I$27,MATCH($C5,'Materials Master'!$A$2:$A$27,0)),IF($B5="Paper Recycling",INDEX('Materials Master'!$J$2:$J$27,MATCH($C5,'Materials Master'!$A$2:$A$27,0)),IF($B5="Terracycle",INDEX('Materials Master'!$K$2:$K$27,MATCH($C5,'Materials Master'!$A$2:$A$27,0)),"No"))))))="Yes",INDEX('Materials Master'!$E$2:$E$27,MATCH($C5,'Materials Master'!$A$2:$A$27,0))="Yes",$B5<>"Trash"),1,0) -> 0 | H5: =INDEX('Materials Master'!$E$2:$E$27,MATCH($C5,'Materials Master'!$A$2:$A$27,0)) -> Yes | I5: =IFERROR(INDEX(Areas!$C$2:$C$6,MATCH($A5,Areas!$B$2:$B$6,0)),"") -> Rest of Building | J5: =IF(IF($B5="Trash",INDEX('Materials Master'!$F$2:$F$27,MATCH($C5,'Materials Master'!$A$2:$A$27,0)),IF($B5="GMPC Recycling",INDEX('Materials Master'!$G$2:$G$27,MATCH($C5,'Materials Master'!$A$2:$A$27,0)),IF($B5="Organics Recycling",INDEX('Materials Master'!$H$2:$H$27,MATCH($C5,'Materials Master'!$A$2:$A$27,0)),IF($B5="Cardboard Recycling",INDEX('Materials Master'!$I$2:$I$27,MATCH($C5,'Materials Master'!$A$2:$A$27,0)),IF($B5="Paper Recycling",INDEX('Materials Master'!$J$2:$J$27,MATCH($C5,'Materials Master'!$A$2:$A$27,0)),IF($B5="Terracycle",INDEX('Materials Master'!$K$2:$K$27,MATCH($C5,'Materials Master'!$A$2:$A$27,0)),"No"))))))="Yes",1,0) -> 0
A6: OFFICES | B6: Trash | C6: FIB05 | D6: =IFERROR(INDEX('Materials Master'!$B$2:$B$27,MATCH($C6,'Materials Master'!$A$2:$A$27,0)),"") -> Soiled Paper | E6: =IFERROR(INDEX('Materials Master'!$C$2:$C$27,MATCH($C6,'Materials Master'!$A$2:$A$27,0)),"") -> Fibers | F6: =IF(SUMIFS(Fact_SortedWeights!$E$2:$E$89,Fact_SortedWeights!$C$2:$C$89,$A6,Fact_SortedWeights!$B$2:$B$89,$B6)=0,0,SUMIFS(Fact_SortedWeights!$E$2:$E$89,Fact_SortedWeights!$C$2:$C$89,$A6,Fact_SortedWeights!$B$2:$B$89,$B6,Fact_SortedWeights!$D$2:$D$89,$C6)/SUMIFS(Fact_SortedWeights!$E$2:$E$89,Fact_SortedWeights!$C$2:$C$89,$A6,Fact_SortedWeights!$B$2:$B$89,$B6)*(IF($B6="Cardboard Recycling",SUMIFS(Fact_SortedWeights!$E$2:$E$89,Fact_SortedWeights!$C$2:$C$89,$A6,Fact_SortedWeights!$B$2:$B$89,$B6),SUMIFS(Fact_PreSortWeights!$E$2:$E$186,Fact_PreSortWeights!$C$2:$C$186,$A6,Fact_PreSortWeights!$B$2:$B$186,$B6)))) -> 0 | G6: =IF(AND(IF($B6="Trash",INDEX('Materials Master'!$F$2:$F$27,MATCH($C6,'Materials Master'!$A$2:$A$27,0)),IF($B6="GMPC Recycling",INDEX('Materials Master'!$G$2:$G$27,MATCH($C6,'Materials Master'!$A$2:$A$27,0)),IF($B6="Organics Recycling",INDEX('Materials Master'!$H$2:$H$27,MATCH($C6,'Materials Master'!$A$2:$A$27,0)),IF($B6="Cardboard Recycling",INDEX('Materials Master'!$I$2:$I$27,MATCH($C6,'Materials Master'!$A$2:$A$27,0)),IF($B6="Paper Recycling",INDEX('Materials Master'!$J$2:$J$27,MATCH($C6,'Materials Master'!$A$2:$A$27,0)),IF($B6="Terracycle",INDEX('Materials Master'!$K$2:$K$27,MATCH($C6,'Materials Master'!$A$2:$A$27,0)),"No"))))))="Yes",INDEX('Materials Master'!$E$2:$E$27,MATCH($C6,'Materials Master'!$A$2:$A$27,0))="Yes",$B6<>"Trash"),1,0) -> 0 | H6: =INDEX('Materials Master'!$E$2:$E$27,MATCH($C6,'Materials Master'!$A$2:$A$27,0)) -> No | I6: =IFERROR(INDEX(Areas!$C$2:$C$6,MATCH($A6,Areas!$B$2:$B$6,0)),"") -> Rest of Building | J6: =IF(IF($B6="Trash",INDEX('Materials Master'!$F$2:$F$27,MATCH($C6,'Materials Master'!$A$2:$A$27,0)),IF($B6="GMPC Recycling",INDEX('Materials Master'!$G$2:$G$27,MATCH($C6,'Materials Master'!$A$2:$A$27,0)),IF($B6="Organics Recycling",INDEX('Materials Master'!$H$2:$H$27,MATCH($C6,'Materials Master'!$A$2:$A$27,0)),IF($B6="Cardboard Recycling",INDEX('Materials Master'!$I$2:$I$27,MATCH($C6,'Materials Master'!$A$2:$A$27,0)),IF($B6="Paper Recycling",INDEX('Materials Master'!$J$2:$J$27,MATCH($C6,'Materials Master'!$A$2:$A$27,0)),IF($B6="Terracycle",INDEX('Materials Master'!$K$2:$K$27,MATCH($C6,'Materials Master'!$A$2:$A$27,0)),"No"))))))="Yes",1,0) -> 1
A7: OFFICES | B7: Trash | C7: FIB06 | D7: =IFERROR(INDEX('Materials Master'!$B$2:$B$27,MATCH($C7,'Materials Master'!$A$2:$A$27,0)),"") -> Beverage Cartons | E7: =IFERROR(INDEX('Materials Master'!$C$2:$C$27,MATCH($C7,'Materials Master'!$A$2:$A$27,0)),"") -> Fibers | F7: =IF(SUMIFS(Fact_SortedWeights!$E$2:$E$89,Fact_SortedWeights!$C$2:$C$89,$A7,Fact_SortedWeights!$B$2:$B$89,$B7)=0,0,SUMIFS(Fact_SortedWeights!$E$2:$E$89,Fact_SortedWeights!$C$2:$C$89,$A7,Fact_SortedWeights!$B$2:$B$89,$B7,Fact_SortedWeights!$D$2:$D$89,$C7)/SUMIFS(Fact_SortedWeights!$E$2:$E$89,Fact_SortedWeights!$C$2:$C$89,$A7,Fact_SortedWeights!$B$2:$B$89,$B7)*(IF($B7="Cardboard Recycling",SUMIFS(Fact_SortedWeights!$E$2:$E$89,Fact_SortedWeights!$C$2:$C$89,$A7,Fact_SortedWeights!$B$2:$B$89,$B7),SUMIFS(Fact_PreSortWeights!$E$2:$E$186,Fact_PreSortWeights!$C$2:$C$186,$A7,Fact_PreSortWeights!$B$2:$B$186,$B7)))) -> 0.14947405 | G7: =IF(AND(IF($B7="Trash",INDEX('Materials Master'!$F$2:$F$27,MATCH($C7,'Materials Master'!$A$2:$A$27,0)),IF($B7="GMPC Recycling",INDEX('Materials Master'!$G$2:$G$27,MATCH($C7,'Materials Master'!$A$2:$A$27,0)),IF($B7="Organics Recycling",INDEX('Materials Master'!$H$2:$H$27,MATCH($C7,'Materials Master'!$A$2:$A$27,0)),IF($B7="Cardboard Recycling",INDEX('Materials Master'!$I$2:$I$27,MATCH($C7,'Materials Master'!$A$2:$A$27,0)),IF($B7="Paper Recycling",INDEX('Materials Master'!$J$2:$J$27,MATCH($C7,'Materials Master'!$A$2:$A$27,0)),IF($B7="Terracycle",INDEX('Materials Master'!$K$2:$K$27,MATCH($C7,'Materials Master'!$A$2:$A$27,0)),"No"))))))="Yes",INDEX('Materials Master'!$E$2:$E$27,MATCH($C7,'Materials Master'!$A$2:$A$27,0))="Yes",$B7<>"Trash"),1,0) -> 0 | H7: =INDEX('Materials Master'!$E$2:$E$27,MATCH($C7,'Materials Master'!$A$2:$A$27,0)) -> Yes | I7: =IFERROR(INDEX(Areas!$C$2:$C$6,MATCH($A7,Areas!$B$2:$B$6,0)),"") -> Rest of Building | J7: =IF(IF($B7="Trash",INDEX('Materials Master'!$F$2:$F$27,MATCH($C7,'Materials Master'!$A$2:$A$27,0)),IF($B7="GMPC Recycling",INDEX('Materials Master'!$G$2:$G$27,MATCH($C7,'Materials Master'!$A$2:$A$27,0)),IF($B7="Organics Recycling",INDEX('Materials Master'!$H$2:$H$27,MATCH($C7,'Materials Master'!$A$2:$A$27,0)),IF($B7="Cardboard Recycling",INDEX('Materials Master'!$I$2:$I$27,MATCH($C7,'Materials Master'!$A$2:$A$27,0)),IF($B7="Paper Recycling",INDEX('Materials Master'!$J$2:$J$27,MATCH($C7,'Materials Master'!$A$2:$A$27,0)),IF($B7="Terracycle",INDEX('Materials Master'!$K$2:$K$27,MATCH($C7,'Materials Master'!$A$2:$A$27,0)),"No"))))))="Yes",1,0) -> 0
A8: OFFICES | B8: Trash | C8: FIB07 | D8: =IFERROR(INDEX('Materials Master'!$B$2:$B$27,MATCH($C8,'Materials Master'!$A$2:$A$27,0)),"") -> Soiled Beverage Cartons | E8: =IFERROR(INDEX('Materials Master'!$C$2:$C$27,MATCH($C8,'Materials Master'!$A$2:$A$27,0)),"") -> Fibers | F8: =IF(SUMIFS(Fact_SortedWeights!$E$2:$E$89,Fact_SortedWeights!$C$2:$C$89,$A8,Fact_SortedWeights!$B$2:$B$89,$B8)=0,0,SUMIFS(Fact_SortedWeights!$E$2:$E$89,Fact_SortedWeights!$C$2:$C$89,$A8,Fact_SortedWeights!$B$2:$B$89,$B8,Fact_SortedWeights!$D$2:$D$89,$C8)/SUMIFS(Fact_SortedWeights!$E$2:$E$89,Fact_SortedWeights!$C$2:$C$89,$A8,Fact_SortedWeights!$B$2:$B$89,$B8)*(IF($B8="Cardboard Recycling",SUMIFS(Fact_SortedWeights!$E$2:$E$89,Fact_SortedWeights!$C$2:$C$89,$A8,Fact_SortedWeights!$B$2:$B$89,$B8),SUMIFS(Fact_PreSortWeights!$E$2:$E$186,Fact_PreSortWeights!$C$2:$C$186,$A8,Fact_PreSortWeights!$B$2:$B$186,$B8)))) -> 0 | G8: =IF(AND(IF($B8="Trash",INDEX('Materials Master'!$F$2:$F$27,MATCH($C8,'Materials Master'!$A$2:$A$27,0)),IF($B8="GMPC Recycling",INDEX('Materials Master'!$G$2:$G$27,MATCH($C8,'Materials Master'!$A$2:$A$27,0)),IF($B8="Organics Recycling",INDEX('Materials Master'!$H$2:$H$27,MATCH($C8,'Materials Master'!$A$2:$A$27,0)),IF($B8="Cardboard Recycling",INDEX('Materials Master'!$I$2:$I$27,MATCH($C8,'Materials Master'!$A$2:$A$27,0)),IF($B8="Paper Recycling",INDEX('Materials Master'!$J$2:$J$27,MATCH($C8,'Materials Master'!$A$2:$A$27,0)),IF($B8="Terracycle",INDEX('Materials Master'!$K$2:$K$27,MATCH($C8,'Materials Master'!$A$2:$A$27,0)),"No"))))))="Yes",INDEX('Materials Master'!$E$2:$E$27,MATCH($C8,'Materials Master'!$A$2:$A$27,0))="Yes",$B8<>"Trash"),1,0) -> 0 | H8: =INDEX('Materials Master'!$E$2:$E$27,MATCH($C8,'Materials Master'!$A$2:$A$27,0)) -> No | I8: =IFERROR(INDEX(Areas!$C$2:$C$6,MATCH($A8,Areas!$B$2:$B$6,0)),"") -> Rest of Building | J8: =IF(IF($B8="Trash",INDEX('Materials Master'!$F$2:$F$27,MATCH($C8,'Materials Master'!$A$2:$A$27,0)),IF($B8="GMPC Recycling",INDEX('Materials Master'!$G$2:$G$27,MATCH($C8,'Materials Master'!$A$2:$A$27,0)),IF($B8="Organics Recycling",INDEX('Materials Master'!$H$2:$H$27,MATCH($C8,'Materials Master'!$A$2:$A$27,0)),IF($B8="Cardboard Recycling",INDEX('Materials Master'!$I$2:$I$27,MATCH($C8,'Materials Master'!$A$2:$A$27,0)),IF($B8="Paper Recycling",INDEX('Materials Master'!$J$2:$J$27,MATCH($C8,'Materials Master'!$A$2:$A$27,0)),IF($B8="Terracycle",INDEX('Materials Master'!$K$2:$K$27,MATCH($C8,'Materials Master'!$A$2:$A$27,0)),"No"))))))="Yes",1,0) -> 1
A9: OFFICES | B9: Trash | C9: FIB08 | D9: =IFERROR(INDEX('Materials Master'!$B$2:$B$27,MATCH($C9,'Materials Master'!$A$2:$A$27,0)),"") -> Paper Cups / Other Coated Paper Containers | E9: =IFERROR(INDEX('Materials Master'!$C$2:$C$27,MATCH($C9,'Materials Master'!$A$2:$A$27,0)),"") -> Fibers | F9: =IF(SUMIFS(Fact_SortedWeights!$E$2:$E$89,Fact_SortedWeights!$C$2:$C$89,$A9,Fact_SortedWeights!$B$2:$B$89,$B9)=0,0,SUMIFS(Fact_SortedWeights!$E$2:$E$89,Fact_SortedWeights!$C$2:$C$89,$A9,Fact_SortedWeights!$B$2:$B$89,$B9,Fact_SortedWeights!$D$2:$D$89,$C9)/SUMIFS(Fact_SortedWeights!$E$2:$E$89,Fact_SortedWeights!$C$2:$C$89,$A9,Fact_SortedWeights!$B$2:$B$89,$B9)*(IF($B9="Cardboard Recycling",SUMIFS(Fact_SortedWeights!$E$2:$E$89,Fact_SortedWeights!$C$2:$C$89,$A9,Fact_SortedWeights!$B$2:$B$89,$B9),SUMIFS(Fact_PreSortWeights!$E$2:$E$186,Fact_PreSortWeights!$C$2:$C$186,$A9,Fact_PreSortWeights!$B$2:$B$186,$B9)))) -> 4.2985114 | G9: =IF(AND(IF($B9="Trash",INDEX('Materials Master'!$F$2:$F$27,MATCH($C9,'Materials Master'!$A$2:$A$27,0)),IF($B9="GMPC Recycling",INDEX('Materials Master'!$G$2:$G$27,MATCH($C9,'Materials Master'!$A$2:$A$27,0)),IF($B9="Organics Recycling",INDEX('Materials Master'!$H$2:$H$27,MATCH($C9,'Materials Master'!$A$2:$A$27,0)),IF($B9="Cardboard Recycling",INDEX('Materials Master'!$I$2:$I$27,MATCH($C9,'Materials Master'!$A$2:$A$27,0)),IF($B9="Paper Recycling",INDEX('Materials Master'!$J$2:$J$27,MATCH($C9,'Materials Master'!$A$2:$A$27,0)),IF($B9="Terracycle",INDEX('Materials Master'!$K$2:$K$27,MATCH($C9,'Materials Master'!$A$2:$A$27,0)),"No"))))))="Yes",INDEX('Materials Master'!$E$2:$E$27,MATCH($C9,'Materials Master'!$A$2:$A$27,0))="Yes",$B9<>"Trash"),1,0) -> 0 | H9: =INDEX('Materials Master'!$E$2:$E$27,MATCH($C9,'Materials Master'!$A$2:$A$27,0)) -> No | I9: =IFERROR(INDEX(Areas!$C$2:$C$6,MATCH($A9,Areas!$B$2:$B$6,0)),"") -> Rest of Building | J9: =IF(IF($B9="Trash",INDEX('Materials Master'!$F$2:$F$27,MATCH($C9,'Materials Master'!$A$2:$A$27,0)),IF($B9="GMPC Recycling",INDEX('Materials Master'!$G$2:$G$27,MATCH($C9,'Materials Master'!$A$2:$A$27,0)),IF($B9="Organics Recycling",INDEX('Materials Master'!$H$2:$H$27,MATCH($C9,'Materials Master'!$A$2:$A$27,0)),IF($B9="Cardboard Recycling",INDEX('Materials Master'!$I$2:$I$27,MATCH($C9,'Materials Master'!$A$2:$A$27,0)),IF($B9="Paper Recycling",INDEX('Materials Master'!$J$2:$J$27,MATCH($C9,'Materials Master'!$A$2:$A$27,0)),IF($B9="Terracycle",INDEX('Materials Master'!$K$2:$K$27,MATCH($C9,'Materials Master'!$A$2:$A$27,0)),"No"))))))="Yes",1,0) -> 1
A10: OFFICES | B10: Trash | C10: GLA01 | D10: =IFERROR(INDEX('Materials Master'!$B$2:$B$27,MATCH($C10,'Materials Master'!$A$2:$A$27,0)),"") -> Glass Bottles & Jars | E10: =IFERROR(INDEX('Materials Master'!$C$2:$C$27,MATCH($C10,'Materials Master'!$A$2:$A$27,0)),"") -> Glass | F10: =IF(SUMIFS(Fact_SortedWeights!$E$2:$E$89,Fact_SortedWeights!$C$2:$C$89,$A10,Fact_SortedWeights!$B$2:$B$89,$B10)=0,0,SUMIFS(Fact_SortedWeights!$E$2:$E$89,Fact_SortedWeights!$C$2:$C$89,$A10,Fact_SortedWeights!$B$2:$B$89,$B10,Fact_SortedWeights!$D$2:$D$89,$C10)/SUMIFS(Fact_SortedWeights!$E$2:$E$89,Fact_SortedWeights!$C$2:$C$89,$A10,Fact_SortedWeights!$B$2:$B$89,$B10)*(IF($B10="Cardboard Recycling",SUMIFS(Fact_SortedWeights!$E$2:$E$89,Fact_SortedWeights!$C$2:$C$89,$A10,Fact_SortedWeights!$B$2:$B$89,$B10),SUMIFS(Fact_PreSortWeights!$E$2:$E$186,Fact_PreSortWeights!$C$2:$C$186,$A10,Fact_PreSortWeights!$B$2:$B$186,$B10)))) -> 3.0136385 | G10: =IF(AND(IF($B10="Trash",INDEX('Materials Master'!$F$2:$F$27,MATCH($C10,'Materials Master'!$A$2:$A$27,0)),IF($B10="GMPC Recycling",INDEX('Materials Master'!$G$2:$G$27,MATCH($C10,'Materials Master'!$A$2:$A$27,0)),IF($B10="Organics Recycling",INDEX('Materials Master'!$H$2:$H$27,MATCH($C10,'Materials Master'!$A$2:$A$27,0)),IF($B10="Cardboard Recycling",INDEX('Materials Master'!$I$2:$I$27,MATCH($C10,'Materials Master'!$A$2:$A$27,0)),IF($B10="Paper Recycling",INDEX('Materials Master'!$J$2:$J$27,MATCH($C10,'Materials Master'!$A$2:$A$27,0)),IF($B10="Terracycle",INDEX('Materials Master'!$K$2:$K$27,MATCH($C10,'Materials Master'!$A$2:$A$27,0)),"No"))))))="Yes",INDEX('Materials Master'!$E$2:$E$27,MATCH($C10,'Materials Master'!$A$2:$A$27,0))="Yes",$B10<>"Trash"),1,0) -> 0 | H10: =INDEX('Materials Master'!$E$2:$E$27,MATCH($C10,'Materials Master'!$A$2:$A$27,0)) -> Yes | I10: =IFERROR(INDEX(Areas!$C$2:$C$6,MATCH($A10,Areas!$B$2:$B$6,0)),"") -> Rest of Building | J10: =IF(IF($B10="Trash",INDEX('Materials Master'!$F$2:$F$27,MATCH($C10,'Materials Master'!$A$2:$A$27,0)),IF($B10="GMPC Recycling",INDEX('Materials Master'!$G$2:$G$27,MATCH($C10,'Materials Master'!$A$2:$A$27,0)),IF($B10="Organics Recycling",INDEX('Materials Master'!$H$2:$H$27,MATCH($C10,'Materials Master'!$A$2:$A$27,0)),IF($B10="Cardboard Recycling",INDEX('Materials Master'!$I$2:$I$27,MATCH($C10,'Materials Master'!$A$2:$A$27,0)),IF($B10="Paper Recycling",INDEX('Materials Master'!$J$2:$J$27,MATCH($C10,'Materials Master'!$A$2:$A$27,0)),IF($B10="Terracycle",INDEX('Materials Master'!$K$2:$K$27,MATCH($C10,'Materials Master'!$A$2:$A$27,0)),"No"))))))="Yes",1,0) -> 0
A11: OFFICES | B11: Trash | C11: GLA02 | D11: =IFERROR(INDEX('Materials Master'!$B$2:$B$27,MATCH($C11,'Materials Master'!$A$2:$A$27,0)),"") -> Soiled Glass | E11: =IFERROR(INDEX('Materials Master'!$C$2:$C$27,MATCH($C11,'Materials Master'!$A$2:$A$27,0)),"") -> Glass | F11: =IF(SUMIFS(Fact_SortedWeights!$E$2:$E$89,Fact_SortedWeights!$C$2:$C$89,$A11,Fact_SortedWeights!$B$2:$B$89,$B11)=0,0,SUMIFS(Fact_SortedWeights!$E$2:$E$89,Fact_SortedWeights!$C$2:$C$89,$A11,Fact_SortedWeights!$B$2:$B$89,$B11,Fact_SortedWeights!$D$2:$D$89,$C11)/SUMIFS(Fact_SortedWeights!$E$2:$E$89,Fact_SortedWeights!$C$2:$C$89,$A11,Fact_SortedWeights!$B$2:$B$89,$B11)*(IF($B11="Cardboard Recycling",SUMIFS(Fact_SortedWeights!$E$2:$E$89,Fact_SortedWeights!$C$2:$C$89,$A11,Fact_SortedWeights!$B$2:$B$89,$B11),SUMIFS(Fact_PreSortWeights!$E$2:$E$186,Fact_PreSortWeights!$C$2:$C$186,$A11,Fact_PreSortWeights!$B$2:$B$186,$B11)))) -> 0 | G11: =IF(AND(IF($B11="Trash",INDEX('Materials Master'!$F$2:$F$27,MATCH($C11,'Materials Master'!$A$2:$A$27,0)),IF($B11="GMPC Recycling",INDEX('Materials Master'!$G$2:$G$27,MATCH($C11,'Materials Master'!$A$2:$A$27,0)),IF($B11="Organics Recycling",INDEX('Materials Master'!$H$2:$H$27,MATCH($C11,'Materials Master'!$A$2:$A$27,0)),IF($B11="Cardboard Recycling",INDEX('Materials Master'!$I$2:$I$27,MATCH($C11,'Materials Master'!$A$2:$A$27,0)),IF($B11="Paper Recycling",INDEX('Materials Master'!$J$2:$J$27,MATCH($C11,'Materials Master'!$A$2:$A$27,0)),IF($B11="Terracycle",INDEX('Materials Master'!$K$2:$K$27,MATCH($C11,'Materials Master'!$A$2:$A$27,0)),"No"))))))="Yes",INDEX('Materials Master'!$E$2:$E$27,MATCH($C11,'Materials Master'!$A$2:$A$27,0))="Yes",$B11<>"Trash"),1,0) -> 0 | H11: =INDEX('Materials Master'!$E$2:$E$27,MATCH($C11,'Materials Master'!$A$2:$A$27,0)) -> No | I11: =IFERROR(INDEX(Areas!$C$2:$C$6,MATCH($A11,Areas!$B$2:$B$6,0)),"") -> Rest of Building | J11: =IF(IF($B11="Trash",INDEX('Materials Master'!$F$2:$F$27,MATCH($C11,'Materials Master'!$A$2:$A$27,0)),IF($B11="GMPC Recycling",INDEX('Materials Master'!$G$2:$G$27,MATCH($C11,'Materials Master'!$A$2:$A$27,0)),IF($B11="Organics Recycling",INDEX('Materials Master'!$H$2:$H$27,MATCH($C11,'Materials Master'!$A$2:$A$27,0)),IF($B11="Cardboard Recycling",INDEX('Materials Master'!$I$2:$I$27,MATCH($C11,'Materials Master'!$A$2:$A$27,0)),IF($B11="Paper Recycling",INDEX('Materials Master'!$J$2:$J$27,MATCH($C11,'Materials Master'!$A$2:$A$27,0)),IF($B11="Terracycle",INDEX('Materials Master'!$K$2:$K$27,MATCH($C11,'Materials Master'!$A$2:$A$27,0)),"No"))))))="Yes",1,0) -> 1
A12: OFFICES | B12: Trash | C12: MET01 | D12: =IFERROR(INDEX('Materials Master'!$B$2:$B$27,MATCH($C12,'Materials Master'!$A$2:$A$27,0)),"") -> Aluminum & Bi-Metal Containers | E12: =IFERROR(INDEX('Materials Master'!$C$2:$C$27,MATCH($C12,'Materials Master'!$A$2:$A$27,0)),"") -> Metals | F12: =IF(SUMIFS(Fact_SortedWeights!$E$2:$E$89,Fact_SortedWeights!$C$2:$C$89,$A12,Fact_SortedWeights!$B$2:$B$89,$B12)=0,0,SUMIFS(Fact_SortedWeights!$E$2:$E$89,Fact_SortedWeights!$C$2:$C$89,$A12,Fact_SortedWeights!$B$2:$B$89,$B12,Fact_SortedWeights!$D$2:$D$89,$C12)/SUMIFS(Fact_SortedWeights!$E$2:$E$89,Fact_SortedWeights!$C$2:$C$89,$A12,Fact_SortedWeights!$B$2:$B$89,$B12)*(IF($B12="Cardboard Recycling",SUMIFS(Fact_SortedWeights!$E$2:$E$89,Fact_SortedWeights!$C$2:$C$89,$A12,Fact_SortedWeights!$B$2:$B$89,$B12),SUMIFS(Fact_PreSortWeights!$E$2:$E$186,Fact_PreSortWeights!$C$2:$C$186,$A12,Fact_PreSortWeights!$B$2:$B$186,$B12)))) -> 0 | G12: =IF(AND(IF($B12="Trash",INDEX('Materials Master'!$F$2:$F$27,MATCH($C12,'Materials Master'!$A$2:$A$27,0)),IF($B12="GMPC Recycling",INDEX('Materials Master'!$G$2:$G$27,MATCH($C12,'Materials Master'!$A$2:$A$27,0)),IF($B12="Organics Recycling",INDEX('Materials Master'!$H$2:$H$27,MATCH($C12,'Materials Master'!$A$2:$A$27,0)),IF($B12="Cardboard Recycling",INDEX('Materials Master'!$I$2:$I$27,MATCH($C12,'Materials Master'!$A$2:$A$27,0)),IF($B12="Paper Recycling",INDEX('Materials Master'!$J$2:$J$27,MATCH($C12,'Materials Master'!$A$2:$A$27,0)),IF($B12="Terracycle",INDEX('Materials Master'!$K$2:$K$27,MATCH($C12,'Materials Master'!$A$2:$A$27,0)),"No"))))))="Yes",INDEX('Materials Master'!$E$2:$E$27,MATCH($C12,'Materials Master'!$A$2:$A$27,0))="Yes",$B12<>"Trash"),1,0) -> 0 | H12: =INDEX('Materials Master'!$E$2:$E$27,MATCH($C12,'Materials Master'!$A$2:$A$27,0)) -> Yes | I12: =IFERROR(INDEX(Areas!$C$2:$C$6,MATCH($A12,Areas!$B$2:$B$6,0)),"") -> Rest of Building | J12: =IF(IF($B12="Trash",INDEX('Materials Master'!$F$2:$F$27,MATCH($C12,'Materials Master'!$A$2:$A$27,0)),IF($B12="GMPC Recycling",INDEX('Materials Master'!$G$2:$G$27,MATCH($C12,'Materials Master'!$A$2:$A$27,0)),IF($B12="Organics Recycling",INDEX('Materials Master'!$H$2:$H$27,MATCH($C12,'Materials Master'!$A$2:$A$27,0)),IF($B12="Cardboard Recycling",INDEX('Materials Master'!$I$2:$I$27,MATCH($C12,'Materials Master'!$A$2:$A$27,0)),IF($B12="Paper Recycling",INDEX('Materials Master'!$J$2:$J$27,MATCH($C12,'Materials Master'!$A$2:$A$27,0)),IF($B12="Terracycle",INDEX('Materials Master'!$K$2:$K$27,MATCH($C12,'Materials Master'!$A$2:$A$27,0)),"No"))))))="Yes",1,0) -> 0
A13: OFFICES | B13: Trash | C13: MET02 | D13: =IFERROR(INDEX('Materials Master'!$B$2:$B$27,MATCH($C13,'Materials Master'!$A$2:$A$27,0)),"") -> Soiled Metals | E13: =IFERROR(INDEX('Materials Master'!$C$2:$C$27,MATCH($C13,'Materials Master'!$A$2:$A$27,0)),"") -> Metals | F13: =IF(SUMIFS(Fact_SortedWeights!$E$2:$E$89,Fact_SortedWeights!$C$2:$C$89,$A13,Fact_SortedWeights!$B$2:$B$89,$B13)=0,0,SUMIFS(Fact_SortedWeights!$E$2:$E$89,Fact_SortedWeights!$C$2:$C$89,$A13,Fact_SortedWeights!$B$2:$B$89,$B13,Fact_SortedWeights!$D$2:$D$89,$C13)/SUMIFS(Fact_SortedWeights!$E$2:$E$89,Fact_SortedWeights!$C$2:$C$89,$A13,Fact_SortedWeights!$B$2:$B$89,$B13)*(IF($B13="Cardboard Recycling",SUMIFS(Fact_SortedWeights!$E$2:$E$89,Fact_SortedWeights!$C$2:$C$89,$A13,Fact_SortedWeights!$B$2:$B$89,$B13),SUMIFS(Fact_PreSortWeights!$E$2:$E$186,Fact_PreSortWeights!$C$2:$C$186,$A13,Fact_PreSortWeights!$B$2:$B$186,$B13)))) -> 0 | G13: =IF(AND(IF($B13="Trash",INDEX('Materials Master'!$F$2:$F$27,MATCH($C13,'Materials Master'!$A$2:$A$27,0)),IF($B13="GMPC Recycling",INDEX('Materials Master'!$G$2:$G$27,MATCH($C13,'Materials Master'!$A$2:$A$27,0)),IF($B13="Organics Recycling",INDEX('Materials Master'!$H$2:$H$27,MATCH($C13,'Materials Master'!$A$2:$A$27,0)),IF($B13="Cardboard Recycling",INDEX('Materials Master'!$I$2:$I$27,MATCH($C13,'Materials Master'!$A$2:$A$27,0)),IF($B13="Paper Recycling",INDEX('Materials Master'!$J$2:$J$27,MATCH($C13,'Materials Master'!$A$2:$A$27,0)),IF($B13="Terracycle",INDEX('Materials Master'!$K$2:$K$27,MATCH($C13,'Materials Master'!$A$2:$A$27,0)),"No"))))))="Yes",INDEX('Materials Master'!$E$2:$E$27,MATCH($C13,'Materials Master'!$A$2:$A$27,0))="Yes",$B13<>"Trash"),1,0) -> 0 | H13: =INDEX('Materials Master'!$E$2:$E$27,MATCH($C13,'Materials Master'!$A$2:$A$27,0)) -> No | I13: =IFERROR(INDEX(Areas!$C$2:$C$6,MATCH($A13,Areas!$B$2:$B$6,0)),"") -> Rest of Building | J13: =IF(IF($B13="Trash",INDEX('Materials Master'!$F$2:$F$27,MATCH($C13,'Materials Master'!$A$2:$A$27,0)),IF($B13="GMPC Recycling",INDEX('Materials Master'!$G$2:$G$27,MATCH($C13,'Materials Master'!$A$2:$A$27,0)),IF($B13="Organics Recycling",INDEX('Materials Master'!$H$2:$H$27,MATCH($C13,'Materials Master'!$A$2:$A$27,0)),IF($B13="Cardboard Recycling",INDEX('Materials Master'!$I$2:$I$27,MATCH($C13,'Materials Master'!$A$2:$A$27,0)),IF($B13="Paper Recycling",INDEX('Materials Master'!$J$2:$J$27,MATCH($C13,'Materials Master'!$A$2:$A$27,0)),IF($B13="Terracycle",INDEX('Materials Master'!$K$2:$K$27,MATCH($C13,'Materials Master'!$A$2:$A$27,0)),"No"))))))="Yes",1,0) -> 1
... A781: BATHROOM | B781: Terracycle | C781: OTH02 | D781: =IFERROR(INDEX('Materials Master'!$B$2:$B$27,MATCH($C781,'Materials Master'!$A$2:$A$27,0)),"") -> Other/Residual Materials | E781: =IFERROR(INDEX('Materials Master'!$C$2:$C$27,MATCH($C781,'Materials Master'!$A$2:$A$27,0)),"") -> Other | F781: =IF(SUMIFS(Fact_SortedWeights!$E$2:$E$89,Fact_SortedWeights!$C$2:$C$89,$A781,Fact_SortedWeights!$B$2:$B$89,$B781)=0,0,SUMIFS(Fact_SortedWeights!$E$2:$E$89,Fact_SortedWeights!$C$2:$C$89,$A781,Fact_SortedWeights!$B$2:$B$89,$B781,Fact_SortedWeights!$D$2:$D$89,$C781)/SUMIFS(Fact_SortedWeights!$E$2:$E$89,Fact_SortedWeights!$C$2:$C$89,$A781,Fact_SortedWeights!$B$2:$B$89,$B781)*(IF($B781="Cardboard Recycling",SUMIFS(Fact_SortedWeights!$E$2:$E$89,Fact_SortedWeights!$C$2:$C$89,$A781,Fact_SortedWeights!$B$2:$B$89,$B781),SUMIFS(Fact_PreSortWeights!$E$2:$E$186,Fact_PreSortWeights!$C$2:$C$186,$A781,Fact_PreSortWeights!$B$2:$B$186,$B781)))) -> 0 | G781: =IF(AND(IF($B781="Trash",INDEX('Materials Master'!$F$2:$F$27,MATCH($C781,'Materials Master'!$A$2:$A$27,0)),IF($B781="GMPC Recycling",INDEX('Materials Master'!$G$2:$G$27,MATCH($C781,'Materials Master'!$A$2:$A$27,0)),IF($B781="Organics Recycling",INDEX('Materials Master'!$H$2:$H$27,MATCH($C781,'Materials Master'!$A$2:$A$27,0)),IF($B781="Cardboard Recycling",INDEX('Materials Master'!$I$2:$I$27,MATCH($C781,'Materials Master'!$A$2:$A$27,0)),IF($B781="Paper Recycling",INDEX('Materials Master'!$J$2:$J$27,MATCH($C781,'Materials Master'!$A$2:$A$27,0)),IF($B781="Terracycle",INDEX('Materials Master'!$K$2:$K$27,MATCH($C781,'Materials Master'!$A$2:$A$27,0)),"No"))))))="Yes",INDEX('Materials Master'!$E$2:$E$27,MATCH($C781,'Materials Master'!$A$2:$A$27,0))="Yes",$B781<>"Trash"),1,0) -> 0 | H781: =INDEX('Materials Master'!$E$2:$E$27,MATCH($C781,'Materials Master'!$A$2:$A$27,0)) -> No | I781: =IFERROR(INDEX(Areas!$C$2:$C$6,MATCH($A781,Areas!$B$2:$B$6,0)),"") -> Rest of Building | J781: =IF(IF($B781="Trash",INDEX('Materials Master'!$F$2:$F$27,MATCH($C781,'Materials Master'!$A$2:$A$27,0)),IF($B781="GMPC Recycling",INDEX('Materials Master'!$G$2:$G$27,MATCH($C781,'Materials Master'!$A$2:$A$27,0)),IF($B781="Organics Recycling",INDEX('Materials Master'!$H$2:$H$27,MATCH($C781,'Materials Master'!$A$2:$A$27,0)),IF($B781="Cardboard Recycling",INDEX('Materials Master'!$I$2:$I$27,MATCH($C781,'Materials Master'!$A$2:$A$27,0)),IF($B781="Paper Recycling",INDEX('Materials Master'!$J$2:$J$27,MATCH($C781,'Materials Master'!$A$2:$A$27,0)),IF($B781="Terracycle",INDEX('Materials Master'!$K$2:$K$27,MATCH($C781,'Materials Master'!$A$2:$A$27,0)),"No"))))))="Yes",1,0) -> 0

Sheet Overall Summary
A1: Total Waste Generation — Day of Audit
A2: Waste Stream | B2: Waste Stream Weight (lbs.) | C2: % of Total Waste Stream | D2: Weight of Material Diverted (lbs.) | E2: % of Material Diverted
A3: Trash | B3: =SUMIFS(Fact_PreSortWeights!$E$2:$E$186,Fact_PreSortWeights!$C$2:$C$186,"OFFICES",Fact_PreSortWeights!$B$2:$B$186,"Trash")+SUMIFS(Fact_PreSortWeights!$E$2:$E$186,Fact_PreSortWeights!$C$2:$C$186,"CAFÉ BOH",Fact_PreSortWeights!$B$2:$B$186,"Trash")+SUMIFS(Fact_PreSortWeights!$E$2:$E$186,Fact_PreSortWeights!$C$2:$C$186,"LOCATION C",Fact_PreSortWeights!$B$2:$B$186,"Trash")+SUMIFS(Fact_PreSortWeights!$E$2:$E$186,Fact_PreSortWeights!$C$2:$C$186,"LOCATION D",Fact_PreSortWeights!$B$2:$B$186,"Trash") -> 1823.3 | C3: =IF($B$10=0,0,B3/$B$10) -> 0.59178322 | D3: =SUMIFS(Fact_Extrapolated!$F$2:$F$781,Fact_Extrapolated!$B$2:$B$781,A3,Fact_Extrapolated!$G$2:$G$781,1) -> 0
A4: GMPC Recycling | B4: =SUMIFS(Fact_PreSortWeights!$E$2:$E$186,Fact_PreSortWeights!$C$2:$C$186,"OFFICES",Fact_PreSortWeights!$B$2:$B$186,"GMPC Recycling")+SUMIFS(Fact_PreSortWeights!$E$2:$E$186,Fact_PreSortWeights!$C$2:$C$186,"CAFÉ BOH",Fact_PreSortWeights!$B$2:$B$186,"GMPC Recycling")+SUMIFS(Fact_PreSortWeights!$E$2:$E$186,Fact_PreSortWeights!$C$2:$C$186,"LOCATION C",Fact_PreSortWeights!$B$2:$B$186,"GMPC Recycling")+SUMIFS(Fact_PreSortWeights!$E$2:$E$186,Fact_PreSortWeights!$C$2:$C$186,"LOCATION D",Fact_PreSortWeights!$B$2:$B$186,"GMPC Recycling") -> 45.2 | C4: =IF($B$10=0,0,B4/$B$10) -> 0.014670434 | D4: =SUMIFS(Fact_Extrapolated!$F$2:$F$781,Fact_Extrapolated!$B$2:$B$781,A4,Fact_Extrapolated!$G$2:$G$781,1) -> 9.4335475
A5: Organics Recycling | B5: =SUMIFS(Fact_PreSortWeights!$E$2:$E$186,Fact_PreSortWeights!$C$2:$C$186,"OFFICES",Fact_PreSortWeights!$B$2:$B$186,"Organics Recycling")+SUMIFS(Fact_PreSortWeights!$E$2:$E$186,Fact_PreSortWeights!$C$2:$C$186,"CAFÉ BOH",Fact_PreSortWeights!$B$2:$B$186,"Organics Recycling")+SUMIFS(Fact_PreSortWeights!$E$2:$E$186,Fact_PreSortWeights!$C$2:$C$186,"LOCATION C",Fact_PreSortWeights!$B$2:$B$186,"Organics Recycling")+SUMIFS(Fact_PreSortWeights!$E$2:$E$186,Fact_PreSortWeights!$C$2:$C$186,"LOCATION D",Fact_PreSortWeights!$B$2:$B$186,"Organics Recycling") -> 635.5 | C5: =IF($B$10=0,0,B5/$B$10) -> 0.2062624 | D5: =SUMIFS(Fact_Extrapolated!$F$2:$F$781,Fact_Extrapolated!$B$2:$B$781,A5,Fact_Extrapolated!$G$2:$G$781,1) -> 247.30753
A6: Cardboard Recycling | B6: =SUMIFS(Fact_SortedWeights!$E$2:$E$89,Fact_SortedWeights!$C$2:$C$89,"OFFICES",Fact_SortedWeights!$B$2:$B$89,"Cardboard Recycling")+SUMIFS(Fact_SortedWeights!$E$2:$E$89,Fact_SortedWeights!$C$2:$C$89,"CAFÉ BOH",Fact_SortedWeights!$B$2:$B$89,"Cardboard Recycling")+SUMIFS(Fact_SortedWeights!$E$2:$E$89,Fact_SortedWeights!$C$2:$C$89,"LOCATION C",Fact_SortedWeights!$B$2:$B$89,"Cardboard Recycling")+SUMIFS(Fact_SortedWeights!$E$2:$E$89,Fact_SortedWeights!$C$2:$C$89,"LOCATION D",Fact_SortedWeights!$B$2:$B$89,"Cardboard Recycling") -> 349.82687 | C6: =IF($B$10=0,0,B6/$B$10) -> 0.1135423 | D6: =SUMIFS(Fact_Extrapolated!$F$2:$F$781,Fact_Extrapolated!$B$2:$B$781,A6,Fact_Extrapolated!$G$2:$G$781,1) -> 335.14312
A7: Paper Recycling | B7: =SUMIFS(Fact_PreSortWeights!$E$2:$E$186,Fact_PreSortWeights!$C$2:$C$186,"OFFICES",Fact_PreSortWeights!$B$2:$B$186,"Paper Recycling")+SUMIFS(Fact_PreSortWeights!$E$2:$E$186,Fact_PreSortWeights!$C$2:$C$186,"CAFÉ BOH",Fact_PreSortWeights!$B$2:$B$186,"Paper Recycling")+SUMIFS(Fact_PreSortWeights!$E$2:$E$186,Fact_PreSortWeights!$C$2:$C$186,"LOCATION C",Fact_PreSortWeights!$B$2:$B$186,"Paper Recycling")+SUMIFS(Fact_PreSortWeights!$E$2:$E$186,Fact_PreSortWeights!$C$2:$C$186,"LOCATION D",Fact_PreSortWeights!$B$2:$B$186,"Paper Recycling") -> 16.7 | C7: =IF($B$10=0,0,B7/$B$10) -> 0.0054202708 | D7: =SUMIFS(Fact_Extrapolated!$F$2:$F$781,Fact_Extrapolated!$B$2:$B$781,A7,Fact_Extrapolated!$G$2:$G$781,1) -> 16.623547
A8: Terracycle | B8: =SUMIFS(Fact_PreSortWeights!$E$2:$E$186,Fact_PreSortWeights!$C$2:$C$186,"OFFICES",Fact_PreSortWeights!$B$2:$B$186,"Terracycle")+SUMIFS(Fact_PreSortWeights!$E$2:$E$186,Fact_PreSortWeights!$C$2:$C$186,"CAFÉ BOH",Fact_PreSortWeights!$B$2:$B$186,"Terracycle")+SUMIFS(Fact_PreSortWeights!$E$2:$E$186,Fact_PreSortWeights!$C$2:$C$186,"LOCATION C",Fact_PreSortWeights!$B$2:$B$186,"Terracycle")+SUMIFS(Fact_PreSortWeights!$E$2:$E$186,Fact_PreSortWeights!$C$2:$C$186,"LOCATION D",Fact_PreSortWeights!$B$2:$B$186,"Terracycle") -> 3.2 | C8: =IF($B$10=0,0,B8/$B$10) -> 0.0010386148 | D8: =SUMIFS(Fact_Extrapolated!$F$2:$F$781,Fact_Extrapolated!$B$2:$B$781,A8,Fact_Extrapolated!$G$2:$G$781,1) -> 3.0717999
A9: BATHROOM Waste | B9: =SUMIFS(Fact_PreSortWeights!$E$2:$E$186,Fact_PreSortWeights!$C$2:$C$186,"BATHROOM")+SUMIFS(Fact_SortedWeights!$E$2:$E$89,Fact_SortedWeights!$C$2:$C$89,"BATHROOM",Fact_SortedWeights!$B$2:$B$89,"Cardboard Recycling") -> 207.3 | C9: =IF($B$10=0,0,B9/$B$10) -> 0.067282763 | D9: 0
A10: Total | B10: =SUM(B3:B9) -> 3081.0269 | C10: =IF($B$10=0,0,B10/$B$10) -> 1 | D10: =SUM(D3:D9) -> 611.57955 | E10: =IF(B10=0,0,D10/B10) -> 0.19849861
A12: Waste Stream Breakdown — by Material Type
A13: Material Type Category | B13: Material Type | C13: Total Material Type Weight (lbs.) | D13: % of Total Waste Stream | E13: Weight of Material Diverted (lbs.) | F13: % of Material Diverted | G13: Currently Divertible?
A14: Fibers | B14: Corrugated Cardboard | C14: =SUMIFS(Fact_Extrapolated!$F$2:$F$781,Fact_Extrapolated!$C$2:$C$781,"FIB01") -> 301.78 | D14: =IF($B$10=0,0,C14/$B$10) -> 0.097947864 | E14: =SUMIFS(Fact_Extrapolated!$F$2:$F$781,Fact_Extrapolated!$C$2:$C$781,"FIB01",Fact_Extrapolated!$G$2:$G$781,1) -> 301.78 | F14: =IF(C14=0,0,E14/C14) -> 1 | G14: =INDEX('Materials Master'!$D$2:$D$27,MATCH(B14,'Materials Master'!$B$2:$B$27,0)) -> Yes
B15: Soiled Cardboard | C15: =SUMIFS(Fact_Extrapolated!$F$2:$F$781,Fact_Extrapolated!$C$2:$C$781,"FIB02") -> 0 | D15: =IF($B$10=0,0,C15/$B$10) -> 0 | E15: =SUMIFS(Fact_Extrapolated!$F$2:$F$781,Fact_Extrapolated!$C$2:$C$781,"FIB02",Fact_Extrapolated!$G$2:$G$781,1) -> 0 | F15: =IF(C15=0,0,E15/C15) -> 0 | G15: =INDEX('Materials Master'!$D$2:$D$27,MATCH(B15,'Materials Master'!$B$2:$B$27,0)) -> No
B16: Waxed Cardboard | C16: =SUMIFS(Fact_Extrapolated!$F$2:$F$781,Fact_Extrapolated!$C$2:$C$781,"FIB03") -> 4.4 | D16: =IF($B$10=0,0,C16/$B$10) -> 0.0014280953 | E16: =SUMIFS(Fact_Extrapolated!$F$2:$F$781,Fact_Extrapolated!$C$2:$C$781,"FIB03",Fact_Extrapolated!$G$2:$G$781,1) -> 0 | F16: =IF(C16=0,0,E16/C16) -> 0 | G16: =INDEX('Materials Master'!$D$2:$D$27,MATCH(B16,'Materials Master'!$B$2:$B$27,0)) -> No
