Workbook

Sheet Audit Info
A1: Audit Info
A3: Client Name | B3: Cushman & Wakefield
A4: Site Name | B4: 730 Third Ave
A5: Site Address | B5: 730 Third Ave, New York, NY 10017
A6: Hauler
A7: Tenant/Area Breakouts | B7: Cafeteria, Base Building
A8: Auditors | B8: Great Forest — Inga Guliyeva, Emilie Fuchs
A9: Audit Date | B9: 2025-07-15
A10: Site Occupancy
A11: Source | B11: Collected via tablet field form

Sheet Materials Master
A1: material_id | B1: material_name | C1: material_category | D1: currently_divertible | E1: accepted_in_program | F1: target: Trash | G1: target: GMPC Recycling | H1: target: Organics Recycling | I1: target: Cardboard Recycling | J1: target: Paper Recycling | K1: target: Terracycle
A2: FIB01 | B2: Corrugated Cardboard | C2: Fibers | D2: Yes | E2: Yes | F2: No | G2: Yes | H2: No | I2: Yes | J2: No | K2: No
A3: FIB02 | B3: Waxed Cardboard | C3: Fibers | D3: No | E3: No | F3: Yes | G3: No | H3: No | I3: No | J3: No | K3: No
A4: FIB03 | B4: Mixed Paper | C4: Fibers | D4: Yes | E4: Yes | F4: No | G4: Yes | H4: Yes | I4: No | J4: No | K4: No
A5: FIB04 | B5: Gable-top & Aseptic Cartons | C5: Fibers | D5: Yes | E5: Yes | F5: No | G5: Yes | H5: No | I5: No | J5: No | K5: No
A6: FIB05 | B6: Other Coated Paper Containers | C6: Fibers | D6: No | E6: No | F6: Yes | G6: No | H6: No | I6: No | J6: No | K6: No
A7: GLA01 | B7: Glass Bottles & Jars | C7: Glass | D7: Yes | E7: Yes | F7: No | G7: Yes | H7: No | I7: No | J7: No | K7: No
A8: GLA02 | B8: Broken Glass | C8: Glass | D8: No | E8: No | F8: Yes | G8: No | H8: No | I8: No | J8: No | K8: No
A9: MET01 | B9: Aluminum & Bi-metal Containers | C9: Metals | D9: Yes | E9: Yes | F9: No | G9: Yes | H9: No | I9: No | J9: No | K9: No
A10: MET02 | B10: Metal Hangers | C10: Metals | D10: No | E10: No | F10: Yes | G10: No | H10: No | I10: No | J10: No | K10: No
A11: PLA01 | B11: Rigid Plastics (1-6) | C11: Plastics | D11: Yes | E11: Yes | F11: No | G11: Yes | H11: No | I11: No | J11: No | K11: No
A12: PLA02 | B12: Soiled Rigid Plastics | C12: Plastics | D12: No | E12: No | F12: Yes | G12: No | H12: No | I12: No | J12: No | K12: No
... A20: OTH01 | B20: Residual Materials | C20: Other | D20: No | E20: No | F20: Yes | G20: No | H20: No | I20: No | J20: No | K20: No

Sheet Areas
A1: area_id | B1: area_name | C1: rollup_group
A2: CAFETERIA | B2: Cafeteria | C2: Cafeteria
A3: BASE_BLDG | B3: Base Building | C3: Base Building

Sheet Streams
A1: stream_name
A2: Trash
A3: GMPC Recycling
A4: Organics Recycling
A5: Cardboard Recycling
A6: Paper Recycling
A7: Terracycle

Sheet Fact_SortedWeights
A1: audit_id | B1: stream | C1: area | D1: material_id | E1: weight_lbs | F1: material_name | G1: material_category | H1: currently_divertible | I1: accepted_in_program | J1: belongs_here | K1: rollup_group | L1: notes
A2: 120PARK-2025 | B2: Trash | C2: Cafeteria | D2: FIB03 | E2: 4.69 | F2: =IFERROR(INDEX('Materials Master'!$B$2:$B$20,MATCH(D2,'Materials Master'!$A$2:$A$20,0)),"") -> Mixed Paper | G2: =IFERROR(INDEX('Materials Master'!$C$2:$C$20,MATCH(D2,'Materials Master'!$A$2:$A$20,0)),"") -> Fibers | H2: =IFERROR(INDEX('Materials Master'!$D$2:$D$20,MATCH(D2,'Materials Master'!$A$2:$A$20,0)),"") -> Yes | I2: =IFERROR(INDEX('Materials Master'!$E$2:$E$20,MATCH(D2,'Materials Master'!$A$2:$A$20,0)),"") -> Yes | J2: =IFERROR(IF(B2="Trash",INDEX('Materials Master'!$F$2:$F$20,MATCH(D2,'Materials Master'!$A$2:$A$20,0)),IF(B2="GMPC Recycling",INDEX('Materials Master'!$G$2:$G$20,MATCH(D2,'Materials Master'!$A$2:$A$20,0)),IF(B2="Organics Recycling",INDEX('Materials Master'!$H$2:$H$20,MATCH(D2,'Materials Master'!$A$2:$A$20,0)),IF(B2="Cardboard Recycling",INDEX('Materials Master'!$I$2:$I$20,MATCH(D2,'Materials Master'!$A$2:$A$20,0)),IF(B2="Paper Recycling",INDEX('Materials Master'!$J$2:$J$20,MATCH(D2,'Materials Master'!$A$2:$A$20,0)),IF(B2="Terracycle",INDEX('Materials Master'!$K$2:$K$20,MATCH(D2,'Materials Master'!$A$2:$A$20,0)),"No")))))),"") -> No | K2: =IFERROR(INDEX(Areas!$C$2:$C$3,MATCH(C2,Areas!$B$2:$B$3,0)),"") -> Cafeteria
A3: 120PARK-2025 | B3: Trash | C3: Cafeteria | D3: FIB04 | E3: 4.02 | F3: =IFERROR(INDEX('Materials Master'!$B$2:$B$20,MATCH(D3,'Materials Master'!$A$2:$A$20,0)),"") -> Gable-top & Aseptic Cartons | G3: =IFERROR(INDEX('Materials Master'!$C$2:$C$20,MATCH(D3,'Materials Master'!$A$2:$A$20,0)),"") -> Fibers | H3: =IFERROR(INDEX('Materials Master'!$D$2:$D$20,MATCH(D3,'Materials Master'!$A$2:$A$20,0)),"") -> Yes | I3: =IFERROR(INDEX('Materials Master'!$E$2:$E$20,MATCH(D3,'Materials Master'!$A$2:$A$20,0)),"") -> Yes | J3: =IFERROR(IF(B3="Trash",INDEX('Materials Master'!$F$2:$F$20,MATCH(D3,'Materials Master'!$A$2:$A$20,0)),IF(B3="GMPC Recycling",INDEX('Materials Master'!$G$2:$G$20,MATCH(D3,'Materials Master'!$A$2:$A$20,0)),IF(B3="Organics Recycling",INDEX('Materials Master'!$H$2:$H$20,MATCH(D3,'Materials Master'!$A$2:$A$20,0)),IF(B3="Cardboard Recycling",INDEX('Materials Master'!$I$2:$I$20,MATCH(D3,'Materials Master'!$A$2:$A$20,0)),IF(B3="Paper Recycling",INDEX('Materials Master'!$J$2:$J$20,MATCH(D3,'Materials Master'!$A$2:$A$20,0)),IF(B3="Terracycle",INDEX('Materials Master'!$K$2:$K$20,MATCH(D3,'Materials Master'!$A$2:$A$20,0)),"No")))))),"") -> No | K3: =IFERROR(INDEX(Areas!$C$2:$C$3,MATCH(C3,Areas!$B$2:$B$3,0)),"") -> Cafeteria
A4: 120PARK-2025 | B4: Trash | C4: Cafeteria | D4: FIB05 | E4: 1 | F4: =IFERROR(INDEX('Materials Master'!$B$2:$B$20,MATCH(D4,'Materials Master'!$A$2:$A$20,0)),"") -> Other Coated Paper Containers | G4: =IFERROR(INDEX('Materials Master'!$C$2:$C$20,MATCH(D4,'Materials Master'!$A$2:$A$20,0)),"") -> Fibers | H4: =IFERROR(INDEX('Materials Master'!$D$2:$D$20,MATCH(D4,'Materials Master'!$A$2:$A$20,0)),"") -> No | I4: =IFERROR(INDEX('Materials Master'!$E$2:$E$20,MATCH(D4,'Materials Master'!$A$2:$A$20,0)),"") -> No | J4: =IFERROR(IF(B4="Trash",INDEX('Materials Master'!$F$2:$F$20,MATCH(D4,'Materials Master'!$A$2:$A$20,0)),IF(B4="GMPC Recycling",INDEX('Materials Master'!$G$2:$G$20,MATCH(D4,'Materials Master'!$A$2:$A$20,0)),IF(B4="Organics Recycling",INDEX('Materials Master'!$H$2:$H$20,MATCH(D4,'Materials Master'!$A$2:$A$20,0)),IF(B4="Cardboard Recycling",INDEX('Materials Master'!$I$2:$I$20,MATCH(D4,'Materials Master'!$A$2:$A$20,0)),IF(B4="Paper Recycling",INDEX('Materials Master'!$J$2:$J$20,MATCH(D4,'Materials Master'!$A$2:$A$20,0)),IF(B4="Terracycle",INDEX('Materials Master'!$K$2:$K$20,MATCH(D4,'Materials Master'!$A$2:$A$20,0)),"No")))))),"") -> Yes | K4: =IFERROR(INDEX(Areas!$C$2:$C$3,MATCH(C4,Areas!$B$2:$B$3,0)),"") -> Cafeteria
A5: 120PARK-2025 | B5: Trash | C5: Cafeteria | D5: GLA01 | E5: 4.35 | F5: =IFERROR(INDEX('Materials Master'!$B$2:$B$20,MATCH(D5,'Materials Master'!$A$2:$A$20,0)),"") -> Glass Bottles & Jars | G5: =IFERROR(INDEX('Materials Master'!$C$2:$C$20,MATCH(D5,'Materials Master'!$A$2:$A$20,0)),"") -> Glass | H5: =IFERROR(INDEX('Materials Master'!$D$2:$D$20,MATCH(D5,'Materials Master'!$A$2:$A$20,0)),"") -> Yes | I5: =IFERROR(INDEX('Materials Master'!$E$2:$E$20,MATCH(D5,'Materials Master'!$A$2:$A$20,0)),"") -> Yes | J5: =IFERROR(IF(B5="Trash",INDEX('Materials Master'!$F$2:$F$20,MATCH(D5,'Materials Master'!$A$2:$A$20,0)),IF(B5="GMPC Recycling",INDEX('Materials Master'!$G$2:$G$20,MATCH(D5,'Materials Master'!$A$2:$A$20,0)),IF(B5="Organics Recycling",INDEX('Materials Master'!$H$2:$H$20,MATCH(D5,'Materials Master'!$A$2:$A$20,0)),IF(B5="Cardboard Recycling",INDEX('Materials Master'!$I$2:$I$20,MATCH(D5,'Materials Master'!$A$2:$A$20,0)),IF(B5="Paper Recycling",INDEX('Materials Master'!$J$2:$J$20,MATCH(D5,'Materials Master'!$A$2:$A$20,0)),IF(B5="Terracycle",INDEX('Materials Master'!$K$2:$K$20,MATCH(D5,'Materials Master'!$A$2:$A$20,0)),"No")))))),"") -> No | K5: =IFERROR(INDEX(Areas!$C$2:$C$3,MATCH(C5,Areas!$B$2:$B$3,0)),"") -> Cafeteria
A6: 120PARK-2025 | B6: Trash | C6: Cafeteria | D6: MET01 | E6: 1 | F6: =IFERROR(INDEX('Materials Master'!$B$2:$B$20,MATCH(D6,'Materials Master'!$A$2:$A$20,0)),"") -> Aluminum & Bi-metal Containers | G6: =IFERROR(INDEX('Materials Master'!$C$2:$C$20,MATCH(D6,'Materials Master'!$A$2:$A$20,0)),"") -> Metals | H6: =IFERROR(INDEX('Materials Master'!$D$2:$D$20,MATCH(D6,'Materials Master'!$A$2:$A$20,0)),"") -> Yes | I6: =IFERROR(INDEX('Materials Master'!$E$2:$E$20,MATCH(D6,'Materials Master'!$A$2:$A$20,0)),"") -> Yes | J6: =IFERROR(IF(B6="Trash",INDEX('Materials Master'!$F$2:$F$20,MATCH(D6,'Materials Master'!$A$2:$A$20,0)),IF(B6="GMPC Recycling",INDEX('Materials Master'!$G$2:$G$20,MATCH(D6,'Materials Master'!$A$2:$A$20,0)),IF(B6="Organics Recycling",INDEX('Materials Master'!$H$2:$H$20,MATCH(D6,'Materials Master'!$A$2:$A$20,0)),IF(B6="Cardboard Recycling",INDEX('Materials Master'!$I$2:$I$20,MATCH(D6,'Materials Master'!$A$2:$A$20,0)),IF(B6="Paper Recycling",INDEX('Materials Master'!$J$2:$J$20,MATCH(D6,'Materials Master'!$A$2:$A$20,0)),IF(B6="Terracycle",INDEX('Materials Master'!$K$2:$K$20,MATCH(D6,'Materials Master'!$A$2:$A$20,0)),"No")))))),"") -> No | K6: =IFERROR(INDEX(Areas!$C$2:$C$3,MATCH(C6,Areas!$B$2:$B$3,0)),"") -> Cafeteria
A7: 120PARK-2025 | B7: Trash | C7: Cafeteria | D7: PLA01 | E7: 21.1 | F7: =IFERROR(INDEX('Materials Master'!$B$2:$B$20,MATCH(D7,'Materials Master'!$A$2:$A$20,0)),"") -> Rigid Plastics (1-6) | G7: =IFERROR(INDEX('Materials Master'!$C$2:$C$20,MATCH(D7,'Materials Master'!$A$2:$A$20,0)),"") -> Plastics | H7: =IFERROR(INDEX('Materials Master'!$D$2:$D$20,MATCH(D7,'Materials Master'!$A$2:$A$20,0)),"") -> Yes | I7: =IFERROR(INDEX('Materials Master'!$E$2:$E$20,MATCH(D7,'Materials Master'!$A$2:$A$20,0)),"") -> Yes | J7: =IFERROR(IF(B7="Trash",INDEX('Materials Master'!$F$2:$F$20,MATCH(D7,'Materials Master'!$A$2:$A$20,0)),IF(B7="GMPC Recycling",INDEX('Materials Master'!$G$2:$G$20,MATCH(D7,'Materials Master'!$A$2:$A$20,0)),IF(B7="Organics Recycling",INDEX('Materials Master'!$H$2:$H$20,MATCH(D7,'Materials Master'!$A$2:$A$20,0)),IF(B7="Cardboard Recycling",INDEX('Materials Master'!$I$2:$I$20,MATCH(D7,'Materials Master'!$A$2:$A$20,0)),IF(B7="Paper Recycling",INDEX('Materials Master'!$J$2:$J$20,MATCH(D7,'Materials Master'!$A$2:$A$20,0)),IF(B7="Terracycle",INDEX('Materials Master'!$K$2:$K$20,MATCH(D7,'Materials Master'!$A$2:$A$20,0)),"No")))))),"") -> No | K7: =IFERROR(INDEX(Areas!$C$2:$C$3,MATCH(C7,Areas!$B$2:$B$3,0)),"") -> Cafeteria
A8: 120PARK-2025 | B8: Trash | C8: Cafeteria | D8: PLA04 | E8: 8.71 | F8: =IFERROR(INDEX('Materials Master'!$B$2:$B$20,MATCH(D8,'Materials Master'!$A$2:$A$20,0)),"") -> Waste Disposal Bags | G8: =IFERROR(INDEX('Materials Master'!$C$2:$C$20,MATCH(D8,'Materials Master'!$A$2:$A$20,0)),"") -> Plastics | H8: =IFERROR(INDEX('Materials Master'!$D$2:$D$20,MATCH(D8,'Materials Master'!$A$2:$A$20,0)),"") -> No | I8: =IFERROR(INDEX('Materials Master'!$E$2:$E$20,MATCH(D8,'Materials Master'!$A$2:$A$20,0)),"") -> No | J8: =IFERROR(IF(B8="Trash",INDEX('Materials Master'!$F$2:$F$20,MATCH(D8,'Materials Master'!$A$2:$A$20,0)),IF(B8="GMPC Recycling",INDEX('Materials Master'!$G$2:$G$20,MATCH(D8,'Materials Master'!$A$2:$A$20,0)),IF(B8="Organics Recycling",INDEX('Materials Master'!$H$2:$H$20,MATCH(D8,'Materials Master'!$A$2:$A$20,0)),IF(B8="Cardboard Recycling",INDEX('Materials Master'!$I$2:$I$20,MATCH(D8,'Materials Master'!$A$2:$A$20,0)),IF(B8="Paper Recycling",INDEX('Materials Master'!$J$2:$J$20,MATCH(D8,'Materials Master'!$A$2:$A$20,0)),IF(B8="Terracycle",INDEX('Materials Master'!$K$2:$K$20,MATCH(D8,'Materials Master'!$A$2:$A$20,0)),"No")))))),"") -> Yes | K8: =IFERROR(INDEX(Areas!$C$2:$C$3,MATCH(C8,Areas!$B$2:$B$3,0)),"") -> Cafeteria
A9: 120PARK-2025 | B9: Trash | C9: Cafeteria | D9: ORG01 | E9: 79.02 | F9: =IFERROR(INDEX('Materials Master'!$B$2:$B$20,MATCH(D9,'Materials Master'!$A$2:$A$20,0)),"") -> Food Waste | G9: =IFERROR(INDEX('Materials Master'!$C$2:$C$20,MATCH(D9,'Materials Master'!$A$2:$A$20,0)),"") -> Organics | H9: =IFERROR(INDEX('Materials Master'!$D$2:$D$20,MATCH(D9,'Materials Master'!$A$2:$A$20,0)),"") -> No | I9: =IFERROR(INDEX('Materials Master'!$E$2:$E$20,MATCH(D9,'Materials Master'!$A$2:$A$20,0)),"") -> Yes | J9: =IFERROR(IF(B9="Trash",INDEX('Materials Master'!$F$2:$F$20,MATCH(D9,'Materials Master'!$A$2:$A$20,0)),IF(B9="GMPC Recycling",INDEX('Materials Master'!$G$2:$G$20,MATCH(D9,'Materials Master'!$A$2:$A$20,0)),IF(B9="Organics Recycling",INDEX('Materials Master'!$H$2:$H$20,MATCH(D9,'Materials Master'!$A$2:$A$20,0)),IF(B9="Cardboard Recycling",INDEX('Materials Master'!$I$2:$I$20,MATCH(D9,'Materials Master'!$A$2:$A$20,0)),IF(B9="Paper Recycling",INDEX('Materials Master'!$J$2:$J$20,MATCH(D9,'Materials Master'!$A$2:$A$20,0)),IF(B9="Terracycle",INDEX('Materials Master'!$K$2:$K$20,MATCH(D9,'Materials Master'!$A$2:$A$20,0)),"No")))))),"") -> No | K9: =IFERROR(INDEX(Areas!$C$2:$C$3,MATCH(C9,Areas!$B$2:$B$3,0)),"") -> Cafeteria
A10: 120PARK-2025 | B10: Trash | C10: Cafeteria | D10: ORG02 | E10: 20.09 | F10: =IFERROR(INDEX('Materials Master'!$B$2:$B$20,MATCH(D10,'Materials Master'!$A$2:$A$20,0)),"") -> Paper Fibers and FSP | G10: =IFERROR(INDEX('Materials Master'!$C$2:$C$20,MATCH(D10,'Materials Master'!$A$2:$A$20,0)),"") -> Organics | H10: =IFERROR(INDEX('Materials Master'!$D$2:$D$20,MATCH(D10,'Materials Master'!$A$2:$A$20,0)),"") -> No | I10: =IFERROR(INDEX('Materials Master'!$E$2:$E$20,MATCH(D10,'Materials Master'!$A$2:$A$20,0)),"") -> No | J10: =IFERROR(IF(B10="Trash",INDEX('Materials Master'!$F$2:$F$20,MATCH(D10,'Materials Master'!$A$2:$A$20,0)),IF(B10="GMPC Recycling",INDEX('Materials Master'!$G$2:$G$20,MATCH(D10,'Materials Master'!$A$2:$A$20,0)),IF(B10="Organics Recycling",INDEX('Materials Master'!$H$2:$H$20,MATCH(D10,'Materials Master'!$A$2:$A$20,0)),IF(B10="Cardboard Recycling",INDEX('Materials Master'!$I$2:$I$20,MATCH(D10,'Materials Master'!$A$2:$A$20,0)),IF(B10="Paper Recycling",INDEX('Materials Master'!$J$2:$J$20,MATCH(D10,'Materials Master'!$A$2:$A$20,0)),IF(B10="Terracycle",INDEX('Materials Master'!$K$2:$K$20,MATCH(D10,'Materials Master'!$A$2:$A$20,0)),"No")))))),"") -> Yes | K10: =IFERROR(INDEX(Areas!$C$2:$C$3,MATCH(C10,Areas!$B$2:$B$3,0)),"") -> Cafeteria
A11: 120PARK-2025 | B11: Trash | C11: Cafeteria | D11: ORG03 | E11: 15.74 | F11: =IFERROR(INDEX('Materials Master'!$B$2:$B$20,MATCH(D11,'Materials Master'!$A$2:$A$20,0)),"") -> Certified Compostables | G11: =IFERROR(INDEX('Materials Master'!$C$2:$C$20,MATCH(D11,'Materials Master'!$A$2:$A$20,0)),"") -> Organics | H11: =IFERROR(INDEX('Materials Master'!$D$2:$D$20,MATCH(D11,'Materials Master'!$A$2:$A$20,0)),"") -> No | I11: =IFERROR(INDEX('Materials Master'!$E$2:$E$20,MATCH(D11,'Materials Master'!$A$2:$A$20,0)),"") -> No | J11: =IFERROR(IF(B11="Trash",INDEX('Materials Master'!$F$2:$F$20,MATCH(D11,'Materials Master'!$A$2:$A$20,0)),IF(B11="GMPC Recycling",INDEX('Materials Master'!$G$2:$G$20,MATCH(D11,'Materials Master'!$A$2:$A$20,0)),IF(B11="Organics Recycling",INDEX('Materials Master'!$H$2:$H$20,MATCH(D11,'Materials Master'!$A$2:$A$20,0)),IF(B11="Cardboard Recycling",INDEX('Materials Master'!$I$2:$I$20,MATCH(D11,'Materials Master'!$A$2:$A$20,0)),IF(B11="Paper Recycling",INDEX('Materials Master'!$J$2:$J$20,MATCH(D11,'Materials Master'!$A$2:$A$20,0)),IF(B11="Terracycle",INDEX('Materials Master'!$K$2:$K$20,MATCH(D11,'Materials Master'!$A$2:$A$20,0)),"No")))))),"") -> Yes | K11: =IFERROR(INDEX(Areas!$C$2:$C$3,MATCH(C11,Areas!$B$2:$B$3,0)),"") -> Cafeteria
A12: 120PARK-2025 | B12: Trash | C12: Cafeteria | D12: UNA02 | E12: 3.35 | F12: =IFERROR(INDEX('Materials Master'!$B$2:$B$20,MATCH(D12,'Materials Master'!$A$2:$A$20,0)),"") -> Liquids | G12: =IFERROR(INDEX('Materials Master'!$C$2:$C$20,MATCH(D12,'Materials Master'!$A$2:$A$20,0)),"") -> Unacceptable | H12: =IFERROR(INDEX('Materials Master'!$D$2:$D$20,MATCH(D12,'Materials Master'!$A$2:$A$20,0)),"") -> Unacceptable | I12: =IFERROR(INDEX('Materials Master'!$E$2:$E$20,MATCH(D12,'Materials Master'!$A$2:$A$20,0)),"") -> No | J12: =IFERROR(IF(B12="Trash",INDEX('Materials Master'!$F$2:$F$20,MATCH(D12,'Materials Master'!$A$2:$A$20,0)),IF(B12="GMPC Recycling",INDEX('Materials Master'!$G$2:$G$20,MATCH(D12,'Materials Master'!$A$2:$A$20,0)),IF(B12="Organics Recycling",INDEX('Materials Master'!$H$2:$H$20,MATCH(D12,'Materials Master'!$A$2:$A$20,0)),IF(B12="Cardboard Recycling",INDEX('Materials Master'!$I$2:$I$20,MATCH(D12,'Materials Master'!$A$2:$A$20,0)),IF(B12="Paper Recycling",INDEX('Materials Master'!$J$2:$J$20,MATCH(D12,'Materials Master'!$A$2:$A$20,0)),IF(B12="Terracycle",INDEX('Materials Master'!$K$2:$K$20,MATCH(D12,'Materials Master'!$A$2:$A$20,0)),"No")))))),"") -> Yes | K12: =IFERROR(INDEX(Areas!$C$2:$C$3,MATCH(C12,Areas!$B$2:$B$3,0)),"") -> Cafeteria
A13: 120PARK-2025 | B13: Trash | C13: Cafeteria | D13: OTH01 | E13: 35.83 | F13: =IFERROR(INDEX('Materials Master'!$B$2:$B$20,MATCH(D13,'Materials Master'!$A$2:$A$20,0)),"") -> Residual Materials | G13: =IFERROR(INDEX('Materials Master'!$C$2:$C$20,MATCH(D13,'Materials Master'!$A$2:$A$20,0)),"") -> Other | H13: =IFERROR(INDEX('Materials Master'!$D$2:$D$20,MATCH(D13,'Materials Master'!$A$2:$A$20,0)),"") -> No | I13: =IFERROR(INDEX('Materials Master'!$E$2:$E$20,MATCH(D13,'Materials Master'!$A$2:$A$20,0)),"") -> No | J13: =IFERROR(IF(B13="Trash",INDEX('Materials Master'!$F$2:$F$20,MATCH(D13,'Materials Master'!$A$2:$A$20,0)),IF(B13="GMPC Recycling",INDEX('Materials Master'!$G$2:$G$20,MATCH(D13,'Materials Master'!$A$2:$A$20,0)),IF(B13="Organics Recycling",INDEX('Materials Master'!$H$2:$H$20,MATCH(D13,'Materials Master'!$A$2:$A$20,0)),IF(B13="Cardboard Recycling",INDEX('Materials Master'!$I$2:$I$20,MATCH(D13,'Materials Master'!$A$2:$A$20,0)),IF(B13="Paper Recycling",INDEX('Materials Master'!$J$2:$J$20,MATCH(D13,'Materials Master'!$A$2:$A$20,0)),IF(B13="Terracycle",INDEX('Materials Master'!$K$2:$K$20,MATCH(D13,'Materials Master'!$A$2:$A$20,0)),"No")))))),"") -> Yes | K13: =IFERROR(INDEX(Areas!$C$2:$C$3,MATCH(C13,Areas!$B$2:$B$3,0)),"") -> Cafeteria
... A67: 120PARK-2025 | B67: Cardboard Recycling | C67: Base Building | D67: FIB01 | E67: 84.6 | F67: =IFERROR(INDEX('Materials Master'!$B$2:$B$20,MATCH(D67,'Materials Master'!$A$2:$A$20,0)),"") -> Corrugated Cardboard | G67: =IFERROR(INDEX('Materials Master'!$C$2:$C$20,MATCH(D67,'Materials Master'!$A$2:$A$20,0)),"") -> Fibers | H67: =IFERROR(INDEX('Materials Master'!$D$2:$D$20,MATCH(D67,'Materials Master'!$A$2:$A$20,0)),"") -> Yes | I67: =IFERROR(INDEX('Materials Master'!$E$2:$E$20,MATCH(D67,'Materials Master'!$A$2:$A$20,0)),"") -> Yes | J67: =IFERROR(IF(B67="Trash",INDEX('Materials Master'!$F$2:$F$20,MATCH(D67,'Materials Master'!$A$2:$A$20,0)),IF(B67="GMPC Recycling",INDEX('Materials Master'!$G$2:$G$20,MATCH(D67,'Materials Master'!$A$2:$A$20,0)),IF(B67="Organics Recycling",INDEX('Materials Master'!$H$2:$H$20,MATCH(D67,'Materials Master'!$A$2:$A$20,0)),IF(B67="Cardboard Recycling",INDEX('Materials Master'!$I$2:$I$20,MATCH(D67,'Materials Master'!$A$2:$A$20,0)),IF(B67="Paper Recycling",INDEX('Materials Master'!$J$2:$J$20,MATCH(D67,'Materials Master'!$A$2:$A$20,0)),IF(B67="Terracycle",INDEX('Materials Master'!$K$2:$K$20,MATCH(D67,'Materials Master'!$A$2:$A$20,0)),"No")))))),"") -> Yes | K67: =IFERROR(INDEX(Areas!$C$2:$C$3,MATCH(C67,Areas!$B$2:$B$3,0)),"") -> Base Building

Sheet Fact_PreSortWeights
A1: audit_id | B1: stream | C1: area | D1: bag_number | E1: weight_lbs | F1: notes
A2: 120PARK-2025 | B2: Trash | C2: Cafeteria | D2: 1 | E2: 198.9
A3: 120PARK-2025 | B3: GMPC Recycling | C3: Cafeteria | D3: 1 | E3: 17.79
A4: 120PARK-2025 | B4: Organics Recycling | C4: Cafeteria | D4: 1 | E4: 305.99
A5: 120PARK-2025 | B5: Trash | C5: Base Building | D5: 1 | E5: 507.98
A6: 120PARK-2025 | B6: GMPC Recycling | C6: Base Building | D6: 1 | E6: 143.8

Sheet Fact_Extrapolated
A1: area | B1: stream | C1: material_id | D1: material_name | E1: material_category | F1: extrapolated_weight_lbs | G1: correctly_placed | H1: accepted_in_program | I1: rollup_group | J1: belongs_here
A2: Cafeteria | B2: Trash | C2: FIB01 | D2: =IFERROR(INDEX('Materials Master'!$B$2:$B$20,MATCH($C2,'Materials Master'!$A$2:$A$20,0)),"") -> Corrugated Cardboard | E2: =IFERROR(INDEX('Materials Master'!$C$2:$C$20,MATCH($C2,'Materials Master'!$A$2:$A$20,0)),"") -> Fibers | F2: =IF(SUMIFS(Fact_SortedWeights!$E$2:$E$67,Fact_SortedWeights!$C$2:$C$67,$A2,Fact_SortedWeights!$B$2:$B$67,$B2)=0,0,SUMIFS(Fact_SortedWeights!$E$2:$E$67,Fact_SortedWeights!$C$2:$C$67,$A2,Fact_SortedWeights!$B$2:$B$67,$B2,Fact_SortedWeights!$D$2:$D$67,$C2)/SUMIFS(Fact_SortedWeights!$E$2:$E$67,Fact_SortedWeights!$C$2:$C$67,$A2,Fact_SortedWeights!$B$2:$B$67,$B2)*(IF($B2="Cardboard Recycling",SUMIFS(Fact_SortedWeights!$E$2:$E$67,Fact_SortedWeights!$C$2:$C$67,$A2,Fact_SortedWeights!$B$2:$B$67,$B2),SUMIFS(Fact_PreSortWeights!$E$2:$E$6,Fact_PreSortWeights!$C$2:$C$6,$A2,Fact_PreSortWeights!$B$2:$B$6,$B2)))) -> 0 | G2: =IF(AND(IF($B2="Trash",INDEX('Materials Master'!$F$2:$F$20,MATCH($C2,'Materials Master'!$A$2:$A$20,0)),IF($B2="GMPC Recycling",INDEX('Materials Master'!$G$2:$G$20,MATCH($C2,'Materials Master'!$A$2:$A$20,0)),IF($B2="Organics Recycling",INDEX('Materials Master'!$H$2:$H$20,MATCH($C2,'Materials Master'!$A$2:$A$20,0)),IF($B2="Cardboard Recycling",INDEX('Materials Master'!$I$2:$I$20,MATCH($C2,'Materials Master'!$A$2:$A$20,0)),IF($B2="Paper Recycling",INDEX('Materials Master'!$J$2:$J$20,MATCH($C2,'Materials Master'!$A$2:$A$20,0)),IF($B2="Terracycle",INDEX('Materials Master'!$K$2:$K$20,MATCH($C2,'Materials Master'!$A$2:$A$20,0)),"No"))))))="Yes",INDEX('Materials Master'!$E$2:$E$20,MATCH($C2,'Materials Master'!$A$2:$A$20,0))="Yes",$B2<>"Trash"),1,0) -> 0 | H2: =INDEX('Materials Master'!$E$2:$E$20,MATCH($C2,'Materials Master'!$A$2:$A$20,0)) -> Yes | I2: =IFERROR(INDEX(Areas!$C$2:$C$3,MATCH($A2,Areas!$B$2:$B$3,0)),"") -> Cafeteria | J2: =IF(IF($B2="Trash",INDEX('Materials Master'!$F$2:$F$20,MATCH($C2,'Materials Master'!$A$2:$A$20,0)),IF($B2="GMPC Recycling",INDEX('Materials Master'!$G$2:$G$20,MATCH($C2,'Materials Master'!$A$2:$A$20,0)),IF($B2="Organics Recycling",INDEX('Materials Master'!$H$2:$H$20,MATCH($C2,'Materials Master'!$A$2:$A$20,0)),IF($B2="Cardboard Recycling",INDEX('Materials Master'!$I$2:$I$20,MATCH($C2,'Materials Master'!$A$2:$A$20,0)),IF($B2="Paper Recycling",INDEX('Materials Master'!$J$2:$J$20,MATCH($C2,'Materials Master'!$A$2:$A$20,0)),IF($B2="Terracycle",INDEX('Materials Master'!$K$2:$K$20,MATCH($C2,'Materials Master'!$A$2:$A$20,0)),"No"))))))="Yes",1,0) -> 0
A3: Cafeteria | B3: Trash | C3: FIB02 | D3: =IFERROR(INDEX('Materials Master'!$B$2:$B$20,MATCH($C3,'Materials Master'!$A$2:$A$20,0)),"") -> Waxed Cardboard | E3: =IFERROR(INDEX('Materials Master'!$C$2:$C$20,MATCH($C3,'Materials Master'!$A$2:$A$20,0)),"") -> Fibers | F3: =IF(SUMIFS(Fact_SortedWeights!$E$2:$E$67,Fact_SortedWeights!$C$2:$C$67,$A3,Fact_SortedWeights!$B$2:$B$67,$B3)=0,0,SUMIFS(Fact_SortedWeights!$E$2:$E$67,Fact_SortedWeights!$C$2:$C$67,$A3,Fact_SortedWeights!$B$2:$B$67,$B3,Fact_SortedWeights!$D$2:$D$67,$C3)/SUMIFS(Fact_SortedWeights!$E$2:$E$67,Fact_SortedWeights!$C$2:$C$67,$A3,Fact_SortedWeights!$B$2:$B$67,$B3)*(IF($B3="Cardboard Recycling",SUMIFS(Fact_SortedWeights!$E$2:$E$67,Fact_SortedWeights!$C$2:$C$67,$A3,Fact_SortedWeights!$B$2:$B$67,$B3),SUMIFS(Fact_PreSortWeights!$E$2:$E$6,Fact_PreSortWeights!$C$2:$C$6,$A3,Fact_PreSortWeights!$B$2:$B$6,$B3)))) -> 0 | G3: =IF(AND(IF($B3="Trash",INDEX('Materials Master'!$F$2:$F$20,MATCH($C3,'Materials Master'!$A$2:$A$20,0)),IF($B3="GMPC Recycling",INDEX('Materials Master'!$G$2:$G$20,MATCH($C3,'Materials Master'!$A$2:$A$20,0)),IF($B3="Organics Recycling",INDEX('Materials Master'!$H$2:$H$20,MATCH($C3,'Materials Master'!$A$2:$A$20,0)),IF($B3="Cardboard Recycling",INDEX('Materials Master'!$I$2:$I$20,MATCH($C3,'Materials Master'!$A$2:$A$20,0)),IF($B3="Paper Recycling",INDEX('Materials Master'!$J$2:$J$20,MATCH($C3,'Materials Master'!$A$2:$A$20,0)),IF($B3="Terracycle",INDEX('Materials Master'!$K$2:$K$20,MATCH($C3,'Materials Master'!$A$2:$A$20,0)),"No"))))))="Yes",INDEX('Materials Master'!$E$2:$E$20,MATCH($C3,'Materials Master'!$A$2:$A$20,0))="Yes",$B3<>"Trash"),1,0) -> 0 | H3: =INDEX('Materials Master'!$E$2:$E$20,MATCH($C3,'Materials Master'!$A$2:$A$20,0)) -> No | I3: =IFERROR(INDEX(Areas!$C$2:$C$3,MATCH($A3,Areas!$B$2:$B$3,0)),"") -> Cafeteria | J3: =IF(IF($B3="Trash",INDEX('Materials Master'!$F$2:$F$20,MATCH($C3,'Materials Master'!$A$2:$A$20,0)),IF($B3="GMPC Recycling",INDEX('Materials Master'!$G$2:$G$20,MATCH($C3,'Materials Master'!$A$2:$A$20,0)),IF($B3="Organics Recycling",INDEX('Materials Master'!$H$2:$H$20,MATCH($C3,'Materials Master'!$A$2:$A$20,0)),IF($B3="Cardboard Recycling",INDEX('Materials Master'!$I$2:$I$20,MATCH($C3,'Materials Master'!$A$2:$A$20,0)),IF($B3="Paper Recycling",INDEX('Materials Master'!$J$2:$J$20,MATCH($C3,'Materials Master'!$A$2:$A$20,0)),IF($B3="Terracycle",INDEX('Materials Master'!$K$2:$K$20,MATCH($C3,'Materials Master'!$A$2:$A$20,0)),"No"))))))="Yes",1,0) -> 1
A4: Cafeteria | B4: Trash | C4: FIB03 | D4: =IFERROR(INDEX('Materials Master'!$B$2:$B$20,MATCH($C4,'Materials Master'!$A$2:$A$20,0)),"") -> Mixed Paper | E4: =IFERROR(INDEX('Materials Master'!$C$2:$C$20,MATCH($C4,'Materials Master'!$A$2:$A$20,0)),"") -> Fibers | F4: =IF(SUMIFS(Fact_SortedWeights!$E$2:$E$67,Fact_SortedWeights!$C$2:$C$67,$A4,Fact_SortedWeights!$B$2:$B$67,$B4)=0,0,SUMIFS(Fact_SortedWeights!$E$2:$E$67,Fact_SortedWeights!$C$2:$C$67,$A4,Fact_SortedWeights!$B$2:$B$67,$B4,Fact_SortedWeights!$D$2:$D$67,$C4)/SUMIFS(Fact_SortedWeights!$E$2:$E$67,Fact_SortedWeights!$C$2:$C$67,$A4,Fact_SortedWeights!$B$2:$B$67,$B4)*(IF($B4="Cardboard Recycling",SUMIFS(Fact_SortedWeights!$E$2:$E$67,Fact_SortedWeights!$C$2:$C$67,$A4,Fact_SortedWeights!$B$2:$B$67,$B4),SUMIFS(Fact_PreSortWeights!$E$2:$E$6,Fact_PreSortWeights!$C$2:$C$6,$A4,Fact_PreSortWeights!$B$2:$B$6,$B4)))) -> 4.69 | G4: =IF(AND(IF($B4="Trash",INDEX('Materials Master'!$F$2:$F$20,MATCH($C4,'Materials Master'!$A$2:$A$20,0)),IF($B4="GMPC Recycling",INDEX('Materials Master'!$G$2:$G$20,MATCH($C4,'Materials Master'!$A$2:$A$20,0)),IF($B4="Organics Recycling",INDEX('Materials Master'!$H$2:$H$20,MATCH($C4,'Materials Master'!$A$2:$A$20,0)),IF($B4="Cardboard Recycling",INDEX('Materials Master'!$I$2:$I$20,MATCH($C4,'Materials Master'!$A$2:$A$20,0)),IF($B4="Paper Recycling",INDEX('Materials Master'!$J$2:$J$20,MATCH($C4,'Materials Master'!$A$2:$A$20,0)),IF($B4="Terracycle",INDEX('Materials Master'!$K$2:$K$20,MATCH($C4,'Materials Master'!$A$2:$A$20,0)),"No"))))))="Yes",INDEX('Materials Master'!$E$2:$E$20,MATCH($C4,'Materials Master'!$A$2:$A$20,0))="Yes",$B4<>"Trash"),1,0) -> 0 | H4: =INDEX('Materials Master'!$E$2:$E$20,MATCH($C4,'Materials Master'!$A$2:$A$20,0)) -> Yes | I4: =IFERROR(INDEX(Areas!$C$2:$C$3,MATCH($A4,Areas!$B$2:$B$3,0)),"") -> Cafeteria | J4: =IF(IF($B4="Trash",INDEX('Materials Master'!$F$2:$F$20,MATCH($C4,'Materials Master'!$A$2:$A$20,0)),IF($B4="GMPC Recycling",INDEX('Materials Master'!$G$2:$G$20,MATCH($C4,'Materials Master'!$A$2:$A$20,0)),IF($B4="Organics Recycling",INDEX('Materials Master'!$H$2:$H$20,MATCH($C4,'Materials Master'!$A$2:$A$20,0)),IF($B4="Cardboard Recycling",INDEX('Materials Master'!$I$2:$I$20,MATCH($C4,'Materials Master'!$A$2:$A$20,0)),IF($B4="Paper Recycling",INDEX('Materials Master'!$J$2:$J$20,MATCH($C4,'Materials Master'!$A$2:$A$20,0)),IF($B4="Terracycle",INDEX('Materials Master'!$K$2:$K$20,MATCH($C4,'Materials Master'!$A$2:$A$20,0)),"No"))))))="Yes",1,0) -> 0
A5: Cafeteria | B5: Trash | C5: FIB04 | D5: =IFERROR(INDEX('Materials Master'!$B$2:$B$20,MATCH($C5,'Materials Master'!$A$2:$A$20,0)),"") -> Gable-top & Aseptic Cartons | E5: =IFERROR(INDEX('Materials Master'!$C$2:$C$20,MATCH($C5,'Materials Master'!$A$2:$A$20,0)),"") -> Fibers | F5: =IF(SUMIFS(Fact_SortedWeights!$E$2:$E$67,Fact_SortedWeights!$C$2:$C$67,$A5,Fact_SortedWeights!$B$2:$B$67,$B5)=0,0,SUMIFS(Fact_SortedWeights!$E$2:$E$67,Fact_SortedWeights!$C$2:$C$67,$A5,Fact_SortedWeights!$B$2:$B$67,$B5,Fact_SortedWeights!$D$2:$D$67,$C5)/SUMIFS(Fact_SortedWeights!$E$2:$E$67,Fact_SortedWeights!$C$2:$C$67,$A5,Fact_SortedWeights!$B$2:$B$67,$B5)*(IF($B5="Cardboard Recycling",SUMIFS(Fact_SortedWeights!$E$2:$E$67,Fact_SortedWeights!$C$2:$C$67,$A5,Fact_SortedWeights!$B$2:$B$67,$B5),SUMIFS(Fact_PreSortWeights!$E$2:$E$6,Fact_PreSortWeights!$C$2:$C$6,$A5,Fact_PreSortWeights!$B$2:$B$6,$B5)))) -> 4.02 | G5: =IF(AND(IF($B5="Trash",INDEX('Materials Master'!$F$2:$F$20,MATCH($C5,'Materials Master'!$A$2:$A$20,0)),IF($B5="GMPC Recycling",INDEX('Materials Master'!$G$2:$G$20,MATCH($C5,'Materials Master'!$A$2:$A$20,0)),IF($B5="Organics Recycling",INDEX('Materials Master'!$H$2:$H$20,MATCH($C5,'Materials Master'!$A$2:$A$20,0)),IF($B5="Cardboard Recycling",INDEX('Materials Master'!$I$2:$I$20,MATCH($C5,'Materials Master'!$A$2:$A$20,0)),IF($B5="Paper Recycling",INDEX('Materials Master'!$J$2:$J$20,MATCH($C5,'Materials Master'!$A$2:$A$20,0)),IF($B5="Terracycle",INDEX('Materials Master'!$K$2:$K$20,MATCH($C5,'Materials Master'!$A$2:$A$20,0)),"No"))))))="Yes",INDEX('Materials Master'!$E$2:$E$20,MATCH($C5,'Materials Master'!$A$2:$A$20,0))="Yes",$B5<>"Trash"),1,0) -> 0 | H5: =INDEX('Materials Master'!$E$2:$E$20,MATCH($C5,'Materials Master'!$A$2:$A$20,0)) -> Yes | I5: =IFERROR(INDEX(Areas!$C$2:$C$3,MATCH($A5,Areas!$B$2:$B$3,0)),"") -> Cafeteria | J5: =IF(IF($B5="Trash",INDEX('Materials Master'!$F$2:$F$20,MATCH($C5,'Materials Master'!$A$2:$A$20,0)),IF($B5="GMPC Recycling",INDEX('Materials Master'!$G$2:$G$20,MATCH($C5,'Materials Master'!$A$2:$A$20,0)),IF($B5="Organics Recycling",INDEX('Materials Master'!$H$2:$H$20,MATCH($C5,'Materials Master'!$A$2:$A$20,0)),IF($B5="Cardboard Recycling",INDEX('Materials Master'!$I$2:$I$20,MATCH($C5,'Materials Master'!$A$2:$A$20,0)),IF($B5="Paper Recycling",INDEX('Materials Master'!$J$2:$J$20,MATCH($C5,'Materials Master'!$A$2:$A$20,0)),IF($B5="Terracycle",INDEX('Materials Master'!$K$2:$K$20,MATCH($C5,'Materials Master'!$A$2:$A$20,0)),"No"))))))="Yes",1,0) -> 0
A6: Cafeteria | B6: Trash | C6: FIB05 | D6: =IFERROR(INDEX('Materials Master'!$B$2:$B$20,MATCH($C6,'Materials Master'!$A$2:$A$20,0)),"") -> Other Coated Paper Containers | E6: =IFERROR(INDEX('Materials Master'!$C$2:$C$20,MATCH($C6,'Materials Master'!$A$2:$A$20,0)),"") -> Fibers | F6: =IF(SUMIFS(Fact_SortedWeights!$E$2:$E$67,Fact_SortedWeights!$C$2:$C$67,$A6,Fact_SortedWeights!$B$2:$B$67,$B6)=0,0,SUMIFS(Fact_SortedWeights!$E$2:$E$67,Fact_SortedWeights!$C$2:$C$67,$A6,Fact_SortedWeights!$B$2:$B$67,$B6,Fact_SortedWeights!$D$2:$D$67,$C6)/SUMIFS(Fact_SortedWeights!$E$2:$E$67,Fact_SortedWeights!$C$2:$C$67,$A6,Fact_SortedWeights!$B$2:$B$67,$B6)*(IF($B6="Cardboard Recycling",SUMIFS(Fact_SortedWeights!$E$2:$E$67,Fact_SortedWeights!$C$2:$C$67,$A6,Fact_SortedWeights!$B$2:$B$67,$B6),SUMIFS(Fact_PreSortWeights!$E$2:$E$6,Fact_PreSortWeights!$C$2:$C$6,$A6,Fact_PreSortWeights!$B$2:$B$6,$B6)))) -> 1 | G6: =IF(AND(IF($B6="Trash",INDEX('Materials Master'!$F$2:$F$20,MATCH($C6,'Materials Master'!$A$2:$A$20,0)),IF($B6="GMPC Recycling",INDEX('Materials Master'!$G$2:$G$20,MATCH($C6,'Materials Master'!$A$2:$A$20,0)),IF($B6="Organics Recycling",INDEX('Materials Master'!$H$2:$H$20,MATCH($C6,'Materials Master'!$A$2:$A$20,0)),IF($B6="Cardboard Recycling",INDEX('Materials Master'!$I$2:$I$20,MATCH($C6,'Materials Master'!$A$2:$A$20,0)),IF($B6="Paper Recycling",INDEX('Materials Master'!$J$2:$J$20,MATCH($C6,'Materials Master'!$A$2:$A$20,0)),IF($B6="Terracycle",INDEX('Materials Master'!$K$2:$K$20,MATCH($C6,'Materials Master'!$A$2:$A$20,0)),"No"))))))="Yes",INDEX('Materials Master'!$E$2:$E$20,MATCH($C6,'Materials Master'!$A$2:$A$20,0))="Yes",$B6<>"Trash"),1,0) -> 0 | H6: =INDEX('Materials Master'!$E$2:$E$20,MATCH($C6,'Materials Master'!$A$2:$A$20,0)) -> No | I6: =IFERROR(INDEX(Areas!$C$2:$C$3,MATCH($A6,Areas!$B$2:$B$3,0)),"") -> Cafeteria | J6: =IF(IF($B6="Trash",INDEX('Materials Master'!$F$2:$F$20,MATCH($C6,'Materials Master'!$A$2:$A$20,0)),IF($B6="GMPC Recycling",INDEX('Materials Master'!$G$2:$G$20,MATCH($C6,'Materials Master'!$A$2:$A$20,0)),IF($B6="Organics Recycling",INDEX('Materials Master'!$H$2:$H$20,MATCH($C6,'Materials Master'!$A$2:$A$20,0)),IF($B6="Cardboard Recycling",INDEX('Materials Master'!$I$2:$I$20,MATCH($C6,'Materials Master'!$A$2:$A$20,0)),IF($B6="Paper Recycling",INDEX('Materials Master'!$J$2:$J$20,MATCH($C6,'Materials Master'!$A$2:$A$20,0)),IF($B6="Terracycle",INDEX('Materials Master'!$K$2:$K$20,MATCH($C6,'Materials Master'!$A$2:$A$20,0)),"No"))))))="Yes",1,0) -> 1
A7: Cafeteria | B7: Trash | C7: GLA01 | D7: =IFERROR(INDEX('Materials Master'!$B$2:$B$20,MATCH($C7,'Materials Master'!$A$2:$A$20,0)),"") -> Glass Bottles & Jars | E7: =IFERROR(INDEX('Materials Master'!$C$2:$C$20,MATCH($C7,'Materials Master'!$A$2:$A$20,0)),"") -> Glass | F7: =IF(SUMIFS(Fact_SortedWeights!$E$2:$E$67,Fact_SortedWeights!$C$2:$C$67,$A7,Fact_SortedWeights!$B$2:$B$67,$B7)=0,0,SUMIFS(Fact_SortedWeights!$E$2:$E$67,Fact_SortedWeights!$C$2:$C$67,$A7,Fact_SortedWeights!$B$2:$B$67,$B7,Fact_SortedWeights!$D$2:$D$67,$C7)/SUMIFS(Fact_SortedWeights!$E$2:$E$67,Fact_SortedWeights!$C$2:$C$67,$A7,Fact_SortedWeights!$B$2:$B$67,$B7)*(IF($B7="Cardboard Recycling",SUMIFS(Fact_SortedWeights!$E$2:$E$67,Fact_SortedWeights!$C$2:$C$67,$A7,Fact_SortedWeights!$B$2:$B$67,$B7),SUMIFS(Fact_PreSortWeights!$E$2:$E$6,Fact_PreSortWeights!$C$2:$C$6,$A7,Fact_PreSortWeights!$B$2:$B$6,$B7)))) -> 4.35 | G7: =IF(AND(IF($B7="Trash",INDEX('Materials Master'!$F$2:$F$20,MATCH($C7,'Materials Master'!$A$2:$A$20,0)),IF($B7="GMPC Recycling",INDEX('Materials Master'!$G$2:$G$20,MATCH($C7,'Materials Master'!$A$2:$A$20,0)),IF($B7="Organics Recycling",INDEX('Materials Master'!$H$2:$H$20,MATCH($C7,'Materials Master'!$A$2:$A$20,0)),IF($B7="Cardboard Recycling",INDEX('Materials Master'!$I$2:$I$20,MATCH($C7,'Materials Master'!$A$2:$A$20,0)),IF($B7="Paper Recycling",INDEX('Materials Master'!$J$2:$J$20,MATCH($C7,'Materials Master'!$A$2:$A$20,0)),IF($B7="Terracycle",INDEX('Materials Master'!$K$2:$K$20,MATCH($C7,'Materials Master'!$A$2:$A$20,0)),"No"))))))="Yes",INDEX('Materials Master'!$E$2:$E$20,MATCH($C7,'Materials Master'!$A$2:$A$20,0))="Yes",$B7<>"Trash"),1,0) -> 0 | H7: =INDEX('Materials Master'!$E$2:$E$20,MATCH($C7,'Materials Master'!$A$2:$A$20,0)) -> Yes | I7: =IFERROR(INDEX(Areas!$C$2:$C$3,MATCH($A7,Areas!$B$2:$B$3,0)),"") -> Cafeteria | J7: =IF(IF($B7="Trash",INDEX('Materials Master'!$F$2:$F$20,MATCH($C7,'Materials Master'!$A$2:$A$20,0)),IF($B7="GMPC Recycling",INDEX('Materials Master'!$G$2:$G$20,MATCH($C7,'Materials Master'!$A$2:$A$20,0)),IF($B7="Organics Recycling",INDEX('Materials Master'!$H$2:$H$20,MATCH($C7,'Materials Master'!$A$2:$A$20,0)),IF($B7="Cardboard Recycling",INDEX('Materials Master'!$I$2:$I$20,MATCH($C7,'Materials Master'!$A$2:$A$20,0)),IF($B7="Paper Recycling",INDEX('Materials Master'!$J$2:$J$20,MATCH($C7,'Materials Master'!$A$2:$A$20,0)),IF($B7="Terracycle",INDEX('Materials Master'!$K$2:$K$20,MATCH($C7,'Materials Master'!$A$2:$A$20,0)),"No"))))))="Yes",1,0) -> 0
A8: Cafeteria | B8: Trash | C8: GLA02 | D8: =IFERROR(INDEX('Materials Master'!$B$2:$B$20,MATCH($C8,'Materials Master'!$A$2:$A$20,0)),"") -> Broken Glass | E8: =IFERROR(INDEX('Materials Master'!$C$2:$C$20,MATCH($C8,'Materials Master'!$A$2:$A$20,0)),"") -> Glass | F8: =IF(SUMIFS(Fact_SortedWeights!$E$2:$E$67,Fact_SortedWeights!$C$2:$C$67,$A8,Fact_SortedWeights!$B$2:$B$67,$B8)=0,0,SUMIFS(Fact_SortedWeights!$E$2:$E$67,Fact_SortedWeights!$C$2:$C$67,$A8,Fact_SortedWeights!$B$2:$B$67,$B8,Fact_SortedWeights!$D$2:$D$67,$C8)/SUMIFS(Fact_SortedWeights!$E$2:$E$67,Fact_SortedWeights!$C$2:$C$67,$A8,Fact_SortedWeights!$B$2:$B$67,$B8)*(IF($B8="Cardboard Recycling",SUMIFS(Fact_SortedWeights!$E$2:$E$67,Fact_SortedWeights!$C$2:$C$67,$A8,Fact_SortedWeights!$B$2:$B$67,$B8),SUMIFS(Fact_PreSortWeights!$E$2:$E$6,Fact_PreSortWeights!$C$2:$C$6,$A8,Fact_PreSortWeights!$B$2:$B$6,$B8)))) -> 0 | G8: =IF(AND(IF($B8="Trash",INDEX('Materials Master'!$F$2:$F$20,MATCH($C8,'Materials Master'!$A$2:$A$20,0)),IF($B8="GMPC Recycling",INDEX('Materials Master'!$G$2:$G$20,MATCH($C8,'Materials Master'!$A$2:$A$20,0)),IF($B8="Organics Recycling",INDEX('Materials Master'!$H$2:$H$20,MATCH($C8,'Materials Master'!$A$2:$A$20,0)),IF($B8="Cardboard Recycling",INDEX('Materials Master'!$I$2:$I$20,MATCH($C8,'Materials Master'!$A$2:$A$20,0)),IF($B8="Paper Recycling",INDEX('Materials Master'!$J$2:$J$20,MATCH($C8,'Materials Master'!$A$2:$A$20,0)),IF($B8="Terracycle",INDEX('Materials Master'!$K$2:$K$20,MATCH($C8,'Materials Master'!$A$2:$A$20,0)),"No"))))))="Yes",INDEX('Materials Master'!$E$2:$E$20,MATCH($C8,'Materials Master'!$A$2:$A$20,0))="Yes",$B8<>"Trash"),1,0) -> 0 | H8: =INDEX('Materials Master'!$E$2:$E$20,MATCH($C8,'Materials Master'!$A$2:$A$20,0)) -> No | I8: =IFERROR(INDEX(Areas!$C$2:$C$3,MATCH($A8,Areas!$B$2:$B$3,0)),"") -> Cafeteria | J8: =IF(IF($B8="Trash",INDEX('Materials Master'!$F$2:$F$20,MATCH($C8,'Materials Master'!$A$2:$A$20,0)),IF($B8="GMPC Recycling",INDEX('Materials Master'!$G$2:$G$20,MATCH($C8,'Materials Master'!$A$2:$A$20,0)),IF($B8="Organics Recycling",INDEX('Materials Master'!$H$2:$H$20,MATCH($C8,'Materials Master'!$A$2:$A$20,0)),IF($B8="Cardboard Recycling",INDEX('Materials Master'!$I$2:$I$20,MATCH($C8,'Materials Master'!$A$2:$A$20,0)),IF($B8="Paper Recycling",INDEX('Materials Master'!$J$2:$J$20,MATCH($C8,'Materials Master'!$A$2:$A$20,0)),IF($B8="Terracycle",INDEX('Materials Master'!$K$2:$K$20,MATCH($C8,'Materials Master'!$A$2:$A$20,0)),"No"))))))="Yes",1,0) -> 1
A9: Cafeteria | B9: Trash | C9: MET01 | D9: =IFERROR(INDEX('Materials Master'!$B$2:$B$20,MATCH($C9,'Materials Master'!$A$2:$A$20,0)),"") -> Aluminum & Bi-metal Containers | E9: =IFERROR(INDEX('Materials Master'!$C$2:$C$20,MATCH($C9,'Materials Master'!$A$2:$A$20,0)),"") -> Metals | F9: =IF(SUMIFS(Fact_SortedWeights!$E$2:$E$67,Fact_SortedWeights!$C$2:$C$67,$A9,Fact_SortedWeights!$B$2:$B$67,$B9)=0,0,SUMIFS(Fact_SortedWeights!$E$2:$E$67,Fact_SortedWeights!$C$2:$C$67,$A9,Fact_SortedWeights!$B$2:$B$67,$B9,Fact_SortedWeights!$D$2:$D$67,$C9)/SUMIFS(Fact_SortedWeights!$E$2:$E$67,Fact_SortedWeights!$C$2:$C$67,$A9,Fact_SortedWeights!$B$2:$B$67,$B9)*(IF($B9="Cardboard Recycling",SUMIFS(Fact_SortedWeights!$E$2:$E$67,Fact_SortedWeights!$C$2:$C$67,$A9,Fact_SortedWeights!$B$2:$B$67,$B9),SUMIFS(Fact_PreSortWeights!$E$2:$E$6,Fact_PreSortWeights!$C$2:$C$6,$A9,Fact_PreSortWeights!$B$2:$B$6,$B9)))) -> 1 | G9: =IF(AND(IF($B9="Trash",INDEX('Materials Master'!$F$2:$F$20,MATCH($C9,'Materials Master'!$A$2:$A$20,0)),IF($B9="GMPC Recycling",INDEX('Materials Master'!$G$2:$G$20,MATCH($C9,'Materials Master'!$A$2:$A$20,0)),IF($B9="Organics Recycling",INDEX('Materials Master'!$H$2:$H$20,MATCH($C9,'Materials Master'!$A$2:$A$20,0)),IF($B9="Cardboard Recycling",INDEX('Materials Master'!$I$2:$I$20,MATCH($C9,'Materials Master'!$A$2:$A$20,0)),IF($B9="Paper Recycling",INDEX('Materials Master'!$J$2:$J$20,MATCH($C9,'Materials Master'!$A$2:$A$20,0)),IF($B9="Terracycle",INDEX('Materials Master'!$K$2:$K$20,MATCH($C9,'Materials Master'!$A$2:$A$20,0)),"No"))))))="Yes",INDEX('Materials Master'!$E$2:$E$20,MATCH($C9,'Materials Master'!$A$2:$A$20,0))="Yes",$B9<>"Trash"),1,0) -> 0 | H9: =INDEX('Materials Master'!$E$2:$E$20,MATCH($C9,'Materials Master'!$A$2:$A$20,0)) -> Yes | I9: =IFERROR(INDEX(Areas!$C$2:$C$3,MATCH($A9,Areas!$B$2:$B$3,0)),"") -> Cafeteria | J9: =IF(IF($B9="Trash",INDEX('Materials Master'!$F$2:$F$20,MATCH($C9,'Materials Master'!$A$2:$A$20,0)),IF($B9="GMPC Recycling",INDEX('Materials Master'!$G$2:$G$20,MATCH($C9,'Materials Master'!$A$2:$A$20,0)),IF($B9="Organics Recycling",INDEX('Materials Master'!$H$2:$H$20,MATCH($C9,'Materials Master'!$A$2:$A$20,0)),IF($B9="Cardboard Recycling",INDEX('Materials Master'!$I$2:$I$20,MATCH($C9,'Materials Master'!$A$2:$A$20,0)),IF($B9="Paper Recycling",INDEX('Materials Master'!$J$2:$J$20,MATCH($C9,'Materials Master'!$A$2:$A$20,0)),IF($B9="Terracycle",INDEX('Materials Master'!$K$2:$K$20,MATCH($C9,'Materials Master'!$A$2:$A$20,0)),"No"))))))="Yes",1,0) -> 0
A10: Cafeteria | B10: Trash | C10: MET02 | D10: =IFERROR(INDEX('Materials Master'!$B$2:$B$20,MATCH($C10,'Materials Master'!$A$2:$A$20,0)),"") -> Metal Hangers | E10: =IFERROR(INDEX('Materials Master'!$C$2:$C$20,MATCH($C10,'Materials Master'!$A$2:$A$20,0)),"") -> Metals | F10: =IF(SUMIFS(Fact_SortedWeights!$E$2:$E$67,Fact_SortedWeights!$C$2:$C$67,$A10,Fact_SortedWeights!$B$2:$B$67,$B10)=0,0,SUMIFS(Fact_SortedWeights!$E$2:$E$67,Fact_SortedWeights!$C$2:$C$67,$A10,Fact_SortedWeights!$B$2:$B$67,$B10,Fact_SortedWeights!$D$2:$D$67,$C10)/SUMIFS(Fact_SortedWeights!$E$2:$E$67,Fact_SortedWeights!$C$2:$C$67,$A10,Fact_SortedWeights!$B$2:$B$67,$B10)*(IF($B10="Cardboard Recycling",SUMIFS(Fact_SortedWeights!$E$2:$E$67,Fact_SortedWeights!$C$2:$C$67,$A10,Fact_SortedWeights!$B$2:$B$67,$B10),SUMIFS(Fact_PreSortWeights!$E$2:$E$6,Fact_PreSortWeights!$C$2:$C$6,$A10,Fact_PreSortWeights!$B$2:$B$6,$B10)))) -> 0 | G10: =IF(AND(IF($B10="Trash",INDEX('Materials Master'!$F$2:$F$20,MATCH($C10,'Materials Master'!$A$2:$A$20,0)),IF($B10="GMPC Recycling",INDEX('Materials Master'!$G$2:$G$20,MATCH($C10,'Materials Master'!$A$2:$A$20,0)),IF($B10="Organics Recycling",INDEX('Materials Master'!$H$2:$H$20,MATCH($C10,'Materials Master'!$A$2:$A$20,0)),IF($B10="Cardboard Recycling",INDEX('Materials Master'!$I$2:$I$20,MATCH($C10,'Materials Master'!$A$2:$A$20,0)),IF($B10="Paper Recycling",INDEX('Materials Master'!$J$2:$J$20,MATCH($C10,'Materials Master'!$A$2:$A$20,0)),IF($B10="Terracycle",INDEX('Materials Master'!$K$2:$K$20,MATCH($C10,'Materials Master'!$A$2:$A$20,0)),"No"))))))="Yes",INDEX('Materials Master'!$E$2:$E$20,MATCH($C10,'Materials Master'!$A$2:$A$20,0))="Yes",$B10<>"Trash"),1,0) -> 0 | H10: =INDEX('Materials Master'!$E$2:$E$20,MATCH($C10,'Materials Master'!$A$2:$A$20,0)) -> No | I10: =IFERROR(INDEX(Areas!$C$2:$C$3,MATCH($A10,Areas!$B$2:$B$3,0)),"") -> Cafeteria | J10: =IF(IF($B10="Trash",INDEX('Materials Master'!$F$2:$F$20,MATCH($C10,'Materials Master'!$A$2:$A$20,0)),IF($B10="GMPC Recycling",INDEX('Materials Master'!$G$2:$G$20,MATCH($C10,'Materials Master'!$A$2:$A$20,0)),IF($B10="Organics Recycling",INDEX('Materials Master'!$H$2:$H$20,MATCH($C10,'Materials Master'!$A$2:$A$20,0)),IF($B10="Cardboard Recycling",INDEX('Materials Master'!$I$2:$I$20,MATCH($C10,'Materials Master'!$A$2:$A$20,0)),IF($B10="Paper Recycling",INDEX('Materials Master'!$J$2:$J$20,MATCH($C10,'Materials Master'!$A$2:$A$20,0)),IF($B10="Terracycle",INDEX('Materials Master'!$K$2:$K$20,MATCH($C10,'Materials Master'!$A$2:$A$20,0)),"No"))))))="Yes",1,0) -> 1
A11: Cafeteria | B11: Trash | C11: PLA01 | D11: =IFERROR(INDEX('Materials Master'!$B$2:$B$20,MATCH($C11,'Materials Master'!$A$2:$A$20,0)),"") -> Rigid Plastics (1-6) | E11: =IFERROR(INDEX('Materials Master'!$C$2:$C$20,MATCH($C11,'Materials Master'!$A$2:$A$20,0)),"") -> Plastics | F11: =IF(SUMIFS(Fact_SortedWeights!$E$2:$E$67,Fact_SortedWeights!$C$2:$C$67,$A11,Fact_SortedWeights!$B$2:$B$67,$B11)=0,0,SUMIFS(Fact_SortedWeights!$E$2:$E$67,Fact_SortedWeights!$C$2:$C$67,$A11,Fact_SortedWeights!$B$2:$B$67,$B11,Fact_SortedWeights!$D$2:$D$67,$C11)/SUMIFS(Fact_SortedWeights!$E$2:$E$67,Fact_SortedWeights!$C$2:$C$67,$A11,Fact_SortedWeights!$B$2:$B$67,$B11)*(IF($B11="Cardboard Recycling",SUMIFS(Fact_SortedWeights!$E$2:$E$67,Fact_SortedWeights!$C$2:$C$67,$A11,Fact_SortedWeights!$B$2:$B$67,$B11),SUMIFS(Fact_PreSortWeights!$E$2:$E$6,Fact_PreSortWeights!$C$2:$C$6,$A11,Fact_PreSortWeights!$B$2:$B$6,$B11)))) -> 21.1 | G11: =IF(AND(IF($B11="Trash",INDEX('Materials Master'!$F$2:$F$20,MATCH($C11,'Materials Master'!$A$2:$A$20,0)),IF($B11="GMPC Recycling",INDEX('Materials Master'!$G$2:$G$20,MATCH($C11,'Materials Master'!$A$2:$A$20,0)),IF($B11="Organics Recycling",INDEX('Materials Master'!$H$2:$H$20,MATCH($C11,'Materials Master'!$A$2:$A$20,0)),IF($B11="Cardboard Recycling",INDEX('Materials Master'!$I$2:$I$20,MATCH($C11,'Materials Master'!$A$2:$A$20,0)),IF($B11="Paper Recycling",INDEX('Materials Master'!$J$2:$J$20,MATCH($C11,'Materials Master'!$A$2:$A$20,0)),IF($B11="Terracycle",INDEX('Materials Master'!$K$2:$K$20,MATCH($C11,'Materials Master'!$A$2:$A$20,0)),"No"))))))="Yes",INDEX('Materials Master'!$E$2:$E$20,MATCH($C11,'Materials Master'!$A$2:$A$20,0))="Yes",$B11<>"Trash"),1,0) -> 0 | H11: =INDEX('Materials Master'!$E$2:$E$20,MATCH($C11,'Materials Master'!$A$2:$A$20,0)) -> Yes | I11: =IFERROR(INDEX(Areas!$C$2:$C$3,MATCH($A11,Areas!$B$2:$B$3,0)),"") -> Cafeteria | J11: =IF(IF($B11="Trash",INDEX('Materials Master'!$F$2:$F$20,MATCH($C11,'Materials Master'!$A$2:$A$20,0)),IF($B11="GMPC Recycling",INDEX('Materials Master'!$G$2:$G$20,MATCH($C11,'Materials Master'!$A$2:$A$20,0)),IF($B11="Organics Recycling",INDEX('Materials Master'!$H$2:$H$20,MATCH($C11,'Materials Master'!$A$2:$A$20,0)),IF($B11="Cardboard Recycling",INDEX('Materials Master'!$I$2:$I$20,MATCH($C11,'Materials Master'!$A$2:$A$20,0)),IF($B11="Paper Recycling",INDEX('Materials Master'!$J$2:$J$20,MATCH($C11,'Materials Master'!$A$2:$A$20,0)),IF($B11="Terracycle",INDEX('Materials Master'!$K$2:$K$20,MATCH($C11,'Materials Master'!$A$2:$A$20,0)),"No"))))))="Yes",1,0) -> 0
A12: Cafeteria | B12: Trash | C12: PLA02 | D12: =IFERROR(INDEX('Materials Master'!$B$2:$B$20,MATCH($C12,'Materials Master'!$A$2:$A$20,0)),"") -> Soiled Rigid Plastics | E12: =IFERROR(INDEX('Materials Master'!$C$2:$C$20,MATCH($C12,'Materials Master'!$A$2:$A$20,0)),"") -> Plastics | F12: =IF(SUMIFS(Fact_SortedWeights!$E$2:$E$67,Fact_SortedWeights!$C$2:$C$67,$A12,Fact_SortedWeights!$B$2:$B$67,$B12)=0,0,SUMIFS(Fact_SortedWeights!$E$2:$E$67,Fact_SortedWeights!$C$2:$C$67,$A12,Fact_SortedWeights!$B$2:$B$67,$B12,Fact_SortedWeights!$D$2:$D$67,$C12)/SUMIFS(Fact_SortedWeights!$E$2:$E$67,Fact_SortedWeights!$C$2:$C$67,$A12,Fact_SortedWeights!$B$2:$B$67,$B12)*(IF($B12="Cardboard Recycling",SUMIFS(Fact_SortedWeights!$E$2:$E$67,Fact_SortedWeights!$C$2:$C$67,$A12,Fact_SortedWeights!$B$2:$B$67,$B12),SUMIFS(Fact_PreSortWeights!$E$2:$E$6,Fact_PreSortWeights!$C$2:$C$6,$A12,Fact_PreSortWeights!$B$2:$B$6,$B12)))) -> 0 | G12: =IF(AND(IF($B12="Trash",INDEX('Materials Master'!$F$2:$F$20,MATCH($C12,'Materials Master'!$A$2:$A$20,0)),IF($B12="GMPC Recycling",INDEX('Materials Master'!$G$2:$G$20,MATCH($C12,'Materials Master'!$A$2:$A$20,0)),IF($B12="Organics Recycling",INDEX('Materials Master'!$H$2:$H$20,MATCH($C12,'Materials Master'!$A$2:$A$20,0)),IF($B12="Cardboard Recycling",INDEX('Materials Master'!$I$2:$I$20,MATCH($C12,'Materials Master'!$A$2:$A$20,0)),IF($B12="Paper Recycling",INDEX('Materials Master'!$J$2:$J$20,MATCH($C12,'Materials Master'!$A$2:$A$20,0)),IF($B12="Terracycle",INDEX('Materials Master'!$K$2:$K$20,MATCH($C12,'Materials Master'!$A$2:$A$20,0)),"No"))))))="Yes",INDEX('Materials Master'!$E$2:$E$20,MATCH($C12,'Materials Master'!$A$2:$A$20,0))="Yes",$B12<>"Trash"),1,0) -> 0 | H12: =INDEX('Materials Master'!$E$2:$E$20,MATCH($C12,'Materials Master'!$A$2:$A$20,0)) -> No | I12: =IFERROR(INDEX(Areas!$C$2:$C$3,MATCH($A12,Areas!$B$2:$B$3,0)),"") -> Cafeteria | J12: =IF(IF($B12="Trash",INDEX('Materials Master'!$F$2:$F$20,MATCH($C12,'Materials Master'!$A$2:$A$20,0)),IF($B12="GMPC Recycling",INDEX('Materials Master'!$G$2:$G$20,MATCH($C12,'Materials Master'!$A$2:$A$20,0)),IF($B12="Organics Recycling",INDEX('Materials Master'!$H$2:$H$20,MATCH($C12,'Materials Master'!$A$2:$A$20,0)),IF($B12="Cardboard Recycling",INDEX('Materials Master'!$I$2:$I$20,MATCH($C12,'Materials Master'!$A$2:$A$20,0)),IF($B12="Paper Recycling",INDEX('Materials Master'!$J$2:$J$20,MATCH($C12,'Materials Master'!$A$2:$A$20,0)),IF($B12="Terracycle",INDEX('Materials Master'!$K$2:$K$20,MATCH($C12,'Materials Master'!$A$2:$A$20,0)),"No"))))))="Yes",1,0) -> 1
A13: Cafeteria | B13: Trash | C13: PLA03 | D13: =IFERROR(INDEX('Materials Master'!$B$2:$B$20,MATCH($C13,'Materials Master'!$A$2:$A$20,0)),"") -> Film Plastics | E13: =IFERROR(INDEX('Materials Master'!$C$2:$C$20,MATCH($C13,'Materials Master'!$A$2:$A$20,0)),"") -> Plastics | F13: =IF(SUMIFS(Fact_SortedWeights!$E$2:$E$67,Fact_SortedWeights!$C$2:$C$67,$A13,Fact_SortedWeights!$B$2:$B$67,$B13)=0,0,SUMIFS(Fact_SortedWeights!$E$2:$E$67,Fact_SortedWeights!$C$2:$C$67,$A13,Fact_SortedWeights!$B$2:$B$67,$B13,Fact_SortedWeights!$D$2:$D$67,$C13)/SUMIFS(Fact_SortedWeights!$E$2:$E$67,Fact_SortedWeights!$C$2:$C$67,$A13,Fact_SortedWeights!$B$2:$B$67,$B13)*(IF($B13="Cardboard Recycling",SUMIFS(Fact_SortedWeights!$E$2:$E$67,Fact_SortedWeights!$C$2:$C$67,$A13,Fact_SortedWeights!$B$2:$B$67,$B13),SUMIFS(Fact_PreSortWeights!$E$2:$E$6,Fact_PreSortWeights!$C$2:$C$6,$A13,Fact_PreSortWeights!$B$2:$B$6,$B13)))) -> 0 | G13: =IF(AND(IF($B13="Trash",INDEX('Materials Master'!$F$2:$F$20,MATCH($C13,'Materials Master'!$A$2:$A$20,0)),IF($B13="GMPC Recycling",INDEX('Materials Master'!$G$2:$G$20,MATCH($C13,'Materials Master'!$A$2:$A$20,0)),IF($B13="Organics Recycling",INDEX('Materials Master'!$H$2:$H$20,MATCH($C13,'Materials Master'!$A$2:$A$20,0)),IF($B13="Cardboard Recycling",INDEX('Materials Master'!$I$2:$I$20,MATCH($C13,'Materials Master'!$A$2:$A$20,0)),IF($B13="Paper Recycling",INDEX('Materials Master'!$J$2:$J$20,MATCH($C13,'Materials Master'!$A$2:$A$20,0)),IF($B13="Terracycle",INDEX('Materials Master'!$K$2:$K$20,MATCH($C13,'Materials Master'!$A$2:$A$20,0)),"No"))))))="Yes",INDEX('Materials Master'!$E$2:$E$20,MATCH($C13,'Materials Master'!$A$2:$A$20,0))="Yes",$B13<>"Trash"),1,0) -> 0 | H13: =INDEX('Materials Master'!$E$2:$E$20,MATCH($C13,'Materials Master'!$A$2:$A$20,0)) -> No | I13: =IFERROR(INDEX(Areas!$C$2:$C$3,MATCH($A13,Areas!$B$2:$B$3,0)),"") -> Cafeteria | J13: =IF(IF($B13="Trash",INDEX('Materials Master'!$F$2:$F$20,MATCH($C13,'Materials Master'!$A$2:$A$20,0)),IF($B13="GMPC Recycling",INDEX('Materials Master'!$G$2:$G$20,MATCH($C13,'Materials Master'!$A$2:$A$20,0)),IF($B13="Organics Recycling",INDEX('Materials Master'!$H$2:$H$20,MATCH($C13,'Materials Master'!$A$2:$A$20,0)),IF($B13="Cardboard Recycling",INDEX('Materials Master'!$I$2:$I$20,MATCH($C13,'Materials Master'!$A$2:$A$20,0)),IF($B13="Paper Recycling",INDEX('Materials Master'!$J$2:$J$20,MATCH($C13,'Materials Master'!$A$2:$A$20,0)),IF($B13="Terracycle",INDEX('Materials Master'!$K$2:$K$20,MATCH($C13,'Materials Master'!$A$2:$A$20,0)),"No"))))))="Yes",1,0) -> 1
... A229: Base Building | B229: Terracycle | C229: OTH01 | D229: =IFERROR(INDEX('Materials Master'!$B$2:$B$20,MATCH($C229,'Materials Master'!$A$2:$A$20,0)),"") -> Residual Materials | E229: =IFERROR(INDEX('Materials Master'!$C$2:$C$20,MATCH($C229,'Materials Master'!$A$2:$A$20,0)),"") -> Other | F229: =IF(SUMIFS(Fact_SortedWeights!$E$2:$E$67,Fact_SortedWeights!$C$2:$C$67,$A229,Fact_SortedWeights!$B$2:$B$67,$B229)=0,0,SUMIFS(Fact_SortedWeights!$E$2:$E$67,Fact_SortedWeights!$C$2:$C$67,$A229,Fact_SortedWeights!$B$2:$B$67,$B229,Fact_SortedWeights!$D$2:$D$67,$C229)/SUMIFS(Fact_SortedWeights!$E$2:$E$67,Fact_SortedWeights!$C$2:$C$67,$A229,Fact_SortedWeights!$B$2:$B$67,$B229)*(IF($B229="Cardboard Recycling",SUMIFS(Fact_SortedWeights!$E$2:$E$67,Fact_SortedWeights!$C$2:$C$67,$A229,Fact_SortedWeights!$B$2:$B$67,$B229),SUMIFS(Fact_PreSortWeights!$E$2:$E$6,Fact_PreSortWeights!$C$2:$C$6,$A229,Fact_PreSortWeights!$B$2:$B$6,$B229)))) -> 0 | G229: =IF(AND(IF($B229="Trash",INDEX('Materials Master'!$F$2:$F$20,MATCH($C229,'Materials Master'!$A$2:$A$20,0)),IF($B229="GMPC Recycling",INDEX('Materials Master'!$G$2:$G$20,MATCH($C229,'Materials Master'!$A$2:$A$20,0)),IF($B229="Organics Recycling",INDEX('Materials Master'!$H$2:$H$20,MATCH($C229,'Materials Master'!$A$2:$A$20,0)),IF($B229="Cardboard Recycling",INDEX('Materials Master'!$I$2:$I$20,MATCH($C229,'Materials Master'!$A$2:$A$20,0)),IF($B229="Paper Recycling",INDEX('Materials Master'!$J$2:$J$20,MATCH($C229,'Materials Master'!$A$2:$A$20,0)),IF($B229="Terracycle",INDEX('Materials Master'!$K$2:$K$20,MATCH($C229,'Materials Master'!$A$2:$A$20,0)),"No"))))))="Yes",INDEX('Materials Master'!$E$2:$E$20,MATCH($C229,'Materials Master'!$A$2:$A$20,0))="Yes",$B229<>"Trash"),1,0) -> 0 | H229: =INDEX('Materials Master'!$E$2:$E$20,MATCH($C229,'Materials Master'!$A$2:$A$20,0)) -> No | I229: =IFERROR(INDEX(Areas!$C$2:$C$3,MATCH($A229,Areas!$B$2:$B$3,0)),"") -> Base Building | J229: =IF(IF($B229="Trash",INDEX('Materials Master'!$F$2:$F$20,MATCH($C229,'Materials Master'!$A$2:$A$20,0)),IF($B229="GMPC Recycling",INDEX('Materials Master'!$G$2:$G$20,MATCH($C229,'Materials Master'!$A$2:$A$20,0)),IF($B229="Organics Recycling",INDEX('Materials Master'!$H$2:$H$20,MATCH($C229,'Materials Master'!$A$2:$A$20,0)),IF($B229="Cardboard Recycling",INDEX('Materials Master'!$I$2:$I$20,MATCH($C229,'Materials Master'!$A$2:$A$20,0)),IF($B229="Paper Recycling",INDEX('Materials Master'!$J$2:$J$20,MATCH($C229,'Materials Master'!$A$2:$A$20,0)),IF($B229="Terracycle",INDEX('Materials Master'!$K$2:$K$20,MATCH($C229,'Materials Master'!$A$2:$A$20,0)),"No"))))))="Yes",1,0) -> 0

Sheet Overall Summary
A1: Total Waste Generation — Day of Audit
A2: Waste Stream | B2: Waste Stream Weight (lbs.) | C2: % of Total Waste Stream | D2: Weight of Material Diverted (lbs.) | E2: % of Material Diverted
A3: Trash | B3: =SUMIFS(Fact_PreSortWeights!$E$2:$E$6,Fact_PreSortWeights!$C$2:$C$6,"Cafeteria",Fact_PreSortWeights!$B$2:$B$6,"Trash")+SUMIFS(Fact_PreSortWeights!$E$2:$E$6,Fact_PreSortWeights!$C$2:$C$6,"Base Building",Fact_PreSortWeights!$B$2:$B$6,"Trash") -> 706.88 | C3: =IF($B$9=0,0,B3/$B$9) -> 0.52499146 | D3: =SUMIFS(Fact_Extrapolated!$F$2:$F$229,Fact_Extrapolated!$B$2:$B$229,A3,Fact_Extrapolated!$G$2:$G$229,1) -> 0
A4: GMPC Recycling | B4: =SUMIFS(Fact_PreSortWeights!$E$2:$E$6,Fact_PreSortWeights!$C$2:$C$6,"Cafeteria",Fact_PreSortWeights!$B$2:$B$6,"GMPC Recycling")+SUMIFS(Fact_PreSortWeights!$E$2:$E$6,Fact_PreSortWeights!$C$2:$C$6,"Base Building",Fact_PreSortWeights!$B$2:$B$6,"GMPC Recycling") -> 161.59 | C4: =IF($B$9=0,0,B4/$B$9) -> 0.12001099 | D4: =SUMIFS(Fact_Extrapolated!$F$2:$F$229,Fact_Extrapolated!$B$2:$B$229,A4,Fact_Extrapolated!$G$2:$G$229,1) -> 75.9
A5: Organics Recycling | B5: =SUMIFS(Fact_PreSortWeights!$E$2:$E$6,Fact_PreSortWeights!$C$2:$C$6,"Cafeteria",Fact_PreSortWeights!$B$2:$B$6,"Organics Recycling")+SUMIFS(Fact_PreSortWeights!$E$2:$E$6,Fact_PreSortWeights!$C$2:$C$6,"Base Building",Fact_PreSortWeights!$B$2:$B$6,"Organics Recycling") -> 305.99 | C5: =IF($B$9=0,0,B5/$B$9) -> 0.22725517 | D5: =SUMIFS(Fact_Extrapolated!$F$2:$F$229,Fact_Extrapolated!$B$2:$B$229,A5,Fact_Extrapolated!$G$2:$G$229,1) -> 303.57
A6: Cardboard Recycling | B6: =SUMIFS(Fact_SortedWeights!$E$2:$E$67,Fact_SortedWeights!$C$2:$C$67,"Cafeteria",Fact_SortedWeights!$B$2:$B$67,"Cardboard Recycling")+SUMIFS(Fact_SortedWeights!$E$2:$E$67,Fact_SortedWeights!$C$2:$C$67,"Base Building",Fact_SortedWeights!$B$2:$B$67,"Cardboard Recycling") -> 172 | C6: =IF($B$9=0,0,B6/$B$9) -> 0.12774238 | D6: =SUMIFS(Fact_Extrapolated!$F$2:$F$229,Fact_Extrapolated!$B$2:$B$229,A6,Fact_Extrapolated!$G$2:$G$229,1) -> 166.74
A7: Paper Recycling | B7: =SUMIFS(Fact_PreSortWeights!$E$2:$E$6,Fact_PreSortWeights!$C$2:$C$6,"Cafeteria",Fact_PreSortWeights!$B$2:$B$6,"Paper Recycling")+SUMIFS(Fact_PreSortWeights!$E$2:$E$6,Fact_PreSortWeights!$C$2:$C$6,"Base Building",Fact_PreSortWeights!$B$2:$B$6,"Paper Recycling") -> 0 | C7: =IF($B$9=0,0,B7/$B$9) -> 0 | D7: =SUMIFS(Fact_Extrapolated!$F$2:$F$229,Fact_Extrapolated!$B$2:$B$229,A7,Fact_Extrapolated!$G$2:$G$229,1) -> 0
A8: Terracycle | B8: =SUMIFS(Fact_PreSortWeights!$E$2:$E$6,Fact_PreSortWeights!$C$2:$C$6,"Cafeteria",Fact_PreSortWeights!$B$2:$B$6,"Terracycle")+SUMIFS(Fact_PreSortWeights!$E$2:$E$6,Fact_PreSortWeights!$C$2:$C$6,"Base Building",Fact_PreSortWeights!$B$2:$B$6,"Terracycle") -> 0 | C8: =IF($B$9=0,0,B8/$B$9) -> 0 | D8: =SUMIFS(Fact_Extrapolated!$F$2:$F$229,Fact_Extrapolated!$B$2:$B$229,A8,Fact_Extrapolated!$G$2:$G$229,1) -> 0
A9: Total | B9: =SUM(B3:B8) -> 1346.46 | C9: =IF($B$9=0,0,B9/$B$9) -> 1 | D9: =SUM(D3:D8) -> 546.21 | E9: =IF(B9=0,0,D9/B9) -> 0.40566374
A11: Waste Stream Breakdown — by Material Type
A12: Material Type Category | B12: Material Type | C12: Total Material Type Weight (lbs.) | D12: % of Total Waste Stream | E12: Weight of Material Diverted (lbs.) | F12: % of Material Diverted | G12: Currently Divertible?
A13: Fibers | B13: Corrugated Cardboard | C13: =SUMIFS(Fact_Extrapolated!$F$2:$F$229,Fact_Extrapolated!$C$2:$C$229,"FIB01") -> 174.59 | D13: =IF($B$9=0,0,C13/$B$9) -> 0.12966594 | E13: =SUMIFS(Fact_Extrapolated!$F$2:$F$229,Fact_Extrapolated!$C$2:$C$229,"FIB01",Fact_Extrapolated!$G$2:$G$229,1) -> 174.59 | F13: =IF(C13=0,0,E13/C13) -> 1 | G13: =INDEX('Materials Master'!$D$2:$D$20,MATCH(B13,'Materials Master'!$B$2:$B$20,0)) -> Yes
B14: Waxed Cardboard | C14: =SUMIFS(Fact_Extrapolated!$F$2:$F$229,Fact_Extrapolated!$C$2:$C$229,"FIB02") -> 5.26 | D14: =IF($B$9=0,0,C14/$B$9) -> 0.0039065401 | E14: =SUMIFS(Fact_Extrapolated!$F$2:$F$229,Fact_Extrapolated!$C$2:$C$229,"FIB02",Fact_Extrapolated!$G$2:$G$229,1) -> 0 | F14: =IF(C14=0,0,E14/C14) -> 0 | G14: =INDEX('Materials Master'!$D$2:$D$20,MATCH(B14,'Materials Master'!$B$2:$B$20,0)) -> No
B15: Mixed Paper | C15: =SUMIFS(Fact_Extrapolated!$F$2:$F$229,Fact_Extrapolated!$C$2:$C$229,"FIB03") -> 55.14 | D15: =IF($B$9=0,0,C15/$B$9) -> 0.040951829 | E15: =SUMIFS(Fact_Extrapolated!$F$2:$F$229,Fact_Extrapolated!$C$2:$C$229,"FIB03",Fact_Extrapolated!$G$2:$G$229,1) -> 20.14 | F15: =IF(C15=0,0,E15/C15) -> 0.36525209 | G15: =INDEX('Materials Master'!$D$2:$D$20,MATCH(B15,'Materials Master'!$B$2:$B$20,0)) -> Yes
B16: Gable-top & Aseptic Cartons | C16: =SUMIFS(Fact_Extrapolated!$F$2:$F$229,Fact_Extrapolated!$C$2:$C$229,"FIB04") -> 4.92 | D16: =IF($B$9=0,0,C16/$B$9) -> 0.0036540261 | E16: =SUMIFS(Fact_Extrapolated!$F$2:$F$229,Fact_Extrapolated!$C$2:$C$229,"FIB04",Fact_Extrapolated!$G$2:$G$229,1) -> 0.9 | F16: =IF(C16=0,0,E16/C16) -> 0.18292683 | G16: =INDEX('Materials Master'!$D$2:$D$20,MATCH(B16,'Materials Master'!$B$2:$B$20,0)) -> Yes
B17: Other Coated Paper Containers | C17: =SUMIFS(Fact_Extrapolated!$F$2:$F$229,Fact_Extrapolated!$C$2:$C$229,"FIB05") -> 38.08 | D17: =IF($B$9=0,0,C17/$B$9) -> 0.028281568 | E17: =SUMIFS(Fact_Extrapolated!$F$2:$F$229,Fact_Extrapolated!$C$2:$C$229,"FIB05",Fact_Extrapolated!$G$2:$G$229,1) -> 0 | F17: =IF(C17=0,0,E17/C17) -> 0 | G17: =INDEX('Materials Master'!$D$2:$D$20,MATCH(B17,'Materials Master'!$B$2:$B$20,0)) -> No
A18: Glass | B18: Glass Bottles & Jars | C18: =SUMIFS(Fact_Extrapolated!$F$2:$F$229,Fact_Extrapolated!$C$2:$C$229,"GLA01") -> 37.97 | D18: =IF($B$9=0,0,C18/$B$9) -> 0.028199872 | E18: =SUMIFS(Fact_Extrapolated!$F$2:$F$229,Fact_Extrapolated!$C$2:$C$229,"GLA01",Fact_Extrapolated!$G$2:$G$229,1) -> 20.75 | F18: =IF(C18=0,0,E18/C18) -> 0.54648407 | G18: =INDEX('Materials Master'!$D$2:$D$20,MATCH(B18,'Materials Master'!$B$2:$B$20,0)) -> Yes
B19: Broken Glass | C19: =SUMIFS(Fact_Extrapolated!$F$2:$F$229,Fact_Extrapolated!$C$2:$C$229,"GLA02") -> 39.04 | D19: =IF($B$9=0,0,C19/$B$9) -> 0.028994549 | E19: =SUMIFS(Fact_Extrapolated!$F$2:$F$229,Fact_Extrapolated!$C$2:$C$229,"GLA02",Fact_Extrapolated!$G$2:$G$229,1) -> 0 | F19: =IF(C19=0,0,E19/C19) -> 0 | G19: =INDEX('Materials Master'!$D$2:$D$20,MATCH(B19,'Materials Master'!$B$2:$B$20,0)) -> No
A20: Metals | B20: Aluminum & Bi-metal Containers | C20: =SUMIFS(Fact_Extrapolated!$F$2:$F$229,Fact_Extrapolated!$C$2:$C$229,"MET01") -> 28.48 | D20: =IF($B$9=0,0,C20/$B$9) -> 0.021151761 | E20: =SUMIFS(Fact_Extrapolated!$F$2:$F$229,Fact_Extrapolated!$C$2:$C$229,"MET01",Fact_Extrapolated!$G$2:$G$229,1) -> 7.44 | F20: =IF(C20=0,0,E20/C20) -> 0.26123596 | G20: =INDEX('Materials Master'!$D$2:$D$20,MATCH(B20,'Materials Master'!$B$2:$B$20,0)) -> Yes
B21: Metal Hangers | C21: =SUMIFS(Fact_Extrapolated!$F$2:$F$229,Fact_Extrapolated!$C$2:$C$229,"MET02") -> 2.98 | D21: =IF($B$9=0,0,C21/$B$9) -> 0.0022132109 | E21: =SUMIFS(Fact_Extrapolated!$F$2:$F$229,Fact_Extrapolated!$C$2:$C$229,"MET02",Fact_Extrapolated!$G$2:$G$229,1) -> 0 | F21: =IF(C21=0,0,E21/C21) -> 0 | G21: =INDEX('Materials Master'!$D$2:$D$20,MATCH(B21,'Materials Master'!$B$2:$B$20,0)) -> No
A22: Plastics | B22: Rigid Plastics (1-6) | C22: =SUMIFS(Fact_Extrapolated!$F$2:$F$229,Fact_Extrapolated!$C$2:$C$229,"PLA01") -> 102.46 | D22: =IF($B$9=0,0,C22/$B$9) -> 0.076095836 | E22: =SUMIFS(Fact_Extrapolated!$F$2:$F$229,Fact_Extrapolated!$C$2:$C$229,"PLA01",Fact_Extrapolated!$G$2:$G$229,1) -> 20.4 | F22: =IF(C22=0,0,E22/C22) -> 0.19910209 | G22: =INDEX('Materials Master'!$D$2:$D$20,MATCH(B22,'Materials Master'!$B$2:$B$20,0)) -> Yes
