Workbook

Sheet Audit Info
A1: Audit Info
A3: Client Name | B3: [Client Name]
A4: Site Name | B4: Scenarios Demo Site
A5: Site Address
A6: Hauler
A7: Tenant/Area Breakouts
A8: Auditors | B8: Prototype walkthrough
A9: Audit Date | B9: 2026-07-23
A10: Site Occupancy
A11: Source | B11: Collected via tablet field form

Sheet Materials Master
A1: material_id | B1: material_name | C1: material_category | D1: currently_divertible | E1: accepted_in_program | F1: target: Trash | G1: target: GMPC Recycling | H1: target: Organics Recycling | I1: target: Cardboard Recycling | J1: target: Paper Recycling | K1: target: Terracycle
A2: FIB01 | B2: Corrugated Cardboard | C2: Fibers | D2: Yes | E2: Yes | F2: No | G2: Yes | H2: No | I2: Yes | J2: Yes | K2: No
A3: FIB02 | B3: Soiled Cardboard | C3: Fibers | D3: No | E3: No | F3: Yes | G3: No | H3: No | I3: No | J3: No | K3: No
A4: FIB03 | B4: Waxed Cardboard | C4: Fibers | D4: No | E4: No | F4: Yes | G4: No | H4: No | I4: No | J4: No | K4: No
A5: FIB04 | B5: Mixed Paper | C5: Fibers | D5: Yes | E5: Yes | F5: No | G5: Yes | H5: Yes | I5: No | J5: No | K5: No
A6: FIB05 | B6: Soiled Paper | C6: Fibers | D6: No | E6: No | F6: Yes | G6: No | H6: No | I6: No | J6: No | K6: No
A7: FIB06 | B7: Beverage Cartons | C7: Fibers | D7: Yes | E7: Yes | F7: No | G7: Yes | H7: No | I7: Yes | J7: Yes | K7: No
A8: FIB07 | B8: Soiled Beverage Cartons | C8: Fibers | D8: No | E8: No | F8: Yes | G8: No | H8: No | I8: No | J8: No | K8: No
A9: FIB08 | B9: Paper Cups / Other Coated Paper Containers | C9: Fibers | D9: No | E9: No | F9: Yes | G9: No | H9: No | I9: No | J9: No | K9: No
A10: GLA01 | B10: Glass Bottles & Jars | C10: Glass | D10: Yes | E10: Yes | F10: No | G10: Yes | H10: No | I10: Yes | J10: Yes | K10: No
A11: GLA02 | B11: Soiled Glass | C11: Glass | D11: No | E11: No | F11: Yes | G11: No | H11: No | I11: No | J11: No | K11: No
A12: MET01 | B12: Aluminum & Bi-Metal Containers | C12: Metals | D12: Yes | E12: Yes | F12: No | G12: Yes | H12: No | I12: Yes | J12: Yes | K12: No
... A27: OTH02 | B27: Other/Residual Materials | C27: Other | D27: No | E27: No | F27: Yes | G27: No | H27: No | I27: No | J27: No | K27: No

Sheet Areas
A1: area_id | B1: area_name | C1: rollup_group | D1: default_material_id
A2: OFFICES | B2: OFFICES | C2: Rest of Building
A3: CAFE_BOH | B3: CAFÉ BOH | C3: BOH
A4: LOC_C | B4: LOCATION C | C4: Rest of Building
A5: LOC_D | B5: LOCATION D | C5: Rest of Building
A6: BATHROOM | B6: BATHROOM | C6: Rest of Building | D6: ORG02

Sheet Streams
A1: stream_name | B1: combined_weigh_sort
A2: Trash | B2: No
A3: GMPC Recycling | B3: No
A4: Organics Recycling | B4: No
A5: Cardboard Recycling | B5: Yes
A6: Paper Recycling | B6: No
A7: Terracycle | B7: No

Sheet Fact_SortedWeights
A1: audit_id | B1: stream | C1: area | D1: material_id | E1: weight_lbs | F1: material_name | G1: material_category | H1: currently_divertible | I1: accepted_in_program | J1: belongs_here | K1: rollup_group | L1: non_representative | M1: notes
A2: 120PARK-2025 | B2: Trash | C2: OFFICES | D2: FIB04 | E2: 35 | F2: =IFERROR(INDEX('Materials Master'!$B$2:$B$27,MATCH(D2,'Materials Master'!$A$2:$A$27,0)),"") -> Mixed Paper | G2: =IFERROR(INDEX('Materials Master'!$C$2:$C$27,MATCH(D2,'Materials Master'!$A$2:$A$27,0)),"") -> Fibers | H2: =IFERROR(INDEX('Materials Master'!$D$2:$D$27,MATCH(D2,'Materials Master'!$A$2:$A$27,0)),"") -> Yes | I2: =IFERROR(INDEX('Materials Master'!$E$2:$E$27,MATCH(D2,'Materials Master'!$A$2:$A$27,0)),"") -> Yes | J2: =IFERROR(IF(B2="Trash",INDEX('Materials Master'!$F$2:$F$27,MATCH(D2,'Materials Master'!$A$2:$A$27,0)),IF(B2="GMPC Recycling",INDEX('Materials Master'!$G$2:$G$27,MATCH(D2,'Materials Master'!$A$2:$A$27,0)),IF(B2="Organics Recycling",INDEX('Materials Master'!$H$2:$H$27,MATCH(D2,'Materials Master'!$A$2:$A$27,0)),IF(B2="Cardboard Recycling",INDEX('Materials Master'!$I$2:$I$27,MATCH(D2,'Materials Master'!$A$2:$A$27,0)),IF(B2="Paper Recycling",INDEX('Materials Master'!$J$2:$J$27,MATCH(D2,'Materials Master'!$A$2:$A$27,0)),IF(B2="Terracycle",INDEX('Materials Master'!$K$2:$K$27,MATCH(D2,'Materials Master'!$A$2:$A$27,0)),"No")))))),"") -> No | K2: =IFERROR(INDEX(Areas!$C$2:$C$6,MATCH(C2,Areas!$B$2:$B$6,0)),"") -> Rest of Building | L2: No | M2: Typical sample
A3: 120PARK-2025 | B3: Trash | C3: OFFICES | D3: GLA02 | E3: 5 | F3: =IFERROR(INDEX('Materials Master'!$B$2:$B$27,MATCH(D3,'Materials Master'!$A$2:$A$27,0)),"") -> Soiled Glass | G3: =IFERROR(INDEX('Materials Master'!$C$2:$C$27,MATCH(D3,'Materials Master'!$A$2:$A$27,0)),"") -> Glass | H3: =IFERROR(INDEX('Materials Master'!$D$2:$D$27,MATCH(D3,'Materials Master'!$A$2:$A$27,0)),"") -> No | I3: =IFERROR(INDEX('Materials Master'!$E$2:$E$27,MATCH(D3,'Materials Master'!$A$2:$A$27,0)),"") -> No | J3: =IFERROR(IF(B3="Trash",INDEX('Materials Master'!$F$2:$F$27,MATCH(D3,'Materials Master'!$A$2:$A$27,0)),IF(B3="GMPC Recycling",INDEX('Materials Master'!$G$2:$G$27,MATCH(D3,'Materials Master'!$A$2:$A$27,0)),IF(B3="Organics Recycling",INDEX('Materials Master'!$H$2:$H$27,MATCH(D3,'Materials Master'!$A$2:$A$27,0)),IF(B3="Cardboard Recycling",INDEX('Materials Master'!$I$2:$I$27,MATCH(D3,'Materials Master'!$A$2:$A$27,0)),IF(B3="Paper Recycling",INDEX('Materials Master'!$J$2:$J$27,MATCH(D3,'Materials Master'!$A$2:$A$27,0)),IF(B3="Terracycle",INDEX('Materials Master'!$K$2:$K$27,MATCH(D3,'Materials Master'!$A$2:$A$27,0)),"No")))))),"") -> Yes | K3: =IFERROR(INDEX(Areas!$C$2:$C$6,MATCH(C3,Areas!$B$2:$B$6,0)),"") -> Rest of Building | L3: Yes | M3: One broken bottle found in the sample bag
A4: 120PARK-2025 | B4: Cardboard Recycling | C4: OFFICES | D4: FIB01 | E4: 50 | F4: =IFERROR(INDEX('Materials Master'!$B$2:$B$27,MATCH(D4,'Materials Master'!$A$2:$A$27,0)),"") -> Corrugated Cardboard | G4: =IFERROR(INDEX('Materials Master'!$C$2:$C$27,MATCH(D4,'Materials Master'!$A$2:$A$27,0)),"") -> Fibers | H4: =IFERROR(INDEX('Materials Master'!$D$2:$D$27,MATCH(D4,'Materials Master'!$A$2:$A$27,0)),"") -> Yes | I4: =IFERROR(INDEX('Materials Master'!$E$2:$E$27,MATCH(D4,'Materials Master'!$A$2:$A$27,0)),"") -> Yes | J4: =IFERROR(IF(B4="Trash",INDEX('Materials Master'!$F$2:$F$27,MATCH(D4,'Materials Master'!$A$2:$A$27,0)),IF(B4="GMPC Recycling",INDEX('Materials Master'!$G$2:$G$27,MATCH(D4,'Materials Master'!$A$2:$A$27,0)),IF(B4="Organics Recycling",INDEX('Materials Master'!$H$2:$H$27,MATCH(D4,'Materials Master'!$A$2:$A$27,0)),IF(B4="Cardboard Recycling",INDEX('Materials Master'!$I$2:$I$27,MATCH(D4,'Materials Master'!$A$2:$A$27,0)),IF(B4="Paper Recycling",INDEX('Materials Master'!$J$2:$J$27,MATCH(D4,'Materials Master'!$A$2:$A$27,0)),IF(B4="Terracycle",INDEX('Materials Master'!$K$2:$K$27,MATCH(D4,'Materials Master'!$A$2:$A$27,0)),"No")))))),"") -> Yes | K4: =IFERROR(INDEX(Areas!$C$2:$C$6,MATCH(C4,Areas!$B$2:$B$6,0)),"") -> Rest of Building | L4: No | M4: Weighed and sorted directly, no bagging step
A5: 120PARK-2025 | B5: GMPC Recycling | C5: OFFICES | D5: FIB04 | E5: 30 | F5: =IFERROR(INDEX('Materials Master'!$B$2:$B$27,MATCH(D5,'Materials Master'!$A$2:$A$27,0)),"") -> Mixed Paper | G5: =IFERROR(INDEX('Materials Master'!$C$2:$C$27,MATCH(D5,'Materials Master'!$A$2:$A$27,0)),"") -> Fibers | H5: =IFERROR(INDEX('Materials Master'!$D$2:$D$27,MATCH(D5,'Materials Master'!$A$2:$A$27,0)),"") -> Yes | I5: =IFERROR(INDEX('Materials Master'!$E$2:$E$27,MATCH(D5,'Materials Master'!$A$2:$A$27,0)),"") -> Yes | J5: =IFERROR(IF(B5="Trash",INDEX('Materials Master'!$F$2:$F$27,MATCH(D5,'Materials Master'!$A$2:$A$27,0)),IF(B5="GMPC Recycling",INDEX('Materials Master'!$G$2:$G$27,MATCH(D5,'Materials Master'!$A$2:$A$27,0)),IF(B5="Organics Recycling",INDEX('Materials Master'!$H$2:$H$27,MATCH(D5,'Materials Master'!$A$2:$A$27,0)),IF(B5="Cardboard Recycling",INDEX('Materials Master'!$I$2:$I$27,MATCH(D5,'Materials Master'!$A$2:$A$27,0)),IF(B5="Paper Recycling",INDEX('Materials Master'!$J$2:$J$27,MATCH(D5,'Materials Master'!$A$2:$A$27,0)),IF(B5="Terracycle",INDEX('Materials Master'!$K$2:$K$27,MATCH(D5,'Materials Master'!$A$2:$A$27,0)),"No")))))),"") -> Yes | K5: =IFERROR(INDEX(Areas!$C$2:$C$6,MATCH(C5,Areas!$B$2:$B$6,0)),"") -> Rest of Building | L5: No
A6: 120PARK-2025 | B6: Organics Recycling | C6: OFFICES | D6: FIB04 | E6: 20 | F6: =IFERROR(INDEX('Materials Master'!$B$2:$B$27,MATCH(D6,'Materials Master'!$A$2:$A$27,0)),"") -> Mixed Paper | G6: =IFERROR(INDEX('Materials Master'!$C$2:$C$27,MATCH(D6,'Materials Master'!$A$2:$A$27,0)),"") -> Fibers | H6: =IFERROR(INDEX('Materials Master'!$D$2:$D$27,MATCH(D6,'Materials Master'!$A$2:$A$27,0)),"") -> Yes | I6: =IFERROR(INDEX('Materials Master'!$E$2:$E$27,MATCH(D6,'Materials Master'!$A$2:$A$27,0)),"") -> Yes | J6: =IFERROR(IF(B6="Trash",INDEX('Materials Master'!$F$2:$F$27,MATCH(D6,'Materials Master'!$A$2:$A$27,0)),IF(B6="GMPC Recycling",INDEX('Materials Master'!$G$2:$G$27,MATCH(D6,'Materials Master'!$A$2:$A$27,0)),IF(B6="Organics Recycling",INDEX('Materials Master'!$H$2:$H$27,MATCH(D6,'Materials Master'!$A$2:$A$27,0)),IF(B6="Cardboard Recycling",INDEX('Materials Master'!$I$2:$I$27,MATCH(D6,'Materials Master'!$A$2:$A$27,0)),IF(B6="Paper Recycling",INDEX('Materials Master'!$J$2:$J$27,MATCH(D6,'Materials Master'!$A$2:$A$27,0)),IF(B6="Terracycle",INDEX('Materials Master'!$K$2:$K$27,MATCH(D6,'Materials Master'!$A$2:$A$27,0)),"No")))))),"") -> Yes | K6: =IFERROR(INDEX(Areas!$C$2:$C$6,MATCH(C6,Areas!$B$2:$B$6,0)),"") -> Rest of Building | L6: No | M6: Also accepted here at this site

Sheet Fact_PreSortWeights
A1: audit_id | B1: stream | C1: area | D1: bag_number | E1: weight_lbs | F1: known_material_id | G1: notes
A2: 120PARK-2025 | B2: Trash | C2: OFFICES | D2: 1 | E2: 40 | G2: Regular bag 1
A3: 120PARK-2025 | B3: Trash | C3: OFFICES | D3: 2 | E3: 40 | G3: Regular bag 2
A4: 120PARK-2025 | B4: Trash | C4: OFFICES | D4: 3 | E4: 40 | G4: Regular bag 3
A5: 120PARK-2025 | B5: Trash | C5: OFFICES | D5: 4 | E5: 40 | G5: Regular bag 4
A6: 120PARK-2025 | B6: Trash | C6: OFFICES | D6: 5 | E6: 40 | G6: Regular bag 5
A7: 120PARK-2025 | B7: Trash | C7: OFFICES | D7: 6 | E7: 40 | G7: Regular bag 6
A8: 120PARK-2025 | B8: Trash | C8: OFFICES | D8: 7 | E8: 40 | G8: Regular bag 7
A9: 120PARK-2025 | B9: Trash | C9: OFFICES | D9: 8 | E9: 40 | G9: Regular bag 8
A10: 120PARK-2025 | B10: Trash | C10: OFFICES | D10: 9 | E10: 40 | G10: Regular bag 9
A11: 120PARK-2025 | B11: Trash | C11: OFFICES | D11: 10 | E11: 40 | G11: Regular bag 10
A12: 120PARK-2025 | B12: Trash | C12: OFFICES | D12: 11 | E12: 20 | F12: FIB01 | G12: Known to be all cardboard
A13: 120PARK-2025 | B13: GMPC Recycling | C13: OFFICES | D13: 1 | E13: 30
A14: 120PARK-2025 | B14: Organics Recycling | C14: OFFICES | D14: 1 | E14: 20
A15: 120PARK-2025 | B15: Trash | C15: BATHROOM | D15: 1 | E15: 30 | G15: Not sorted for sanitary reasons

Sheet Fact_Extrapolated
A1: area | B1: stream | C1: material_id | D1: material_name | E1: material_category | F1: extrapolated_weight_lbs | G1: correctly_placed | H1: accepted_in_program | I1: rollup_group | J1: belongs_here
A2: OFFICES | B2: Trash | C2: FIB01 | D2: =IFERROR(INDEX('Materials Master'!$B$2:$B$27,MATCH($C2,'Materials Master'!$A$2:$A$27,0)),"") -> Corrugated Cardboard | E2: =IFERROR(INDEX('Materials Master'!$C$2:$C$27,MATCH($C2,'Materials Master'!$A$2:$A$27,0)),"") -> Fibers | F2: =(SUMIFS(Fact_PreSortWeights!$E$2:$E$15,Fact_PreSortWeights!$C$2:$C$15,$A2,Fact_PreSortWeights!$B$2:$B$15,$B2,Fact_PreSortWeights!$F$2:$F$15,$C2))+(SUMIFS(Fact_SortedWeights!$E$2:$E$6,Fact_SortedWeights!$C$2:$C$6,$A2,Fact_SortedWeights!$B$2:$B$6,$B2,Fact_SortedWeights!$D$2:$D$6,$C2,Fact_SortedWeights!$L$2:$L$6,"Yes"))+IF((SUMIFS(Fact_SortedWeights!$E$2:$E$6,Fact_SortedWeights!$C$2:$C$6,$A2,Fact_SortedWeights!$B$2:$B$6,$B2,Fact_SortedWeights!$L$2:$L$6,"No"))=0,0,(SUMIFS(Fact_SortedWeights!$E$2:$E$6,Fact_SortedWeights!$C$2:$C$6,$A2,Fact_SortedWeights!$B$2:$B$6,$B2,Fact_SortedWeights!$D$2:$D$6,$C2,Fact_SortedWeights!$L$2:$L$6,"No"))/(SUMIFS(Fact_SortedWeights!$E$2:$E$6,Fact_SortedWeights!$C$2:$C$6,$A2,Fact_SortedWeights!$B$2:$B$6,$B2,Fact_SortedWeights!$L$2:$L$6,"No"))*((SUMIFS(Fact_PreSortWeights!$E$2:$E$15,Fact_PreSortWeights!$C$2:$C$15,$A2,Fact_PreSortWeights!$B$2:$B$15,$B2,Fact_PreSortWeights!$F$2:$F$15,""))-(SUMIFS(Fact_SortedWeights!$E$2:$E$6,Fact_SortedWeights!$C$2:$C$6,$A2,Fact_SortedWeights!$B$2:$B$6,$B2,Fact_SortedWeights!$L$2:$L$6,"Yes")))) -> 20 | G2: =IF(AND(IF($B2="Trash",INDEX('Materials Master'!$F$2:$F$27,MATCH($C2,'Materials Master'!$A$2:$A$27,0)),IF($B2="GMPC Recycling",INDEX('Materials Master'!$G$2:$G$27,MATCH($C2,'Materials Master'!$A$2:$A$27,0)),IF($B2="Organics Recycling",INDEX('Materials Master'!$H$2:$H$27,MATCH($C2,'Materials Master'!$A$2:$A$27,0)),IF($B2="Cardboard Recycling",INDEX('Materials Master'!$I$2:$I$27,MATCH($C2,'Materials Master'!$A$2:$A$27,0)),IF($B2="Paper Recycling",INDEX('Materials Master'!$J$2:$J$27,MATCH($C2,'Materials Master'!$A$2:$A$27,0)),IF($B2="Terracycle",INDEX('Materials Master'!$K$2:$K$27,MATCH($C2,'Materials Master'!$A$2:$A$27,0)),"No"))))))="Yes",INDEX('Materials Master'!$E$2:$E$27,MATCH($C2,'Materials Master'!$A$2:$A$27,0))="Yes",$B2<>"Trash"),1,0) -> 0 | H2: =INDEX('Materials Master'!$E$2:$E$27,MATCH($C2,'Materials Master'!$A$2:$A$27,0)) -> Yes | I2: =IFERROR(INDEX(Areas!$C$2:$C$6,MATCH($A2,Areas!$B$2:$B$6,0)),"") -> Rest of Building | J2: =IF(IF($B2="Trash",INDEX('Materials Master'!$F$2:$F$27,MATCH($C2,'Materials Master'!$A$2:$A$27,0)),IF($B2="GMPC Recycling",INDEX('Materials Master'!$G$2:$G$27,MATCH($C2,'Materials Master'!$A$2:$A$27,0)),IF($B2="Organics Recycling",INDEX('Materials Master'!$H$2:$H$27,MATCH($C2,'Materials Master'!$A$2:$A$27,0)),IF($B2="Cardboard Recycling",INDEX('Materials Master'!$I$2:$I$27,MATCH($C2,'Materials Master'!$A$2:$A$27,0)),IF($B2="Paper Recycling",INDEX('Materials Master'!$J$2:$J$27,MATCH($C2,'Materials Master'!$A$2:$A$27,0)),IF($B2="Terracycle",INDEX('Materials Master'!$K$2:$K$27,MATCH($C2,'Materials Master'!$A$2:$A$27,0)),"No"))))))="Yes",1,0) -> 0
A3: OFFICES | B3: Trash | C3: FIB02 | D3: =IFERROR(INDEX('Materials Master'!$B$2:$B$27,MATCH($C3,'Materials Master'!$A$2:$A$27,0)),"") -> Soiled Cardboard | E3: =IFERROR(INDEX('Materials Master'!$C$2:$C$27,MATCH($C3,'Materials Master'!$A$2:$A$27,0)),"") -> Fibers | F3: =(SUMIFS(Fact_PreSortWeights!$E$2:$E$15,Fact_PreSortWeights!$C$2:$C$15,$A3,Fact_PreSortWeights!$B$2:$B$15,$B3,Fact_PreSortWeights!$F$2:$F$15,$C3))+(SUMIFS(Fact_SortedWeights!$E$2:$E$6,Fact_SortedWeights!$C$2:$C$6,$A3,Fact_SortedWeights!$B$2:$B$6,$B3,Fact_SortedWeights!$D$2:$D$6,$C3,Fact_SortedWeights!$L$2:$L$6,"Yes"))+IF((SUMIFS(Fact_SortedWeights!$E$2:$E$6,Fact_SortedWeights!$C$2:$C$6,$A3,Fact_SortedWeights!$B$2:$B$6,$B3,Fact_SortedWeights!$L$2:$L$6,"No"))=0,0,(SUMIFS(Fact_SortedWeights!$E$2:$E$6,Fact_SortedWeights!$C$2:$C$6,$A3,Fact_SortedWeights!$B$2:$B$6,$B3,Fact_SortedWeights!$D$2:$D$6,$C3,Fact_SortedWeights!$L$2:$L$6,"No"))/(SUMIFS(Fact_SortedWeights!$E$2:$E$6,Fact_SortedWeights!$C$2:$C$6,$A3,Fact_SortedWeights!$B$2:$B$6,$B3,Fact_SortedWeights!$L$2:$L$6,"No"))*((SUMIFS(Fact_PreSortWeights!$E$2:$E$15,Fact_PreSortWeights!$C$2:$C$15,$A3,Fact_PreSortWeights!$B$2:$B$15,$B3,Fact_PreSortWeights!$F$2:$F$15,""))-(SUMIFS(Fact_SortedWeights!$E$2:$E$6,Fact_SortedWeights!$C$2:$C$6,$A3,Fact_SortedWeights!$B$2:$B$6,$B3,Fact_SortedWeights!$L$2:$L$6,"Yes")))) -> 0 | G3: =IF(AND(IF($B3="Trash",INDEX('Materials Master'!$F$2:$F$27,MATCH($C3,'Materials Master'!$A$2:$A$27,0)),IF($B3="GMPC Recycling",INDEX('Materials Master'!$G$2:$G$27,MATCH($C3,'Materials Master'!$A$2:$A$27,0)),IF($B3="Organics Recycling",INDEX('Materials Master'!$H$2:$H$27,MATCH($C3,'Materials Master'!$A$2:$A$27,0)),IF($B3="Cardboard Recycling",INDEX('Materials Master'!$I$2:$I$27,MATCH($C3,'Materials Master'!$A$2:$A$27,0)),IF($B3="Paper Recycling",INDEX('Materials Master'!$J$2:$J$27,MATCH($C3,'Materials Master'!$A$2:$A$27,0)),IF($B3="Terracycle",INDEX('Materials Master'!$K$2:$K$27,MATCH($C3,'Materials Master'!$A$2:$A$27,0)),"No"))))))="Yes",INDEX('Materials Master'!$E$2:$E$27,MATCH($C3,'Materials Master'!$A$2:$A$27,0))="Yes",$B3<>"Trash"),1,0) -> 0 | H3: =INDEX('Materials Master'!$E$2:$E$27,MATCH($C3,'Materials Master'!$A$2:$A$27,0)) -> No | I3: =IFERROR(INDEX(Areas!$C$2:$C$6,MATCH($A3,Areas!$B$2:$B$6,0)),"") -> Rest of Building | J3: =IF(IF($B3="Trash",INDEX('Materials Master'!$F$2:$F$27,MATCH($C3,'Materials Master'!$A$2:$A$27,0)),IF($B3="GMPC Recycling",INDEX('Materials Master'!$G$2:$G$27,MATCH($C3,'Materials Master'!$A$2:$A$27,0)),IF($B3="Organics Recycling",INDEX('Materials Master'!$H$2:$H$27,MATCH($C3,'Materials Master'!$A$2:$A$27,0)),IF($B3="Cardboard Recycling",INDEX('Materials Master'!$I$2:$I$27,MATCH($C3,'Materials Master'!$A$2:$A$27,0)),IF($B3="Paper Recycling",INDEX('Materials Master'!$J$2:$J$27,MATCH($C3,'Materials Master'!$A$2:$A$27,0)),IF($B3="Terracycle",INDEX('Materials Master'!$K$2:$K$27,MATCH($C3,'Materials Master'!$A$2:$A$27,0)),"No"))))))="Yes",1,0) -> 1
A4: OFFICES | B4: Trash | C4: FIB03 | D4: =IFERROR(INDEX('Materials Master'!$B$2:$B$27,MATCH($C4,'Materials Master'!$A$2:$A$27,0)),"") -> Waxed Cardboard | E4: =IFERROR(INDEX('Materials Master'!$C$2:$C$27,MATCH($C4,'Materials Master'!$A$2:$A$27,0)),"") -> Fibers | F4: =(SUMIFS(Fact_PreSortWeights!$E$2:$E$15,Fact_PreSortWeights!$C$2:$C$15,$A4,Fact_PreSortWeights!$B$2:$B$15,$B4,Fact_PreSortWeights!$F$2:$F$15,$C4))+(SUMIFS(Fact_SortedWeights!$E$2:$E$6,Fact_SortedWeights!$C$2:$C$6,$A4,Fact_SortedWeights!$B$2:$B$6,$B4,Fact_SortedWeights!$D$2:$D$6,$C4,Fact_SortedWeights!$L$2:$L$6,"Yes"))+IF((SUMIFS(Fact_SortedWeights!$E$2:$E$6,Fact_SortedWeights!$C$2:$C$6,$A4,Fact_SortedWeights!$B$2:$B$6,$B4,Fact_SortedWeights!$L$2:$L$6,"No"))=0,0,(SUMIFS(Fact_SortedWeights!$E$2:$E$6,Fact_SortedWeights!$C$2:$C$6,$A4,Fact_SortedWeights!$B$2:$B$6,$B4,Fact_SortedWeights!$D$2:$D$6,$C4,Fact_SortedWeights!$L$2:$L$6,"No"))/(SUMIFS(Fact_SortedWeights!$E$2:$E$6,Fact_SortedWeights!$C$2:$C$6,$A4,Fact_SortedWeights!$B$2:$B$6,$B4,Fact_SortedWeights!$L$2:$L$6,"No"))*((SUMIFS(Fact_PreSortWeights!$E$2:$E$15,Fact_PreSortWeights!$C$2:$C$15,$A4,Fact_PreSortWeights!$B$2:$B$15,$B4,Fact_PreSortWeights!$F$2:$F$15,""))-(SUMIFS(Fact_SortedWeights!$E$2:$E$6,Fact_SortedWeights!$C$2:$C$6,$A4,Fact_SortedWeights!$B$2:$B$6,$B4,Fact_SortedWeights!$L$2:$L$6,"Yes")))) -> 0 | G4: =IF(AND(IF($B4="Trash",INDEX('Materials Master'!$F$2:$F$27,MATCH($C4,'Materials Master'!$A$2:$A$27,0)),IF($B4="GMPC Recycling",INDEX('Materials Master'!$G$2:$G$27,MATCH($C4,'Materials Master'!$A$2:$A$27,0)),IF($B4="Organics Recycling",INDEX('Materials Master'!$H$2:$H$27,MATCH($C4,'Materials Master'!$A$2:$A$27,0)),IF($B4="Cardboard Recycling",INDEX('Materials Master'!$I$2:$I$27,MATCH($C4,'Materials Master'!$A$2:$A$27,0)),IF($B4="Paper Recycling",INDEX('Materials Master'!$J$2:$J$27,MATCH($C4,'Materials Master'!$A$2:$A$27,0)),IF($B4="Terracycle",INDEX('Materials Master'!$K$2:$K$27,MATCH($C4,'Materials Master'!$A$2:$A$27,0)),"No"))))))="Yes",INDEX('Materials Master'!$E$2:$E$27,MATCH($C4,'Materials Master'!$A$2:$A$27,0))="Yes",$B4<>"Trash"),1,0) -> 0 | H4: =INDEX('Materials Master'!$E$2:$E$27,MATCH($C4,'Materials Master'!$A$2:$A$27,0)) -> No | I4: =IFERROR(INDEX(Areas!$C$2:$C$6,MATCH($A4,Areas!$B$2:$B$6,0)),"") -> Rest of Building | J4: =IF(IF($B4="Trash",INDEX('Materials Master'!$F$2:$F$27,MATCH($C4,'Materials Master'!$A$2:$A$27,0)),IF($B4="GMPC Recycling",INDEX('Materials Master'!$G$2:$G$27,MATCH($C4,'Materials Master'!$A$2:$A$27,0)),IF($B4="Organics Recycling",INDEX('Materials Master'!$H$2:$H$27,MATCH($C4,'Materials Master'!$A$2:$A$27,0)),IF($B4="Cardboard Recycling",INDEX('Materials Master'!$I$2:$I$27,MATCH($C4,'Materials Master'!$A$2:$A$27,0)),IF($B4="Paper Recycling",INDEX('Materials Master'!$J$2:$J$27,MATCH($C4,'Materials Master'!$A$2:$A$27,0)),IF($B4="Terracycle",INDEX('Materials Master'!$K$2:$K$27,MATCH($C4,'Materials Master'!$A$2:$A$27,0)),"No"))))))="Yes",1,0) -> 1
A5: OFFICES | B5: Trash | C5: FIB04 | D5: =IFERROR(INDEX('Materials Master'!$B$2:$B$27,MATCH($C5,'Materials Master'!$A$2:$A$27,0)),"") -> Mixed Paper | E5: =IFERROR(INDEX('Materials Master'!$C$2:$C$27,MATCH($C5,'Materials Master'!$A$2:$A$27,0)),"") -> Fibers | F5: =(SUMIFS(Fact_PreSortWeights!$E$2:$E$15,Fact_PreSortWeights!$C$2:$C$15,$A5,Fact_PreSortWeights!$B$2:$B$15,$B5,Fact_PreSortWeights!$F$2:$F$15,$C5))+(SUMIFS(Fact_SortedWeights!$E$2:$E$6,Fact_SortedWeights!$C$2:$C$6,$A5,Fact_SortedWeights!$B$2:$B$6,$B5,Fact_SortedWeights!$D$2:$D$6,$C5,Fact_SortedWeights!$L$2:$L$6,"Yes"))+IF((SUMIFS(Fact_SortedWeights!$E$2:$E$6,Fact_SortedWeights!$C$2:$C$6,$A5,Fact_SortedWeights!$B$2:$B$6,$B5,Fact_SortedWeights!$L$2:$L$6,"No"))=0,0,(SUMIFS(Fact_SortedWeights!$E$2:$E$6,Fact_SortedWeights!$C$2:$C$6,$A5,Fact_SortedWeights!$B$2:$B$6,$B5,Fact_SortedWeights!$D$2:$D$6,$C5,Fact_SortedWeights!$L$2:$L$6,"No"))/(SUMIFS(Fact_SortedWeights!$E$2:$E$6,Fact_SortedWeights!$C$2:$C$6,$A5,Fact_SortedWeights!$B$2:$B$6,$B5,Fact_SortedWeights!$L$2:$L$6,"No"))*((SUMIFS(Fact_PreSortWeights!$E$2:$E$15,Fact_PreSortWeights!$C$2:$C$15,$A5,Fact_PreSortWeights!$B$2:$B$15,$B5,Fact_PreSortWeights!$F$2:$F$15,""))-(SUMIFS(Fact_SortedWeights!$E$2:$E$6,Fact_SortedWeights!$C$2:$C$6,$A5,Fact_SortedWeights!$B$2:$B$6,$B5,Fact_SortedWeights!$L$2:$L$6,"Yes")))) -> 395 | G5: =IF(AND(IF($B5="Trash",INDEX('Materials Master'!$F$2:$F$27,MATCH($C5,'Materials Master'!$A$2:$A$27,0)),IF($B5="GMPC Recycling",INDEX('Materials Master'!$G$2:$G$27,MATCH($C5,'Materials Master'!$A$2:$A$27,0)),IF($B5="Organics Recycling",INDEX('Materials Master'!$H$2:$H$27,MATCH($C5,'Materials Master'!$A$2:$A$27,0)),IF($B5="Cardboard Recycling",INDEX('Materials Master'!$I$2:$I$27,MATCH($C5,'Materials Master'!$A$2:$A$27,0)),IF($B5="Paper Recycling",INDEX('Materials Master'!$J$2:$J$27,MATCH($C5,'Materials Master'!$A$2:$A$27,0)),IF($B5="Terracycle",INDEX('Materials Master'!$K$2:$K$27,MATCH($C5,'Materials Master'!$A$2:$A$27,0)),"No"))))))="Yes",INDEX('Materials Master'!$E$2:$E$27,MATCH($C5,'Materials Master'!$A$2:$A$27,0))="Yes",$B5<>"Trash"),1,0) -> 0 | H5: =INDEX('Materials Master'!$E$2:$E$27,MATCH($C5,'Materials Master'!$A$2:$A$27,0)) -> Yes | I5: =IFERROR(INDEX(Areas!$C$2:$C$6,MATCH($A5,Areas!$B$2:$B$6,0)),"") -> Rest of Building | J5: =IF(IF($B5="Trash",INDEX('Materials Master'!$F$2:$F$27,MATCH($C5,'Materials Master'!$A$2:$A$27,0)),IF($B5="GMPC Recycling",INDEX('Materials Master'!$G$2:$G$27,MATCH($C5,'Materials Master'!$A$2:$A$27,0)),IF($B5="Organics Recycling",INDEX('Materials Master'!$H$2:$H$27,MATCH($C5,'Materials Master'!$A$2:$A$27,0)),IF($B5="Cardboard Recycling",INDEX('Materials Master'!$I$2:$I$27,MATCH($C5,'Materials Master'!$A$2:$A$27,0)),IF($B5="Paper Recycling",INDEX('Materials Master'!$J$2:$J$27,MATCH($C5,'Materials Master'!$A$2:$A$27,0)),IF($B5="Terracycle",INDEX('Materials Master'!$K$2:$K$27,MATCH($C5,'Materials Master'!$A$2:$A$27,0)),"No"))))))="Yes",1,0) -> 0
A6: OFFICES | B6: Trash | C6: FIB05 | D6: =IFERROR(INDEX('Materials Master'!$B$2:$B$27,MATCH($C6,'Materials Master'!$A$2:$A$27,0)),"") -> Soiled Paper | E6: =IFERROR(INDEX('Materials Master'!$C$2:$C$27,MATCH($C6,'Materials Master'!$A$2:$A$27,0)),"") -> Fibers | F6: =(SUMIFS(Fact_PreSortWeights!$E$2:$E$15,Fact_PreSortWeights!$C$2:$C$15,$A6,Fact_PreSortWeights!$B$2:$B$15,$B6,Fact_PreSortWeights!$F$2:$F$15,$C6))+(SUMIFS(Fact_SortedWeights!$E$2:$E$6,Fact_SortedWeights!$C$2:$C$6,$A6,Fact_SortedWeights!$B$2:$B$6,$B6,Fact_SortedWeights!$D$2:$D$6,$C6,Fact_SortedWeights!$L$2:$L$6,"Yes"))+IF((SUMIFS(Fact_SortedWeights!$E$2:$E$6,Fact_SortedWeights!$C$2:$C$6,$A6,Fact_SortedWeights!$B$2:$B$6,$B6,Fact_SortedWeights!$L$2:$L$6,"No"))=0,0,(SUMIFS(Fact_SortedWeights!$E$2:$E$6,Fact_SortedWeights!$C$2:$C$6,$A6,Fact_SortedWeights!$B$2:$B$6,$B6,Fact_SortedWeights!$D$2:$D$6,$C6,Fact_SortedWeights!$L$2:$L$6,"No"))/(SUMIFS(Fact_SortedWeights!$E$2:$E$6,Fact_SortedWeights!$C$2:$C$6,$A6,Fact_SortedWeights!$B$2:$B$6,$B6,Fact_SortedWeights!$L$2:$L$6,"No"))*((SUMIFS(Fact_PreSortWeights!$E$2:$E$15,Fact_PreSortWeights!$C$2:$C$15,$A6,Fact_PreSortWeights!$B$2:$B$15,$B6,Fact_PreSortWeights!$F$2:$F$15,""))-(SUMIFS(Fact_SortedWeights!$E$2:$E$6,Fact_SortedWeights!$C$2:$C$6,$A6,Fact_SortedWeights!$B$2:$B$6,$B6,Fact_SortedWeights!$L$2:$L$6,"Yes")))) -> 0 | G6: =IF(AND(IF($B6="Trash",INDEX('Materials Master'!$F$2:$F$27,MATCH($C6,'Materials Master'!$A$2:$A$27,0)),IF($B6="GMPC Recycling",INDEX('Materials Master'!$G$2:$G$27,MATCH($C6,'Materials Master'!$A$2:$A$27,0)),IF($B6="Organics Recycling",INDEX('Materials Master'!$H$2:$H$27,MATCH($C6,'Materials Master'!$A$2:$A$27,0)),IF($B6="Cardboard Recycling",INDEX('Materials Master'!$I$2:$I$27,MATCH($C6,'Materials Master'!$A$2:$A$27,0)),IF($B6="Paper Recycling",INDEX('Materials Master'!$J$2:$J$27,MATCH($C6,'Materials Master'!$A$2:$A$27,0)),IF($B6="Terracycle",INDEX('Materials Master'!$K$2:$K$27,MATCH($C6,'Materials Master'!$A$2:$A$27,0)),"No"))))))="Yes",INDEX('Materials Master'!$E$2:$E$27,MATCH($C6,'Materials Master'!$A$2:$A$27,0))="Yes",$B6<>"Trash"),1,0) -> 0 | H6: =INDEX('Materials Master'!$E$2:$E$27,MATCH($C6,'Materials Master'!$A$2:$A$27,0)) -> No | I6: =IFERROR(INDEX(Areas!$C$2:$C$6,MATCH($A6,Areas!$B$2:$B$6,0)),"") -> Rest of Building | J6: =IF(IF($B6="Trash",INDEX('Materials Master'!$F$2:$F$27,MATCH($C6,'Materials Master'!$A$2:$A$27,0)),IF($B6="GMPC Recycling",INDEX('Materials Master'!$G$2:$G$27,MATCH($C6,'Materials Master'!$A$2:$A$27,0)),IF($B6="Organics Recycling",INDEX('Materials Master'!$H$2:$H$27,MATCH($C6,'Materials Master'!$A$2:$A$27,0)),IF($B6="Cardboard Recycling",INDEX('Materials Master'!$I$2:$I$27,MATCH($C6,'Materials Master'!$A$2:$A$27,0)),IF($B6="Paper Recycling",INDEX('Materials Master'!$J$2:$J$27,MATCH($C6,'Materials Master'!$A$2:$A$27,0)),IF($B6="Terracycle",INDEX('Materials Master'!$K$2:$K$27,MATCH($C6,'Materials Master'!$A$2:$A$27,0)),"No"))))))="Yes",1,0) -> 1
A7: OFFICES | B7: Trash | C7: FIB06 | D7: =IFERROR(INDEX('Materials Master'!$B$2:$B$27,MATCH($C7,'Materials Master'!$A$2:$A$27,0)),"") -> Beverage Cartons | E7: =IFERROR(INDEX('Materials Master'!$C$2:$C$27,MATCH($C7,'Materials Master'!$A$2:$A$27,0)),"") -> Fibers | F7: =(SUMIFS(Fact_PreSortWeights!$E$2:$E$15,Fact_PreSortWeights!$C$2:$C$15,$A7,Fact_PreSortWeights!$B$2:$B$15,$B7,Fact_PreSortWeights!$F$2:$F$15,$C7))+(SUMIFS(Fact_SortedWeights!$E$2:$E$6,Fact_SortedWeights!$C$2:$C$6,$A7,Fact_SortedWeights!$B$2:$B$6,$B7,Fact_SortedWeights!$D$2:$D$6,$C7,Fact_SortedWeights!$L$2:$L$6,"Yes"))+IF((SUMIFS(Fact_SortedWeights!$E$2:$E$6,Fact_SortedWeights!$C$2:$C$6,$A7,Fact_SortedWeights!$B$2:$B$6,$B7,Fact_SortedWeights!$L$2:$L$6,"No"))=0,0,(SUMIFS(Fact_SortedWeights!$E$2:$E$6,Fact_SortedWeights!$C$2:$C$6,$A7,Fact_SortedWeights!$B$2:$B$6,$B7,Fact_SortedWeights!$D$2:$D$6,$C7,Fact_SortedWeights!$L$2:$L$6,"No"))/(SUMIFS(Fact_SortedWeights!$E$2:$E$6,Fact_SortedWeights!$C$2:$C$6,$A7,Fact_SortedWeights!$B$2:$B$6,$B7,Fact_SortedWeights!$L$2:$L$6,"No"))*((SUMIFS(Fact_PreSortWeights!$E$2:$E$15,Fact_PreSortWeights!$C$2:$C$15,$A7,Fact_PreSortWeights!$B$2:$B$15,$B7,Fact_PreSortWeights!$F$2:$F$15,""))-(SUMIFS(Fact_SortedWeights!$E$2:$E$6,Fact_SortedWeights!$C$2:$C$6,$A7,Fact_SortedWeights!$B$2:$B$6,$B7,Fact_SortedWeights!$L$2:$L$6,"Yes")))) -> 0 | G7: =IF(AND(IF($B7="Trash",INDEX('Materials Master'!$F$2:$F$27,MATCH($C7,'Materials Master'!$A$2:$A$27,0)),IF($B7="GMPC Recycling",INDEX('Materials Master'!$G$2:$G$27,MATCH($C7,'Materials Master'!$A$2:$A$27,0)),IF($B7="Organics Recycling",INDEX('Materials Master'!$H$2:$H$27,MATCH($C7,'Materials Master'!$A$2:$A$27,0)),IF($B7="Cardboard Recycling",INDEX('Materials Master'!$I$2:$I$27,MATCH($C7,'Materials Master'!$A$2:$A$27,0)),IF($B7="Paper Recycling",INDEX('Materials Master'!$J$2:$J$27,MATCH($C7,'Materials Master'!$A$2:$A$27,0)),IF($B7="Terracycle",INDEX('Materials Master'!$K$2:$K$27,MATCH($C7,'Materials Master'!$A$2:$A$27,0)),"No"))))))="Yes",INDEX('Materials Master'!$E$2:$E$27,MATCH($C7,'Materials Master'!$A$2:$A$27,0))="Yes",$B7<>"Trash"),1,0) -> 0 | H7: =INDEX('Materials Master'!$E$2:$E$27,MATCH($C7,'Materials Master'!$A$2:$A$27,0)) -> Yes | I7: =IFERROR(INDEX(Areas!$C$2:$C$6,MATCH($A7,Areas!$B$2:$B$6,0)),"") -> Rest of Building | J7: =IF(IF($B7="Trash",INDEX('Materials Master'!$F$2:$F$27,MATCH($C7,'Materials Master'!$A$2:$A$27,0)),IF($B7="GMPC Recycling",INDEX('Materials Master'!$G$2:$G$27,MATCH($C7,'Materials Master'!$A$2:$A$27,0)),IF($B7="Organics Recycling",INDEX('Materials Master'!$H$2:$H$27,MATCH($C7,'Materials Master'!$A$2:$A$27,0)),IF($B7="Cardboard Recycling",INDEX('Materials Master'!$I$2:$I$27,MATCH($C7,'Materials Master'!$A$2:$A$27,0)),IF($B7="Paper Recycling",INDEX('Materials Master'!$J$2:$J$27,MATCH($C7,'Materials Master'!$A$2:$A$27,0)),IF($B7="Terracycle",INDEX('Materials Master'!$K$2:$K$27,MATCH($C7,'Materials Master'!$A$2:$A$27,0)),"No"))))))="Yes",1,0) -> 0
A8: OFFICES | B8: Trash | C8: FIB07 | D8: =IFERROR(INDEX('Materials Master'!$B$2:$B$27,MATCH($C8,'Materials Master'!$A$2:$A$27,0)),"") -> Soiled Beverage Cartons | E8: =IFERROR(INDEX('Materials Master'!$C$2:$C$27,MATCH($C8,'Materials Master'!$A$2:$A$27,0)),"") -> Fibers | F8: =(SUMIFS(Fact_PreSortWeights!$E$2:$E$15,Fact_PreSortWeights!$C$2:$C$15,$A8,Fact_PreSortWeights!$B$2:$B$15,$B8,Fact_PreSortWeights!$F$2:$F$15,$C8))+(SUMIFS(Fact_SortedWeights!$E$2:$E$6,Fact_SortedWeights!$C$2:$C$6,$A8,Fact_SortedWeights!$B$2:$B$6,$B8,Fact_SortedWeights!$D$2:$D$6,$C8,Fact_SortedWeights!$L$2:$L$6,"Yes"))+IF((SUMIFS(Fact_SortedWeights!$E$2:$E$6,Fact_SortedWeights!$C$2:$C$6,$A8,Fact_SortedWeights!$B$2:$B$6,$B8,Fact_SortedWeights!$L$2:$L$6,"No"))=0,0,(SUMIFS(Fact_SortedWeights!$E$2:$E$6,Fact_SortedWeights!$C$2:$C$6,$A8,Fact_SortedWeights!$B$2:$B$6,$B8,Fact_SortedWeights!$D$2:$D$6,$C8,Fact_SortedWeights!$L$2:$L$6,"No"))/(SUMIFS(Fact_SortedWeights!$E$2:$E$6,Fact_SortedWeights!$C$2:$C$6,$A8,Fact_SortedWeights!$B$2:$B$6,$B8,Fact_SortedWeights!$L$2:$L$6,"No"))*((SUMIFS(Fact_PreSortWeights!$E$2:$E$15,Fact_PreSortWeights!$C$2:$C$15,$A8,Fact_PreSortWeights!$B$2:$B$15,$B8,Fact_PreSortWeights!$F$2:$F$15,""))-(SUMIFS(Fact_SortedWeights!$E$2:$E$6,Fact_SortedWeights!$C$2:$C$6,$A8,Fact_SortedWeights!$B$2:$B$6,$B8,Fact_SortedWeights!$L$2:$L$6,"Yes")))) -> 0 | G8: =IF(AND(IF($B8="Trash",INDEX('Materials Master'!$F$2:$F$27,MATCH($C8,'Materials Master'!$A$2:$A$27,0)),IF($B8="GMPC Recycling",INDEX('Materials Master'!$G$2:$G$27,MATCH($C8,'Materials Master'!$A$2:$A$27,0)),IF($B8="Organics Recycling",INDEX('Materials Master'!$H$2:$H$27,MATCH($C8,'Materials Master'!$A$2:$A$27,0)),IF($B8="Cardboard Recycling",INDEX('Materials Master'!$I$2:$I$27,MATCH($C8,'Materials Master'!$A$2:$A$27,0)),IF($B8="Paper Recycling",INDEX('Materials Master'!$J$2:$J$27,MATCH($C8,'Materials Master'!$A$2:$A$27,0)),IF($B8="Terracycle",INDEX('Materials Master'!$K$2:$K$27,MATCH($C8,'Materials Master'!$A$2:$A$27,0)),"No"))))))="Yes",INDEX('Materials Master'!$E$2:$E$27,MATCH($C8,'Materials Master'!$A$2:$A$27,0))="Yes",$B8<>"Trash"),1,0) -> 0 | H8: =INDEX('Materials Master'!$E$2:$E$27,MATCH($C8,'Materials Master'!$A$2:$A$27,0)) -> No | I8: =IFERROR(INDEX(Areas!$C$2:$C$6,MATCH($A8,Areas!$B$2:$B$6,0)),"") -> Rest of Building | J8: =IF(IF($B8="Trash",INDEX('Materials Master'!$F$2:$F$27,MATCH($C8,'Materials Master'!$A$2:$A$27,0)),IF($B8="GMPC Recycling",INDEX('Materials Master'!$G$2:$G$27,MATCH($C8,'Materials Master'!$A$2:$A$27,0)),IF($B8="Organics Recycling",INDEX('Materials Master'!$H$2:$H$27,MATCH($C8,'Materials Master'!$A$2:$A$27,0)),IF($B8="Cardboard Recycling",INDEX('Materials Master'!$I$2:$I$27,MATCH($C8,'Materials Master'!$A$2:$A$27,0)),IF($B8="Paper Recycling",INDEX('Materials Master'!$J$2:$J$27,MATCH($C8,'Materials Master'!$A$2:$A$27,0)),IF($B8="Terracycle",INDEX('Materials Master'!$K$2:$K$27,MATCH($C8,'Materials Master'!$A$2:$A$27,0)),"No"))))))="Yes",1,0) -> 1
A9: OFFICES | B9: Trash | C9: FIB08 | D9: =IFERROR(INDEX('Materials Master'!$B$2:$B$27,MATCH($C9,'Materials Master'!$A$2:$A$27,0)),"") -> Paper Cups / Other Coated Paper Containers | E9: =IFERROR(INDEX('Materials Master'!$C$2:$C$27,MATCH($C9,'Materials Master'!$A$2:$A$27,0)),"") -> Fibers | F9: =(SUMIFS(Fact_PreSortWeights!$E$2:$E$15,Fact_PreSortWeights!$C$2:$C$15,$A9,Fact_PreSortWeights!$B$2:$B$15,$B9,Fact_PreSortWeights!$F$2:$F$15,$C9))+(SUMIFS(Fact_SortedWeights!$E$2:$E$6,Fact_SortedWeights!$C$2:$C$6,$A9,Fact_SortedWeights!$B$2:$B$6,$B9,Fact_SortedWeights!$D$2:$D$6,$C9,Fact_SortedWeights!$L$2:$L$6,"Yes"))+IF((SUMIFS(Fact_SortedWeights!$E$2:$E$6,Fact_SortedWeights!$C$2:$C$6,$A9,Fact_SortedWeights!$B$2:$B$6,$B9,Fact_SortedWeights!$L$2:$L$6,"No"))=0,0,(SUMIFS(Fact_SortedWeights!$E$2:$E$6,Fact_SortedWeights!$C$2:$C$6,$A9,Fact_SortedWeights!$B$2:$B$6,$B9,Fact_SortedWeights!$D$2:$D$6,$C9,Fact_SortedWeights!$L$2:$L$6,"No"))/(SUMIFS(Fact_SortedWeights!$E$2:$E$6,Fact_SortedWeights!$C$2:$C$6,$A9,Fact_SortedWeights!$B$2:$B$6,$B9,Fact_SortedWeights!$L$2:$L$6,"No"))*((SUMIFS(Fact_PreSortWeights!$E$2:$E$15,Fact_PreSortWeights!$C$2:$C$15,$A9,Fact_PreSortWeights!$B$2:$B$15,$B9,Fact_PreSortWeights!$F$2:$F$15,""))-(SUMIFS(Fact_SortedWeights!$E$2:$E$6,Fact_SortedWeights!$C$2:$C$6,$A9,Fact_SortedWeights!$B$2:$B$6,$B9,Fact_SortedWeights!$L$2:$L$6,"Yes")))) -> 0 | G9: =IF(AND(IF($B9="Trash",INDEX('Materials Master'!$F$2:$F$27,MATCH($C9,'Materials Master'!$A$2:$A$27,0)),IF($B9="GMPC Recycling",INDEX('Materials Master'!$G$2:$G$27,MATCH($C9,'Materials Master'!$A$2:$A$27,0)),IF($B9="Organics Recycling",INDEX('Materials Master'!$H$2:$H$27,MATCH($C9,'Materials Master'!$A$2:$A$27,0)),IF($B9="Cardboard Recycling",INDEX('Materials Master'!$I$2:$I$27,MATCH($C9,'Materials Master'!$A$2:$A$27,0)),IF($B9="Paper Recycling",INDEX('Materials Master'!$J$2:$J$27,MATCH($C9,'Materials Master'!$A$2:$A$27,0)),IF($B9="Terracycle",INDEX('Materials Master'!$K$2:$K$27,MATCH($C9,'Materials Master'!$A$2:$A$27,0)),"No"))))))="Yes",INDEX('Materials Master'!$E$2:$E$27,MATCH($C9,'Materials Master'!$A$2:$A$27,0))="Yes",$B9<>"Trash"),1,0) -> 0 | H9: =INDEX('Materials Master'!$E$2:$E$27,MATCH($C9,'Materials Master'!$A$2:$A$27,0)) -> No | I9: =IFERROR(INDEX(Areas!$C$2:$C$6,MATCH($A9,Areas!$B$2:$B$6,0)),"") -> Rest of Building | J9: =IF(IF($B9="Trash",INDEX('Materials Master'!$F$2:$F$27,MATCH($C9,'Materials Master'!$A$2:$A$27,0)),IF($B9="GMPC Recycling",INDEX('Materials Master'!$G$2:$G$27,MATCH($C9,'Materials Master'!$A$2:$A$27,0)),IF($B9="Organics Recycling",INDEX('Materials Master'!$H$2:$H$27,MATCH($C9,'Materials Master'!$A$2:$A$27,0)),IF($B9="Cardboard Recycling",INDEX('Materials Master'!$I$2:$I$27,MATCH($C9,'Materials Master'!$A$2:$A$27,0)),IF($B9="Paper Recycling",INDEX('Materials Master'!$J$2:$J$27,MATCH($C9,'Materials Master'!$A$2:$A$27,0)),IF($B9="Terracycle",INDEX('Materials Master'!$K$2:$K$27,MATCH($C9,'Materials Master'!$A$2:$A$27,0)),"No"))))))="Yes",1,0) -> 1
A10: OFFICES | B10: Trash | C10: GLA01 | D10: =IFERROR(INDEX('Materials Master'!$B$2:$B$27,MATCH($C10,'Materials Master'!$A$2:$A$27,0)),"") -> Glass Bottles & Jars | E10: =IFERROR(INDEX('Materials Master'!$C$2:$C$27,MATCH($C10,'Materials Master'!$A$2:$A$27,0)),"") -> Glass | F10: =(SUMIFS(Fact_PreSortWeights!$E$2:$E$15,Fact_PreSortWeights!$C$2:$C$15,$A10,Fact_PreSortWeights!$B$2:$B$15,$B10,Fact_PreSortWeights!$F$2:$F$15,$C10))+(SUMIFS(Fact_SortedWeights!$E$2:$E$6,Fact_SortedWeights!$C$2:$C$6,$A10,Fact_SortedWeights!$B$2:$B$6,$B10,Fact_SortedWeights!$D$2:$D$6,$C10,Fact_SortedWeights!$L$2:$L$6,"Yes"))+IF((SUMIFS(Fact_SortedWeights!$E$2:$E$6,Fact_SortedWeights!$C$2:$C$6,$A10,Fact_SortedWeights!$B$2:$B$6,$B10,Fact_SortedWeights!$L$2:$L$6,"No"))=0,0,(SUMIFS(Fact_SortedWeights!$E$2:$E$6,Fact_SortedWeights!$C$2:$C$6,$A10,Fact_SortedWeights!$B$2:$B$6,$B10,Fact_SortedWeights!$D$2:$D$6,$C10,Fact_SortedWeights!$L$2:$L$6,"No"))/(SUMIFS(Fact_SortedWeights!$E$2:$E$6,Fact_SortedWeights!$C$2:$C$6,$A10,Fact_SortedWeights!$B$2:$B$6,$B10,Fact_SortedWeights!$L$2:$L$6,"No"))*((SUMIFS(Fact_PreSortWeights!$E$2:$E$15,Fact_PreSortWeights!$C$2:$C$15,$A10,Fact_PreSortWeights!$B$2:$B$15,$B10,Fact_PreSortWeights!$F$2:$F$15,""))-(SUMIFS(Fact_SortedWeights!$E$2:$E$6,Fact_SortedWeights!$C$2:$C$6,$A10,Fact_SortedWeights!$B$2:$B$6,$B10,Fact_SortedWeights!$L$2:$L$6,"Yes")))) -> 0 | G10: =IF(AND(IF($B10="Trash",INDEX('Materials Master'!$F$2:$F$27,MATCH($C10,'Materials Master'!$A$2:$A$27,0)),IF($B10="GMPC Recycling",INDEX('Materials Master'!$G$2:$G$27,MATCH($C10,'Materials Master'!$A$2:$A$27,0)),IF($B10="Organics Recycling",INDEX('Materials Master'!$H$2:$H$27,MATCH($C10,'Materials Master'!$A$2:$A$27,0)),IF($B10="Cardboard Recycling",INDEX('Materials Master'!$I$2:$I$27,MATCH($C10,'Materials Master'!$A$2:$A$27,0)),IF($B10="Paper Recycling",INDEX('Materials Master'!$J$2:$J$27,MATCH($C10,'Materials Master'!$A$2:$A$27,0)),IF($B10="Terracycle",INDEX('Materials Master'!$K$2:$K$27,MATCH($C10,'Materials Master'!$A$2:$A$27,0)),"No"))))))="Yes",INDEX('Materials Master'!$E$2:$E$27,MATCH($C10,'Materials Master'!$A$2:$A$27,0))="Yes",$B10<>"Trash"),1,0) -> 0 | H10: =INDEX('Materials Master'!$E$2:$E$27,MATCH($C10,'Materials Master'!$A$2:$A$27,0)) -> Yes | I10: =IFERROR(INDEX(Areas!$C$2:$C$6,MATCH($A10,Areas!$B$2:$B$6,0)),"") -> Rest of Building | J10: =IF(IF($B10="Trash",INDEX('Materials Master'!$F$2:$F$27,MATCH($C10,'Materials Master'!$A$2:$A$27,0)),IF($B10="GMPC Recycling",INDEX('Materials Master'!$G$2:$G$27,MATCH($C10,'Materials Master'!$A$2:$A$27,0)),IF($B10="Organics Recycling",INDEX('Materials Master'!$H$2:$H$27,MATCH($C10,'Materials Master'!$A$2:$A$27,0)),IF($B10="Cardboard Recycling",INDEX('Materials Master'!$I$2:$I$27,MATCH($C10,'Materials Master'!$A$2:$A$27,0)),IF($B10="Paper Recycling",INDEX('Materials Master'!$J$2:$J$27,MATCH($C10,'Materials Master'!$A$2:$A$27,0)),IF($B10="Terracycle",INDEX('Materials Master'!$K$2:$K$27,MATCH($C10,'Materials Master'!$A$2:$A$27,0)),"No"))))))="Yes",1,0) -> 0
A11: OFFICES | B11: Trash | C11: GLA02 | D11: =IFERROR(INDEX('Materials Master'!$B$2:$B$27,MATCH($C11,'Materials Master'!$A$2:$A$27,0)),"") -> Soiled Glass | E11: =IFERROR(INDEX('Materials Master'!$C$2:$C$27,MATCH($C11,'Materials Master'!$A$2:$A$27,0)),"") -> Glass | F11: =(SUMIFS(Fact_PreSortWeights!$E$2:$E$15,Fact_PreSortWeights!$C$2:$C$15,$A11,Fact_PreSortWeights!$B$2:$B$15,$B11,Fact_PreSortWeights!$F$2:$F$15,$C11))+(SUMIFS(Fact_SortedWeights!$E$2:$E$6,Fact_SortedWeights!$C$2:$C$6,$A11,Fact_SortedWeights!$B$2:$B$6,$B11,Fact_SortedWeights!$D$2:$D$6,$C11,Fact_SortedWeights!$L$2:$L$6,"Yes"))+IF((SUMIFS(Fact_SortedWeights!$E$2:$E$6,Fact_SortedWeights!$C$2:$C$6,$A11,Fact_SortedWeights!$B$2:$B$6,$B11,Fact_SortedWeights!$L$2:$L$6,"No"))=0,0,(SUMIFS(Fact_SortedWeights!$E$2:$E$6,Fact_SortedWeights!$C$2:$C$6,$A11,Fact_SortedWeights!$B$2:$B$6,$B11,Fact_SortedWeights!$D$2:$D$6,$C11,Fact_SortedWeights!$L$2:$L$6,"No"))/(SUMIFS(Fact_SortedWeights!$E$2:$E$6,Fact_SortedWeights!$C$2:$C$6,$A11,Fact_SortedWeights!$B$2:$B$6,$B11,Fact_SortedWeights!$L$2:$L$6,"No"))*((SUMIFS(Fact_PreSortWeights!$E$2:$E$15,Fact_PreSortWeights!$C$2:$C$15,$A11,Fact_PreSortWeights!$B$2:$B$15,$B11,Fact_PreSortWeights!$F$2:$F$15,""))-(SUMIFS(Fact_SortedWeights!$E$2:$E$6,Fact_SortedWeights!$C$2:$C$6,$A11,Fact_SortedWeights!$B$2:$B$6,$B11,Fact_SortedWeights!$L$2:$L$6,"Yes")))) -> 5 | G11: =IF(AND(IF($B11="Trash",INDEX('Materials Master'!$F$2:$F$27,MATCH($C11,'Materials Master'!$A$2:$A$27,0)),IF($B11="GMPC Recycling",INDEX('Materials Master'!$G$2:$G$27,MATCH($C11,'Materials Master'!$A$2:$A$27,0)),IF($B11="Organics Recycling",INDEX('Materials Master'!$H$2:$H$27,MATCH($C11,'Materials Master'!$A$2:$A$27,0)),IF($B11="Cardboard Recycling",INDEX('Materials Master'!$I$2:$I$27,MATCH($C11,'Materials Master'!$A$2:$A$27,0)),IF($B11="Paper Recycling",INDEX('Materials Master'!$J$2:$J$27,MATCH($C11,'Materials Master'!$A$2:$A$27,0)),IF($B11="Terracycle",INDEX('Materials Master'!$K$2:$K$27,MATCH($C11,'Materials Master'!$A$2:$A$27,0)),"No"))))))="Yes",INDEX('Materials Master'!$E$2:$E$27,MATCH($C11,'Materials Master'!$A$2:$A$27,0))="Yes",$B11<>"Trash"),1,0) -> 0 | H11: =INDEX('Materials Master'!$E$2:$E$27,MATCH($C11,'Materials Master'!$A$2:$A$27,0)) -> No | I11: =IFERROR(INDEX(Areas!$C$2:$C$6,MATCH($A11,Areas!$B$2:$B$6,0)),"") -> Rest of Building | J11: =IF(IF($B11="Trash",INDEX('Materials Master'!$F$2:$F$27,MATCH($C11,'Materials Master'!$A$2:$A$27,0)),IF($B11="GMPC Recycling",INDEX('Materials Master'!$G$2:$G$27,MATCH($C11,'Materials Master'!$A$2:$A$27,0)),IF($B11="Organics Recycling",INDEX('Materials Master'!$H$2:$H$27,MATCH($C11,'Materials Master'!$A$2:$A$27,0)),IF($B11="Cardboard Recycling",INDEX('Materials Master'!$I$2:$I$27,MATCH($C11,'Materials Master'!$A$2:$A$27,0)),IF($B11="Paper Recycling",INDEX('Materials Master'!$J$2:$J$27,MATCH($C11,'Materials Master'!$A$2:$A$27,0)),IF($B11="Terracycle",INDEX('Materials Master'!$K$2:$K$27,MATCH($C11,'Materials Master'!$A$2:$A$27,0)),"No"))))))="Yes",1,0) -> 1
A12: OFFICES | B12: Trash | C12: MET01 | D12: =IFERROR(INDEX('Materials Master'!$B$2:$B$27,MATCH($C12,'Materials Master'!$A$2:$A$27,0)),"") -> Aluminum & Bi-Metal Containers | E12: =IFERROR(INDEX('Materials Master'!$C$2:$C$27,MATCH($C12,'Materials Master'!$A$2:$A$27,0)),"") -> Metals | F12: =(SUMIFS(Fact_PreSortWeights!$E$2:$E$15,Fact_PreSortWeights!$C$2:$C$15,$A12,Fact_PreSortWeights!$B$2:$B$15,$B12,Fact_PreSortWeights!$F$2:$F$15,$C12))+(SUMIFS(Fact_SortedWeights!$E$2:$E$6,Fact_SortedWeights!$C$2:$C$6,$A12,Fact_SortedWeights!$B$2:$B$6,$B12,Fact_SortedWeights!$D$2:$D$6,$C12,Fact_SortedWeights!$L$2:$L$6,"Yes"))+IF((SUMIFS(Fact_SortedWeights!$E$2:$E$6,Fact_SortedWeights!$C$2:$C$6,$A12,Fact_SortedWeights!$B$2:$B$6,$B12,Fact_SortedWeights!$L$2:$L$6,"No"))=0,0,(SUMIFS(Fact_SortedWeights!$E$2:$E$6,Fact_SortedWeights!$C$2:$C$6,$A12,Fact_SortedWeights!$B$2:$B$6,$B12,Fact_SortedWeights!$D$2:$D$6,$C12,Fact_SortedWeights!$L$2:$L$6,"No"))/(SUMIFS(Fact_SortedWeights!$E$2:$E$6,Fact_SortedWeights!$C$2:$C$6,$A12,Fact_SortedWeights!$B$2:$B$6,$B12,Fact_SortedWeights!$L$2:$L$6,"No"))*((SUMIFS(Fact_PreSortWeights!$E$2:$E$15,Fact_PreSortWeights!$C$2:$C$15,$A12,Fact_PreSortWeights!$B$2:$B$15,$B12,Fact_PreSortWeights!$F$2:$F$15,""))-(SUMIFS(Fact_SortedWeights!$E$2:$E$6,Fact_SortedWeights!$C$2:$C$6,$A12,Fact_SortedWeights!$B$2:$B$6,$B12,Fact_SortedWeights!$L$2:$L$6,"Yes")))) -> 0 | G12: =IF(AND(IF($B12="Trash",INDEX('Materials Master'!$F$2:$F$27,MATCH($C12,'Materials Master'!$A$2:$A$27,0)),IF($B12="GMPC Recycling",INDEX('Materials Master'!$G$2:$G$27,MATCH($C12,'Materials Master'!$A$2:$A$27,0)),IF($B12="Organics Recycling",INDEX('Materials Master'!$H$2:$H$27,MATCH($C12,'Materials Master'!$A$2:$A$27,0)),IF($B12="Cardboard Recycling",INDEX('Materials Master'!$I$2:$I$27,MATCH($C12,'Materials Master'!$A$2:$A$27,0)),IF($B12="Paper Recycling",INDEX('Materials Master'!$J$2:$J$27,MATCH($C12,'Materials Master'!$A$2:$A$27,0)),IF($B12="Terracycle",INDEX('Materials Master'!$K$2:$K$27,MATCH($C12,'Materials Master'!$A$2:$A$27,0)),"No"))))))="Yes",INDEX('Materials Master'!$E$2:$E$27,MATCH($C12,'Materials Master'!$A$2:$A$27,0))="Yes",$B12<>"Trash"),1,0) -> 0 | H12: =INDEX('Materials Master'!$E$2:$E$27,MATCH($C12,'Materials Master'!$A$2:$A$27,0)) -> Yes | I12: =IFERROR(INDEX(Areas!$C$2:$C$6,MATCH($A12,Areas!$B$2:$B$6,0)),"") -> Rest of Building | J12: =IF(IF($B12="Trash",INDEX('Materials Master'!$F$2:$F$27,MATCH($C12,'Materials Master'!$A$2:$A$27,0)),IF($B12="GMPC Recycling",INDEX('Materials Master'!$G$2:$G$27,MATCH($C12,'Materials Master'!$A$2:$A$27,0)),IF($B12="Organics Recycling",INDEX('Materials Master'!$H$2:$H$27,MATCH($C12,'Materials Master'!$A$2:$A$27,0)),IF($B12="Cardboard Recycling",INDEX('Materials Master'!$I$2:$I$27,MATCH($C12,'Materials Master'!$A$2:$A$27,0)),IF($B12="Paper Recycling",INDEX('Materials Master'!$J$2:$J$27,MATCH($C12,'Materials Master'!$A$2:$A$27,0)),IF($B12="Terracycle",INDEX('Materials Master'!$K$2:$K$27,MATCH($C12,'Materials Master'!$A$2:$A$27,0)),"No"))))))="Yes",1,0) -> 0
A13: OFFICES | B13: Trash | C13: MET02 | D13: =IFERROR(INDEX('Materials Master'!$B$2:$B$27,MATCH($C13,'Materials Master'!$A$2:$A$27,0)),"") -> Soiled Metals | E13: =IFERROR(INDEX('Materials Master'!$C$2:$C$27,MATCH($C13,'Materials Master'!$A$2:$A$27,0)),"") -> Metals | F13: =(SUMIFS(Fact_PreSortWeights!$E$2:$E$15,Fact_PreSortWeights!$C$2:$C$15,$A13,Fact_PreSortWeights!$B$2:$B$15,$B13,Fact_PreSortWeights!$F$2:$F$15,$C13))+(SUMIFS(Fact_SortedWeights!$E$2:$E$6,Fact_SortedWeights!$C$2:$C$6,$A13,Fact_SortedWeights!$B$2:$B$6,$B13,Fact_SortedWeights!$D$2:$D$6,$C13,Fact_SortedWeights!$L$2:$L$6,"Yes"))+IF((SUMIFS(Fact_SortedWeights!$E$2:$E$6,Fact_SortedWeights!$C$2:$C$6,$A13,Fact_SortedWeights!$B$2:$B$6,$B13,Fact_SortedWeights!$L$2:$L$6,"No"))=0,0,(SUMIFS(Fact_SortedWeights!$E$2:$E$6,Fact_SortedWeights!$C$2:$C$6,$A13,Fact_SortedWeights!$B$2:$B$6,$B13,Fact_SortedWeights!$D$2:$D$6,$C13,Fact_SortedWeights!$L$2:$L$6,"No"))/(SUMIFS(Fact_SortedWeights!$E$2:$E$6,Fact_SortedWeights!$C$2:$C$6,$A13,Fact_SortedWeights!$B$2:$B$6,$B13,Fact_SortedWeights!$L$2:$L$6,"No"))*((SUMIFS(Fact_PreSortWeights!$E$2:$E$15,Fact_PreSortWeights!$C$2:$C$15,$A13,Fact_PreSortWeights!$B$2:$B$15,$B13,Fact_PreSortWeights!$F$2:$F$15,""))-(SUMIFS(Fact_SortedWeights!$E$2:$E$6,Fact_SortedWeights!$C$2:$C$6,$A13,Fact_SortedWeights!$B$2:$B$6,$B13,Fact_SortedWeights!$L$2:$L$6,"Yes")))) -> 0 | G13: =IF(AND(IF($B13="Trash",INDEX('Materials Master'!$F$2:$F$27,MATCH($C13,'Materials Master'!$A$2:$A$27,0)),IF($B13="GMPC Recycling",INDEX('Materials Master'!$G$2:$G$27,MATCH($C13,'Materials Master'!$A$2:$A$27,0)),IF($B13="Organics Recycling",INDEX('Materials Master'!$H$2:$H$27,MATCH($C13,'Materials Master'!$A$2:$A$27,0)),IF($B13="Cardboard Recycling",INDEX('Materials Master'!$I$2:$I$27,MATCH($C13,'Materials Master'!$A$2:$A$27,0)),IF($B13="Paper Recycling",INDEX('Materials Master'!$J$2:$J$27,MATCH($C13,'Materials Master'!$A$2:$A$27,0)),IF($B13="Terracycle",INDEX('Materials Master'!$K$2:$K$27,MATCH($C13,'Materials Master'!$A$2:$A$27,0)),"No"))))))="Yes",INDEX('Materials Master'!$E$2:$E$27,MATCH($C13,'Materials Master'!$A$2:$A$27,0))="Yes",$B13<>"Trash"),1,0) -> 0 | H13: =INDEX('Materials Master'!$E$2:$E$27,MATCH($C13,'Materials Master'!$A$2:$A$27,0)) -> No | I13: =IFERROR(INDEX(Areas!$C$2:$C$6,MATCH($A13,Areas!$B$2:$B$6,0)),"") -> Rest of Building | J13: =IF(IF($B13="Trash",INDEX('Materials Master'!$F$2:$F$27,MATCH($C13,'Materials Master'!$A$2:$A$27,0)),IF($B13="GMPC Recycling",INDEX('Materials Master'!$G$2:$G$27,MATCH($C13,'Materials Master'!$A$2:$A$27,0)),IF($B13="Organics Recycling",INDEX('Materials Master'!$H$2:$H$27,MATCH($C13,'Materials Master'!$A$2:$A$27,0)),IF($B13="Cardboard Recycling",INDEX('Materials Master'!$I$2:$I$27,MATCH($C13,'Materials Master'!$A$2:$A$27,0)),IF($B13="Paper Recycling",INDEX('Materials Master'!$J$2:$J$27,MATCH($C13,'Materials Master'!$A$2:$A$27,0)),IF($B13="Terracycle",INDEX('Materials Master'!$K$2:$K$27,MATCH($C13,'Materials Master'!$A$2:$A$27,0)),"No"))))))="Yes",1,0) -> 1
... A79: OFFICES | B79: Organics Recycling | C79: OTH02 | D79: =IFERROR(INDEX('Materials Master'!$B$2:$B$27,MATCH($C79,'Materials Master'!$A$2:$A$27,0)),"") -> Other/Residual Materials | E79: =IFERROR(INDEX('Materials Master'!$C$2:$C$27,MATCH($C79,'Materials Master'!$A$2:$A$27,0)),"") -> Other | F79: =(SUMIFS(Fact_PreSortWeights!$E$2:$E$15,Fact_PreSortWeights!$C$2:$C$15,$A79,Fact_PreSortWeights!$B$2:$B$15,$B79,Fact_PreSortWeights!$F$2:$F$15,$C79))+(SUMIFS(Fact_SortedWeights!$E$2:$E$6,Fact_SortedWeights!$C$2:$C$6,$A79,Fact_SortedWeights!$B$2:$B$6,$B79,Fact_SortedWeights!$D$2:$D$6,$C79,Fact_SortedWeights!$L$2:$L$6,"Yes"))+IF((SUMIFS(Fact_SortedWeights!$E$2:$E$6,Fact_SortedWeights!$C$2:$C$6,$A79,Fact_SortedWeights!$B$2:$B$6,$B79,Fact_SortedWeights!$L$2:$L$6,"No"))=0,0,(SUMIFS(Fact_SortedWeights!$E$2:$E$6,Fact_SortedWeights!$C$2:$C$6,$A79,Fact_SortedWeights!$B$2:$B$6,$B79,Fact_SortedWeights!$D$2:$D$6,$C79,Fact_SortedWeights!$L$2:$L$6,"No"))/(SUMIFS(Fact_SortedWeights!$E$2:$E$6,Fact_SortedWeights!$C$2:$C$6,$A79,Fact_SortedWeights!$B$2:$B$6,$B79,Fact_SortedWeights!$L$2:$L$6,"No"))*((SUMIFS(Fact_PreSortWeights!$E$2:$E$15,Fact_PreSortWeights!$C$2:$C$15,$A79,Fact_PreSortWeights!$B$2:$B$15,$B79,Fact_PreSortWeights!$F$2:$F$15,""))-(SUMIFS(Fact_SortedWeights!$E$2:$E$6,Fact_SortedWeights!$C$2:$C$6,$A79,Fact_SortedWeights!$B$2:$B$6,$B79,Fact_SortedWeights!$L$2:$L$6,"Yes")))) -> 0 | G79: =IF(AND(IF($B79="Trash",INDEX('Materials Master'!$F$2:$F$27,MATCH($C79,'Materials Master'!$A$2:$A$27,0)),IF($B79="GMPC Recycling",INDEX('Materials Master'!$G$2:$G$27,MATCH($C79,'Materials Master'!$A$2:$A$27,0)),IF($B79="Organics Recycling",INDEX('Materials Master'!$H$2:$H$27,MATCH($C79,'Materials Master'!$A$2:$A$27,0)),IF($B79="Cardboard Recycling",INDEX('Materials Master'!$I$2:$I$27,MATCH($C79,'Materials Master'!$A$2:$A$27,0)),IF($B79="Paper Recycling",INDEX('Materials Master'!$J$2:$J$27,MATCH($C79,'Materials Master'!$A$2:$A$27,0)),IF($B79="Terracycle",INDEX('Materials Master'!$K$2:$K$27,MATCH($C79,'Materials Master'!$A$2:$A$27,0)),"No"))))))="Yes",INDEX('Materials Master'!$E$2:$E$27,MATCH($C79,'Materials Master'!$A$2:$A$27,0))="Yes",$B79<>"Trash"),1,0) -> 0 | H79: =INDEX('Materials Master'!$E$2:$E$27,MATCH($C79,'Materials Master'!$A$2:$A$27,0)) -> No | I79: =IFERROR(INDEX(Areas!$C$2:$C$6,MATCH($A79,Areas!$B$2:$B$6,0)),"") -> Rest of Building | J79: =IF(IF($B79="Trash",INDEX('Materials Master'!$F$2:$F$27,MATCH($C79,'Materials Master'!$A$2:$A$27,0)),IF($B79="GMPC Recycling",INDEX('Materials Master'!$G$2:$G$27,MATCH($C79,'Materials Master'!$A$2:$A$27,0)),IF($B79="Organics Recycling",INDEX('Materials Master'!$H$2:$H$27,MATCH($C79,'Materials Master'!$A$2:$A$27,0)),IF($B79="Cardboard Recycling",INDEX('Materials Master'!$I$2:$I$27,MATCH($C79,'Materials Master'!$A$2:$A$27,0)),IF($B79="Paper Recycling",INDEX('Materials Master'!$J$2:$J$27,MATCH($C79,'Materials Master'!$A$2:$A$27,0)),IF($B79="Terracycle",INDEX('Materials Master'!$K$2:$K$27,MATCH($C79,'Materials Master'!$A$2:$A$27,0)),"No"))))))="Yes",1,0) -> 0
A80: OFFICES | B80: Cardboard Recycling | C80: FIB01 | D80: =IFERROR(INDEX('Materials Master'!$B$2:$B$27,MATCH($C80,'Materials Master'!$A$2:$A$27,0)),"") -> Corrugated Cardboard | E80: =IFERROR(INDEX('Materials Master'!$C$2:$C$27,MATCH($C80,'Materials Master'!$A$2:$A$27,0)),"") -> Fibers | F80: =SUMIFS(Fact_SortedWeights!$E$2:$E$6,Fact_SortedWeights!$C$2:$C$6,$A80,Fact_SortedWeights!$B$2:$B$6,$B80,Fact_SortedWeights!$D$2:$D$6,$C80) -> 50 | G80: =IF(AND(IF($B80="Trash",INDEX('Materials Master'!$F$2:$F$27,MATCH($C80,'Materials Master'!$A$2:$A$27,0)),IF($B80="GMPC Recycling",INDEX('Materials Master'!$G$2:$G$27,MATCH($C80,'Materials Master'!$A$2:$A$27,0)),IF($B80="Organics Recycling",INDEX('Materials Master'!$H$2:$H$27,MATCH($C80,'Materials Master'!$A$2:$A$27,0)),IF($B80="Cardboard Recycling",INDEX('Materials Master'!$I$2:$I$27,MATCH($C80,'Materials Master'!$A$2:$A$27,0)),IF($B80="Paper Recycling",INDEX('Materials Master'!$J$2:$J$27,MATCH($C80,'Materials Master'!$A$2:$A$27,0)),IF($B80="Terracycle",INDEX('Materials Master'!$K$2:$K$27,MATCH($C80,'Materials Master'!$A$2:$A$27,0)),"No"))))))="Yes",INDEX('Materials Master'!$E$2:$E$27,MATCH($C80,'Materials Master'!$A$2:$A$27,0))="Yes",$B80<>"Trash"),1,0) -> 1 | H80: =INDEX('Materials Master'!$E$2:$E$27,MATCH($C80,'Materials Master'!$A$2:$A$27,0)) -> Yes | I80: =IFERROR(INDEX(Areas!$C$2:$C$6,MATCH($A80,Areas!$B$2:$B$6,0)),"") -> Rest of Building | J80: =IF(IF($B80="Trash",INDEX('Materials Master'!$F$2:$F$27,MATCH($C80,'Materials Master'!$A$2:$A$27,0)),IF($B80="GMPC Recycling",INDEX('Materials Master'!$G$2:$G$27,MATCH($C80,'Materials Master'!$A$2:$A$27,0)),IF($B80="Organics Recycling",INDEX('Materials Master'!$H$2:$H$27,MATCH($C80,'Materials Master'!$A$2:$A$27,0)),IF($B80="Cardboard Recycling",INDEX('Materials Master'!$I$2:$I$27,MATCH($C80,'Materials Master'!$A$2:$A$27,0)),IF($B80="Paper Recycling",INDEX('Materials Master'!$J$2:$J$27,MATCH($C80,'Materials Master'!$A$2:$A$27,0)),IF($B80="Terracycle",INDEX('Materials Master'!$K$2:$K$27,MATCH($C80,'Materials Master'!$A$2:$A$27,0)),"No"))))))="Yes",1,0) -> 1
A81: OFFICES | B81: Cardboard Recycling | C81: FIB02 | D81: =IFERROR(INDEX('Materials Master'!$B$2:$B$27,MATCH($C81,'Materials Master'!$A$2:$A$27,0)),"") -> Soiled Cardboard | E81: =IFERROR(INDEX('Materials Master'!$C$2:$C$27,MATCH($C81,'Materials Master'!$A$2:$A$27,0)),"") -> Fibers | F81: =SUMIFS(Fact_SortedWeights!$E$2:$E$6,Fact_SortedWeights!$C$2:$C$6,$A81,Fact_SortedWeights!$B$2:$B$6,$B81,Fact_SortedWeights!$D$2:$D$6,$C81) -> 0 | G81: =IF(AND(IF($B81="Trash",INDEX('Materials Master'!$F$2:$F$27,MATCH($C81,'Materials Master'!$A$2:$A$27,0)),IF($B81="GMPC Recycling",INDEX('Materials Master'!$G$2:$G$27,MATCH($C81,'Materials Master'!$A$2:$A$27,0)),IF($B81="Organics Recycling",INDEX('Materials Master'!$H$2:$H$27,MATCH($C81,'Materials Master'!$A$2:$A$27,0)),IF($B81="Cardboard Recycling",INDEX('Materials Master'!$I$2:$I$27,MATCH($C81,'Materials Master'!$A$2:$A$27,0)),IF($B81="Paper Recycling",INDEX('Materials Master'!$J$2:$J$27,MATCH($C81,'Materials Master'!$A$2:$A$27,0)),IF($B81="Terracycle",INDEX('Materials Master'!$K$2:$K$27,MATCH($C81,'Materials Master'!$A$2:$A$27,0)),"No"))))))="Yes",INDEX('Materials Master'!$E$2:$E$27,MATCH($C81,'Materials Master'!$A$2:$A$27,0))="Yes",$B81<>"Trash"),1,0) -> 0 | H81: =INDEX('Materials Master'!$E$2:$E$27,MATCH($C81,'Materials Master'!$A$2:$A$27,0)) -> No | I81: =IFERROR(INDEX(Areas!$C$2:$C$6,MATCH($A81,Areas!$B$2:$B$6,0)),"") -> Rest of Building | J81: =IF(IF($B81="Trash",INDEX('Materials Master'!$F$2:$F$27,MATCH($C81,'Materials Master'!$A$2:$A$27,0)),IF($B81="GMPC Recycling",INDEX('Materials Master'!$G$2:$G$27,MATCH($C81,'Materials Master'!$A$2:$A$27,0)),IF($B81="Organics Recycling",INDEX('Materials Master'!$H$2:$H$27,MATCH($C81,'Materials Master'!$A$2:$A$27,0)),IF($B81="Cardboard Recycling",INDEX('Materials Master'!$I$2:$I$27,MATCH($C81,'Materials Master'!$A$2:$A$27,0)),IF($B81="Paper Recycling",INDEX('Materials Master'!$J$2:$J$27,MATCH($C81,'Materials Master'!$A$2:$A$27,0)),IF($B81="Terracycle",INDEX('Materials Master'!$K$2:$K$27,MATCH($C81,'Materials Master'!$A$2:$A$27,0)),"No"))))))="Yes",1,0) -> 0
A82: OFFICES | B82: Cardboard Recycling | C82: FIB03 | D82: =IFERROR(INDEX('Materials Master'!$B$2:$B$27,MATCH($C82,'Materials Master'!$A$2:$A$27,0)),"") -> Waxed Cardboard | E82: =IFERROR(INDEX('Materials Master'!$C$2:$C$27,MATCH($C82,'Materials Master'!$A$2:$A$27,0)),"") -> Fibers | F82: =SUMIFS(Fact_SortedWeights!$E$2:$E$6,Fact_SortedWeights!$C$2:$C$6,$A82,Fact_SortedWeights!$B$2:$B$6,$B82,Fact_SortedWeights!$D$2:$D$6,$C82) -> 0 | G82: =IF(AND(IF($B82="Trash",INDEX('Materials Master'!$F$2:$F$27,MATCH($C82,'Materials Master'!$A$2:$A$27,0)),IF($B82="GMPC Recycling",INDEX('Materials Master'!$G$2:$G$27,MATCH($C82,'Materials Master'!$A$2:$A$27,0)),IF($B82="Organics Recycling",INDEX('Materials Master'!$H$2:$H$27,MATCH($C82,'Materials Master'!$A$2:$A$27,0)),IF($B82="Cardboard Recycling",INDEX('Materials Master'!$I$2:$I$27,MATCH($C82,'Materials Master'!$A$2:$A$27,0)),IF($B82="Paper Recycling",INDEX('Materials Master'!$J$2:$J$27,MATCH($C82,'Materials Master'!$A$2:$A$27,0)),IF($B82="Terracycle",INDEX('Materials Master'!$K$2:$K$27,MATCH($C82,'Materials Master'!$A$2:$A$27,0)),"No"))))))="Yes",INDEX('Materials Master'!$E$2:$E$27,MATCH($C82,'Materials Master'!$A$2:$A$27,0))="Yes",$B82<>"Trash"),1,0) -> 0 | H82: =INDEX('Materials Master'!$E$2:$E$27,MATCH($C82,'Materials Master'!$A$2:$A$27,0)) -> No | I82: =IFERROR(INDEX(Areas!$C$2:$C$6,MATCH($A82,Areas!$B$2:$B$6,0)),"") -> Rest of Building | J82: =IF(IF($B82="Trash",INDEX('Materials Master'!$F$2:$F$27,MATCH($C82,'Materials Master'!$A$2:$A$27,0)),IF($B82="GMPC Recycling",INDEX('Materials Master'!$G$2:$G$27,MATCH($C82,'Materials Master'!$A$2:$A$27,0)),IF($B82="Organics Recycling",INDEX('Materials Master'!$H$2:$H$27,MATCH($C82,'Materials Master'!$A$2:$A$27,0)),IF($B82="Cardboard Recycling",INDEX('Materials Master'!$I$2:$I$27,MATCH($C82,'Materials Master'!$A$2:$A$27,0)),IF($B82="Paper Recycling",INDEX('Materials Master'!$J$2:$J$27,MATCH($C82,'Materials Master'!$A$2:$A$27,0)),IF($B82="Terracycle",INDEX('Materials Master'!$K$2:$K$27,MATCH($C82,'Materials Master'!$A$2:$A$27,0)),"No"))))))="Yes",1,0) -> 0
A83: OFFICES | B83: Cardboard Recycling | C83: FIB04 | D83: =IFERROR(INDEX('Materials Master'!$B$2:$B$27,MATCH($C83,'Materials Master'!$A$2:$A$27,0)),"") -> Mixed Paper | E83: =IFERROR(INDEX('Materials Master'!$C$2:$C$27,MATCH($C83,'Materials Master'!$A$2:$A$27,0)),"") -> Fibers | F83: =SUMIFS(Fact_SortedWeights!$E$2:$E$6,Fact_SortedWeights!$C$2:$C$6,$A83,Fact_SortedWeights!$B$2:$B$6,$B83,Fact_SortedWeights!$D$2:$D$6,$C83) -> 0 | G83: =IF(AND(IF($B83="Trash",INDEX('Materials Master'!$F$2:$F$27,MATCH($C83,'Materials Master'!$A$2:$A$27,0)),IF($B83="GMPC Recycling",INDEX('Materials Master'!$G$2:$G$27,MATCH($C83,'Materials Master'!$A$2:$A$27,0)),IF($B83="Organics Recycling",INDEX('Materials Master'!$H$2:$H$27,MATCH($C83,'Materials Master'!$A$2:$A$27,0)),IF($B83="Cardboard Recycling",INDEX('Materials Master'!$I$2:$I$27,MATCH($C83,'Materials Master'!$A$2:$A$27,0)),IF($B83="Paper Recycling",INDEX('Materials Master'!$J$2:$J$27,MATCH($C83,'Materials Master'!$A$2:$A$27,0)),IF($B83="Terracycle",INDEX('Materials Master'!$K$2:$K$27,MATCH($C83,'Materials Master'!$A$2:$A$27,0)),"No"))))))="Yes",INDEX('Materials Master'!$E$2:$E$27,MATCH($C83,'Materials Master'!$A$2:$A$27,0))="Yes",$B83<>"Trash"),1,0) -> 0 | H83: =INDEX('Materials Master'!$E$2:$E$27,MATCH($C83,'Materials Master'!$A$2:$A$27,0)) -> Yes | I83: =IFERROR(INDEX(Areas!$C$2:$C$6,MATCH($A83,Areas!$B$2:$B$6,0)),"") -> Rest of Building | J83: =IF(IF($B83="Trash",INDEX('Materials Master'!$F$2:$F$27,MATCH($C83,'Materials Master'!$A$2:$A$27,0)),IF($B83="GMPC Recycling",INDEX('Materials Master'!$G$2:$G$27,MATCH($C83,'Materials Master'!$A$2:$A$27,0)),IF($B83="Organics Recycling",INDEX('Materials Master'!$H$2:$H$27,MATCH($C83,'Materials Master'!$A$2:$A$27,0)),IF($B83="Cardboard Recycling",INDEX('Materials Master'!$I$2:$I$27,MATCH($C83,'Materials Master'!$A$2:$A$27,0)),IF($B83="Paper Recycling",INDEX('Materials Master'!$J$2:$J$27,MATCH($C83,'Materials Master'!$A$2:$A$27,0)),IF($B83="Terracycle",INDEX('Materials Master'!$K$2:$K$27,MATCH($C83,'Materials Master'!$A$2:$A$27,0)),"No"))))))="Yes",1,0) -> 0
A84: OFFICES | B84: Cardboard Recycling | C84: FIB05 | D84: =IFERROR(INDEX('Materials Master'!$B$2:$B$27,MATCH($C84,'Materials Master'!$A$2:$A$27,0)),"") -> Soiled Paper | E84: =IFERROR(INDEX('Materials Master'!$C$2:$C$27,MATCH($C84,'Materials Master'!$A$2:$A$27,0)),"") -> Fibers | F84: =SUMIFS(Fact_SortedWeights!$E$2:$E$6,Fact_SortedWeights!$C$2:$C$6,$A84,Fact_SortedWeights!$B$2:$B$6,$B84,Fact_SortedWeights!$D$2:$D$6,$C84) -> 0 | G84: =IF(AND(IF($B84="Trash",INDEX('Materials Master'!$F$2:$F$27,MATCH($C84,'Materials Master'!$A$2:$A$27,0)),IF($B84="GMPC Recycling",INDEX('Materials Master'!$G$2:$G$27,MATCH($C84,'Materials Master'!$A$2:$A$27,0)),IF($B84="Organics Recycling",INDEX('Materials Master'!$H$2:$H$27,MATCH($C84,'Materials Master'!$A$2:$A$27,0)),IF($B84="Cardboard Recycling",INDEX('Materials Master'!$I$2:$I$27,MATCH($C84,'Materials Master'!$A$2:$A$27,0)),IF($B84="Paper Recycling",INDEX('Materials Master'!$J$2:$J$27,MATCH($C84,'Materials Master'!$A$2:$A$27,0)),IF($B84="Terracycle",INDEX('Materials Master'!$K$2:$K$27,MATCH($C84,'Materials Master'!$A$2:$A$27,0)),"No"))))))="Yes",INDEX('Materials Master'!$E$2:$E$27,MATCH($C84,'Materials Master'!$A$2:$A$27,0))="Yes",$B84<>"Trash"),1,0) -> 0 | H84: =INDEX('Materials Master'!$E$2:$E$27,MATCH($C84,'Materials Master'!$A$2:$A$27,0)) -> No | I84: =IFERROR(INDEX(Areas!$C$2:$C$6,MATCH($A84,Areas!$B$2:$B$6,0)),"") -> Rest of Building | J84: =IF(IF($B84="Trash",INDEX('Materials Master'!$F$2:$F$27,MATCH($C84,'Materials Master'!$A$2:$A$27,0)),IF($B84="GMPC Recycling",INDEX('Materials Master'!$G$2:$G$27,MATCH($C84,'Materials Master'!$A$2:$A$27,0)),IF($B84="Organics Recycling",INDEX('Materials Master'!$H$2:$H$27,MATCH($C84,'Materials Master'!$A$2:$A$27,0)),IF($B84="Cardboard Recycling",INDEX('Materials Master'!$I$2:$I$27,MATCH($C84,'Materials Master'!$A$2:$A$27,0)),IF($B84="Paper Recycling",INDEX('Materials Master'!$J$2:$J$27,MATCH($C84,'Materials Master'!$A$2:$A$27,0)),IF($B84="Terracycle",INDEX('Materials Master'!$K$2:$K$27,MATCH($C84,'Materials Master'!$A$2:$A$27,0)),"No"))))))="Yes",1,0) -> 0
